Workbook
Name DayNumber: #REF!
Name DayNumber: #REF!
Name diff: INT(('Phạm Giờ(nháp)'!jd_DayNumber - 'Phạm Giờ(nháp)'!jd_a11) / 29)
Name diff: INT((jd_DayNumber - jd_a11) / 29)
Name dr: PI()/180
Name jd_a11: INT(IF('Phạm Giờ(nháp)'!l_a11>='Phạm Giờ(nháp)'!monthStart,DATE('Phạm Giờ(nháp)'!Year-1,12,20)-TEXT(DATE('Phạm Giờ(nháp)'!Year-1,12,20),"[$-0011042A]dd"),'Phạm Giờ(nháp)'!l_a11)+2415018.5)
Name jd_a11: INT(IF(l_a11>=monthStart,DATE(Year-1,12,20)-TEXT(DATE(Year-1,12,20),"[$-0011042A]dd"),l_a11)+2415018.5)
Name jd_DayNumber: INT(#REF!+2415018.5)
Name jd_DayNumber: INT(#REF!+2415018.5)
Name l_a11: #REF!
Name l_a11: #REF!
Name LeapMonthDiff: #REF!
Name LeapMonthDiff: #REF!
Name LeapYear: #REF!
Name LeapYear: #REF!
Name listcheck: '[1]AN CÁC SAO CHÍNH TINH'!$AN:$AO
Name LunarDay: TEXT('Phạm Giờ(nháp)'!DayNumber,"[$-0011042A]dd")
Name LunarDay: TEXT(DayNumber,"[$-0011042A]dd")
Name LunarMonth: IF(AND('Phạm Giờ(nháp)'!LeapYear,'Phạm Giờ(nháp)'!diff>='Phạm Giờ(nháp)'!LeapMonthDiff),'Phạm Giờ(nháp)'!diff+10,'Phạm Giờ(nháp)'!diff+ 11)
Name LunarMonth: IF(AND(LeapYear,diff>=LeapMonthDiff),diff+10,diff+ 11)
Name LunarMonth2: TEXT(IF('Phạm Giờ(nháp)'!LunarMonth>12,MOD('Phạm Giờ(nháp)'!LunarMonth,12),'Phạm Giờ(nháp)'!LunarMonth),"00")
Name LunarMonth2: TEXT(IF(LunarMonth>12,MOD(LunarMonth,12),LunarMonth),"00")
Name monthStart: IF(EDATE(DayNumber,1)-TEXT(EDATE(DayNumber,1),"[$-0011042A]dd")+1>DayNumber,DayNumber-TEXT(DayNumber,"[$-0011042A]dd")+1,EDATE(DayNumber,1)-TEXT(EDATE(DayNumber,1),"[$-0011042A]dd")+1)
Name NAMLIST: #REF!
Name NAMLIST: #REF!
Name Year: #REF!
Name Year: #REF!

Sheet Nguyên Tắc AI Luận Giải
A1: Nguyên Tắc 1: Lấy Toàn bộ dữ liệu Lá Số Tử Vi(Admin) sau khi User đã nhập các dữ liệu Ngày tháng năm sinh và giờ sinh chuẩn và Xác Nhận Thành Công để luận giải. Nguyên Tắc 2: Các form Mẫu của 5 nút bấm khi in ra sẽ được cung cấp yêu cầu AI phải mặc định tuân theo bộ khung đã định sẵn được để ở trong đường dẫn sau(E:\Tu vi online\AI học tử vi\Các Nguyên Tắc Để AI Luận Giải 1 Lá Số Tử Vi\.....). Nguyên Tắc 3: AI sẽ được học và cập nhật thêm các Tài liệu để trong đường dẫn sauE:\Tu vi online\AI học tử vi\Thư Viện cho AI Học\...). Trong thư viện này có 3 tầng học. Tầng 1 là các sách vở... là những dữ liệu quan trọng nhất, chuẩn hóa nhất, bắt buộc AI phải Tuân theo. Tầng 2 là các sách vở ... là những dữ liệu đã được Chọn lọc tuy nhiên chưa được Chuẩn Hóa như tầng 1 AI có thể tham khảo và bổ sung kiến thức thêm. Tầng 3 là sách vở... những dữ liệu chưa được chọn lọc, chuẩn hóa nó không bằng Tầng 1 và Tầng 2 nhưng vẫn được dùng để Tham khảo bổ Sung cho luận đoán. Đây là 3 Nguyên Tắc Mặc định AI phải tuân theo.

Sheet An 12 con giáp theo Ngũ Hành
A1: STT | B1: 12 con Giáp | C1: Ngũ Hành
A2: 1 | B2: năm Tý | C2: (+)Thủy
A3: 2 | B3: năm Sửu | C3: (+) Thổ
A4: 3 | B4: năm Dần | C4: (+) Mộc
A5: 4 | B5: năm Mão | C5: (-) Mộc
A6: 5 | B6: năm Thìn | C6: (+) Thổ
A7: 6 | B7: năm Tỵ | C7: (-) Hỏa
A8: 7 | B8: năm Ngọ | C8: (+) Hỏa
A9: 8 | B9: năm Mùi | C9: (-) Thổ
A10: 9 | B10: năm Thân | C10: (+) Kim
A11: 10 | B11: năm Dậu | C11: (-) Kim
A12: 11 | B12: năm Tuất | C12: (-) Thổ
A13: 12 | B13: năm Hợi | C13: (-) Thủy

Sheet Lục Thập Hoa Giáp theo Ngũ Hành
A1: NĂM | B1: HÀNG CAN | C1: HÀNG CHI | D1: MỆNH | E1: Ngũ hành | F1: Giải nghĩa | G1: Mệnh nam | H1: Mệnh nữ
A2: 1 | B2: TÂN | C2: DẬU | D2: Tân Dậu | E2: Thạch Lựu Mộc | F2: Gỗ cây lựu | G2: Đoài Kim | H2: Cấn Thổ
A3: 2 | B3: NHÂM | C3: TUẤT | D3: Nhâm Tuất | E3: Đại Hải Thủy | F3: Nước biển lớn | G3: Càn Kim | H3: Ly Hoả
A4: 3 | B4: QUÝ | C4: HỢI | D4: Quý Hợi | E4: Đại Hải Thủy | F4: Nước biển lớn | G4: Khôn Thổ | H4: Khảm Thuỷ
A5: 4 | B5: GIÁP | C5: TÝ | D5: Giáp Tý | E5: Hải Trung Kim | F5: Vàng trong biển | G5: Tốn Mộc | H5: Khôn Thổ
A6: 5 | B6: ẤT | C6: SỬU | D6: Ất Sửu | E6: Hải Trung Kim | F6: Vàng trong biển | G6: Chấn Mộc | H6: Chấn Mộc
A7: 6 | B7: BÍNH | C7: DẦN | D7: Bính Dần | E7: Lư Trung Hỏa | F7: Lửa trong lò | G7: Khôn Thổ | H7: Tốn Mộc
A8: 7 | B8: ĐINH | C8: MÃO | D8: Đinh Mão | E8: Lư Trung Hỏa | F8: Lửa trong lò | G8: Khảm Thuỷ | H8: Khôn Thổ
A9: 8 | B9: MẬU | C9: THÌN | D9: Mậu Thìn | E9: Đại Lâm Mộc | F9: Gỗ rừng già | G9: Ly Hoả | H9: Càn Kim
A10: 9 | B10: KỶ | C10: TỴ | D10: Kỷ Tỵ | E10: Đại Lâm Mộc | F10: Gỗ rừng già | G10: Cấn Thổ | H10: Đoài Kim
A11: 10 | B11: CANH | C11: NGỌ | D11: Canh Ngọ | E11: Lộ Bàng Thổ | F11: Đất đường đi | G11: Đoài Kim | H11: Cấn Thổ
A12: 11 | B12: TÂN | C12: MÙI | D12: Tân Mùi | E12: Lộ Bàng Thổ | F12: Đất đường đi | G12: Càn Kim | H12: Ly Hoả
A13: 12 | B13: NHÂM | C13: THÂN | D13: Nhâm Thân | E13: Kiếm Phong Kim | F13: Vàng mũi kiếm | G13: Khôn Thổ | H13: Khảm Thuỷ
... A61: 60 | B61: CANH | C61: THÂN | D61: Canh Thân | E61: Thạch Lựu Mộc | F61: Gỗ cây lựu | G61: Cấn Thổ | H61: Đoài Kim

Sheet Phạm Giờ
A1: STT | B1: Phạm Giờ | C1: Tháng 1 | D1: Tháng 2 | E1: Tháng 3 | F1: Tháng 4 | G1: Tháng 5 | H1: Tháng 6 | I1: Tháng 7 | J1: Tháng 8 | K1: Tháng 9 | L1: Tháng 10 | M1: Tháng 11 | N1: Tháng 12 | O1: Ý Nghĩa | P1: Mức Độ Nguy Hiểm | Q1: Cách Hóa Giải Khi Trẻ Bị Phạm Giờ Sinh
C2: Sinh vào giờ | D2: Sinh vào giờ | E2: Sinh vào giờ | F2: Sinh vào giờ | G2: Sinh vào giờ | H2: Sinh vào giờ | I2: Sinh vào giờ | J2: Sinh vào giờ | K2: Sinh vào giờ | L2: Sinh vào giờ | M2: Sinh vào giờ | N2: Sinh vào giờ
A3: 1 | B3: Quan Sát | C3: Tỵ | D3: Thìn | E3: Mão | F3: Dần | G3: Sửu | H3: Tý | I3: Hợi | J3: Tuất | K3: Dậu | L3: Thân | M3: Mùi | N3: Ngọ | O3: Trẻ có thể bị mất ngay sau khi sinh. Nếu may mắn qua được thì lớn lên cũng hay đau ốm, tính khí ngang bướng, ngỗ ngược. | P3: Quan trọng | Q3: Dòng 28-48
A4: 2 | B4: Diêm Vương | C4: Sửu, Mùi | D4: Sửu, Mùi | E4: Sửu, Mùi | F4: Thìn, Tuất | G4: Thìn, Tuất | H4: Thìn, Tuất | I4: Tý, Ngọ | J4: Tý, Ngọ | K4: Tý, Ngọ | L4: Mão, Dậu | M4: Mão, Dậu | N4: Mão, Dậu | O4: Trẻ thường hay giật mình, thần kinh có nhiều bất ổn, trẻ thường sợ sệt và bị ám ảnh bởi điều gì đó. | P4: Quan trọng | Q4: Dòng 28-48
A5: 3 | B5: Dạ Đề | C5: Ngọ | D5: Ngọ | E5: Ngọ | F5: Dậu | G5: Dậu | H5: Dậu | I5: Tý | J5: Tý | K5: Tý | L5: Mão | M5: Mão | N5: Mão | O5: Trẻ thường quấy khóc ngằn ngặt vào ban đêm, khí huyết bị trì trệ gây mệt mỏi, khó chịu. | P5: Nhẹ, Không Quá Lo Lắng | Q5: Dòng 28-48
A6: 4 | B6: Tướng Quân | C6: Thìn, Tuất, Dậu | D6: Thìn, Tuất, Dậu | E6: Thìn, Tuất, Dậu | F6: Tý, Mão, Mùi | G6: Tý, Mão, Mùi | H6: Tý, Mão, Mùi | I6: Dần, Ngọ, Sửu | J6: Dần, Ngọ, Sửu | K6: Dần, Ngọ, Sửu | L6: Thân, Tỵ, Hợi | M6: Thân, Tỵ, Hợi | N6: Thân, Tỵ, Hợi | O6: Trẻ phạm giờ này lúc nhỏ thường hay bị sài đẹn, quấy khóc, hay đau ốm bệnh tật. Đến khi lớn lên tính khí bướng bỉnh, nghịch ngợm. | P6: Nhẹ, Không Quá Lo Lắng | Q6: Dòng 28-48
A7: 5 | B7: Phạm Kị Cha Mẹ | C7: Tỵ, Hợi | D7: Thìn, Tuất, Dậu | E7: Mão, Dậu | F7: Dần, Thân | G7: Sửu, Mùi | H7: Tý, Ngọ | I7: Tỵ, Hợi | J7: Thìn, Tuất | K7: Mão, Dậu | L7: Dần, Thân | M7: Sửu, Mùi | N7: Tý, Ngọ | O7: Lúc nhỏ thường đau yếu khó nuôi khiến cho bố mẹ vất vả, nếu nuôi được thì lớn cha mẹ dễ chia li, trường hợp cha mẹ không chia li thì con dễ gặp tai họa. | P7: Quan trọng | Q7: Dòng 28-48
A8: 6 | B8: Quan Quả | C8: Tỵ | D8: Tỵ | E8: TỴ | F8: Thân, Thìn | G8: Thân, Thìn | H8: Thân, Thìn | I8: Mùi, Hợi | J8: Mùi, Hợi | K8: Mùi, Hợi | L8: Dậu, Mão | M8: Dậu, Mão | N8: Dậu, Mão | P8: Quan trọng
A9: 7 | B9: Kim Xà Thiết Tỏa | C9: Cách Tính Phạm giờ Kim Xà Thiết Tỏa Và Bàng Giờ như sau: Trước hết phải biết giờ, ngày, tháng, năm sinh. 'Sau đó từ cung Tuất (an trên bàn tay phải theo trình tự 12 con giáp trên bàn tay) bắt đầu khởi năm Tý, đếm theo chiều thuận Kim Đồng Hồ đến năm sinh; 'Đến cung nào, kể cung đó là tháng Giêng, đếm theo chiều nghịch Kim Đồng Hồ đến tháng sinh; 'Đến cung nào, kể cung đó là mùng một, đếm theo chiều thuận Kim Đồng Hồ đến ngày sinh; 'Đến cung nào, kể cung đó là giờ Tý, đếm theo chiều nghịch Kim Đồng Hồ đến giờ sinh thì dừng lại ở cung này. 'Nếu là trai, mà cung này là cung Thìn hoặc Tuất thì phạm giờ Kim Xà Thiết Tỏa. Còn nếu cung này là cung Sửu hay Mùi thì phạm vào Bàng Giờ. Nếu là gái, mà cung này là cung Sửu hoặc Mùi thì phạm giờ Kim Xà Thiết Tỏa, còn nếu rơi vào cung Thìn hay Tuất thì chỉ phạm Bàng Giờ. | O9: Trường hợp phạm giờ Kim xà, trai hay gái, dễ yểu mệnh trước 13 tuổi. Còn nếu chỉ phạm Bàng giờ thì có cơ may tồn tại, nhưng sẽ hết sức khó nuôi. Tuy nhiên, nếu bản mệnh đứa trẻ bị bản mệnh người mẹ hoặc người cha khắc thì ít hy vọng, đứa nhỏ sẽ có thể yểu, sau nhiều lần đau yếu. Tuy nhiên, trong trường hợp có hy vọng tồn tại, còn phải xem thêm các sát tinh thủ cung Mệnh đứa trẻ để quyết đoán cho chắc chắn | P9: Quan trọng | Q9: Dòng 28-48
A10: 8 | B10: Bàng Giờ | P10: Quan trọng | Q10: Dòng 28-48
A13: Trong năm điều phạm trên đây thì phạm giờ Quan sát, Diêm Vương, kị Cha mẹ là nghiêm trọng nhất. Giờ Dạ đề và Tướng quân nhẹ hơn, không cần quá lo lắng.
A14: Tháng 1: Phạm Quan sát: giờ Tị. Phạm Diêm Vương: giờ Sửu, Mùi. Phạm Dạ đề: giờ Ngọ. Phạm Tướng quân: Giờ Thìn, Tuất, Dậu. Phạm Kị Cha mẹ: Giờ Tị, Hợi.
A15: Tháng 2: Phạm Quan sát: giờ Thìn. Phạm Diêm Vương: giờ Sửu, Mùi. Phạm Dạ đề: giờ Ngọ. Phạm Tướng quân: Giờ Thìn, Tuất, Dậu. Phạm Kị Cha mẹ: Giờ Thìn, Tuất.
A16: Tháng 3: Phạm Quan sát: giờ Mão. Phạm Diêm Vương: giờ Sửu, Mùi. Phạm Dạ đề: giờ Ngọ. Phạm Tướng quân: Giờ Thìn, Tuất, Dậu. Phạm Kị Cha mẹ: Giờ Mão, Dậu.
A17: Tháng 4: Phạm Quan sát: giờ Dần. Phạm Diêm Vương: giờ Thìn, Tuất. Phạm Dạ đề: giờ Dậu. Phạm Tướng quân: Giờ Tí, Mão, Mùi. Phạm Kị Cha mẹ: Giờ Dần, Thân.
A18: Tháng 5: Phạm Quan sát: giờ Sửu. Phạm Diêm Vương: giờ Thìn, Tuất. Phạm Dạ đề: giờ Dậu. Phạm Tướng quân: Giờ Tí, Mão, Mùi. Phạm Kị Cha mẹ: Giờ Sửu, Mùi.
A19: Tháng 6: Phạm Quan sát: giờ Tí. Phạm Diêm Vương: giờ Thìn, Tuất. Phạm Dạ đề: giờ Dậu. Phạm Tướng quân: Giờ Tí, Mão, Mùi. Phạm Kị Cha mẹ: Giờ Tí, Ngọ.
A20: Tháng 7: Phạm Quan sát: giờ Hợi. Phạm Diêm Vương: giờ Tí, Ngọ. Phạm Dạ đề: giờ Tí. Phạm Tướng quân: Giờ Dần, Ngọ, Sửu. Phạm Kị Cha mẹ: Giờ Tị, Hợi.
A21: Tháng 8: Phạm Quan sát: giờ Tuất. Phạm Diêm Vương: giờ Tí, Ngọ. Phạm Dạ đề: giờ Tí. Phạm Tướng quân: Giờ Dần, Ngọ, Sửu. Phạm Kị Cha mẹ: Giờ Thìn, Tuất.
A22: Tháng 9: Phạm Quan sát: giờ Dậu. Phạm Diêm Vương: giờ Tí, Ngọ. Phạm Dạ đề: giờ Tí. Phạm Tướng quân: Giờ Dần, Ngọ, Sửu. Phạm Kị Cha mẹ: Giờ Mão, Dậu.
A23: Tháng 10: Phạm Quan sát: giờ Thân. Phạm Diêm Vương: giờ Mão, Dậu. Phạm Dạ đề: giờ Mão. Phạm Tướng quân: Giờ Thân, Tị, Hợi. Phạm Kị Cha mẹ: Giờ Dần, Thân.
A24: Tháng 11: Phạm Quan sát: giờ Mùi. Phạm Diêm Vương: giờ Mão, Dậu. Phạm Dạ đề: giờ Mão. Phạm Tướng quân: Giờ Thân, Tị, Hợi. Phạm Kị Cha mẹ: Giờ Sửu, Mùi.
... A48: Trên tinh thần Đức Năng Thắng Số, mọi người cứ sống tốt, làm nhiều việc thiện thì mọi tai ương sẽ được tiêu trừ và hóa giải.

Sheet Phạm Giờ(nháp)
A1: Phạm Giờ | D1: Ý Nghĩa | E1: Mức Độ | F1: Cách Khắc Phục | H1: Phạm Giờ | M1: Ý Nghĩa | N1: Cách Khắc Phục
A2: Quan Sát | B2: tháng 1 | C2: tỵ | D2: Trẻ có thể bị mất ngay sau khi sinh. Nếu may mắn qua được thì lớn lên cũng hay đau ốm, tính khí ngang bướng, ngỗ ngược. | E2: Quan trọng | H2: Kim Xà Thiết Tỏa và Bàng Giờ | I2: Cách Tính Phạm giờ Kim Xà Thiết Tỏa Và Bàng Giờ như sau: | J2: GIỜ KIM XÀ THIẾT TỎA | K2: NỮ | L2: NAM | M2: Trường hợp phạm giờ Kim xà, trai hay gái, dễ yểu mệnh trước 13 tuổi. Còn nếu chỉ phạm Bàng giờ thì có cơ may tồn tại, nhưng sẽ hết sức khó nuôi. Tuy nhiên, nếu bản mệnh đứa trẻ bị bản mệnh người mẹ hoặc người cha khắc thì ít hy vọng, đứa nhỏ sẽ có thể yểu, sau nhiều lần đau yếu. Tuy nhiên, trong trường hợp có hy vọng tồn tại, còn phải xem thêm các sát tinh thủ cung Mệnh đứa trẻ để quyết đoán cho chắc chắn
A3: Quan Sát | B3: tháng 2 | C3: thìn | I3: Trước hết phải biết giờ, ngày, tháng, năm sinh. | J3: TỪ CUNG TUẤT LÀ NĂM TÝ | K3: SỬU | L3: THÌN
A4: Quan Sát | B4: tháng 3 | C4: mão | I4: Sau đó từ cung Tuất (an trên bàn tay phải theo trình tự 12 con giáp trên bàn tay) bắt đầu khởi năm Tý, đếm theo chiều thuận Kim Đồng Hồ đến năm sinh; | J4: KHỞI THUẬN ĐẾN NĂM SINH | K4: MÙI | L4: TUẤT
A5: Quan Sát | B5: tháng 4 | C5: dần | I5: Đến cung nào, kể cung đó là tháng Giêng, đếm theo chiều nghịch Kim Đồng Hồ đến tháng sinh; | J5: TỪ ĐÓ KHỞI NGHỊCH ĐẾN THÁNG SINH
A6: Quan Sát | B6: tháng 5 | C6: sửu | I6: Đến cung nào, kể cung đó là mùng một, đếm theo chiều thuận Kim Đồng Hồ đến ngày sinh; | J6: KHỞI THUẬN ĐẾN NGÀY SINH
A7: Quan Sát | B7: tháng 6 | C7: tý | I7: Đến cung nào, kể cung đó là giờ Tý, đếm theo chiều nghịch Kim Đồng Hồ đến giờ sinh thì dừng lại ở cung này. | J7: KHỞI NGHỊCH ĐẾN GIỜ SINH
A8: Quan Sát | B8: tháng 7 | C8: hợi | I8: Nếu là trai, mà cung này là cung Thìn hoặc Tuất thì phạm giờ Kim Xà Thiết Tỏa. Còn nếu cung này là cung Sửu hay Mùi thì phạm vào Bàng Giờ.
A9: Quan Sát | B9: tháng 8 | C9: sửu | I9: Nếu là gái, mà cung này là cung Sửu hoặc Mùi thì phạm giờ Kim Xà Thiết Tỏa, còn nếu rơi vào cung Thìn hay Tuất thì chỉ phạm Bàng Giờ.
A10: Quan Sát | B10: tháng 9 | C10: sửu | J10: GIỜ BÀNG GIỜ | K10: NAM | L10: NỮ
B11: tháng 10
A12: Quan Sát | B12: tháng 11
A13: Quan Sát | B13: tháng 12 | C13: sửu | J13: TỪ CUNG TUẤT LÀ NĂM TÝ | K13: SỬU | L13: THÌN
A14: Diêm Vương | B14: tháng 1 | C14: mùi | D14: Trẻ thường hay giật mình, thần kinh có nhiều bất ổn, trẻ thường sợ sệt và bị ám ảnh bởi điều gì đó. | E14: Quan trọng | J14: KHỞI THUẬN ĐẾN NĂM SINH | K14: MÙI | L14: TUẤT
A15: Diêm Vương | B15: tháng 2 | C15: mùi | J15: TỪ ĐÓ KHỞI NGHỊCH ĐẾN THÁNG SINH
A16: Diêm Vương | B16: tháng 3 | C16: mùi | J16: KHỞI THUẬN ĐẾN NGÀY SINH
A17: Diêm Vương | B17: tháng 4 | C17: thìn | J17: KHỞI NGHỊCH ĐẾN GIỜ SINH
A18: Diêm Vương | B18: tháng 5 | C18: thìn
A19: Diêm Vương | B19: tháng 6 | C19: thìn | J19: NAM THÌN | K19: GIỜ KIM THIẾT
A20: Diêm Vương | B20: tháng 4 | C20: tuất | J20: NAM TUẤT | K20: GIỜ KIM THIẾT
A21: Diêm Vương | B21: tháng 5 | C21: tuất | J21: NỮ SỬU | K21: GIỜ KIM THIẾT
A22: Diêm Vương | B22: tháng 6 | C22: tuất | J22: NỮ MÙI | K22: GIỜ KIM THIẾT
A23: Diêm Vương | B23: tháng 7 | C23: tý | J23: NAM SỬU | K23: GIỜ BÀNG GIỜ
A24: Diêm Vương | B24: tháng 8 | C24: tý | J24: NAM MÙI | K24: GIỜ BÀNG GIỜ
A25: Diêm Vương | B25: tháng 9 | C25: tý | J25: NỮ THÌN | K25: GIỜ BÀNG GIỜ
A26: Diêm Vương | B26: tháng 7 | C26: ngọ | J26: NỮ TUẤT | K26: GIỜ BÀNG GIỜ
A27: Diêm Vương | B27: tháng 8 | C27: ngọ
A28: Diêm Vương | B28: tháng 9 | C28: ngọ
A29: Diêm Vương | B29: tháng 10 | C29: mão
A30: Diêm Vương | B30: tháng 11 | C30: mão
A31: Diêm Vương | B31: tháng 12 | C31: mão
A32: Diêm Vương | B32: tháng 10 | C32: dậu
A33: Diêm Vương | B33: tháng 11 | C33: dậu
A34: Diêm Vương | B34: tháng 12 | C34: dậu
A35: Dạ Đề | B35: tháng 1 | C35: ngọ | D35: Trẻ thường quấy khóc ngằn ngặt vào ban đêm, khí huyết bị trì trệ gây mệt mỏi, khó chịu. | E35: Nhẹ, Không Quá Lo Lắng
A36: Dạ Đề | B36: tháng 2 | C36: ngọ
A37: Dạ Đề | B37: tháng 3 | C37: ngọ
A38: Dạ Đề | B38: tháng 4 | C38: dậu
A39: Dạ Đề | B39: tháng 5 | C39: dậu
A40: Dạ Đề | B40: tháng 6 | C40: dậu
...

Sheet Hạn Sao Theo Năm Hiện Tại
A1: TUỔI NĂM XEM | B1: NỮ | C1: NAM
A2: 10 | B2: KẾ ĐÔ - HÀNH THỔ | C2: LA HẦU - HÀNH KIM
A3: 11 | B3: VÂN HỚN - HÀNH HỎA | C3: THỔ TÚ - HÀNH THỔ
A4: 12 | B4: MỘC ĐỨC- HÀNH MỘC- HÀNH MỘC | C4: THỦY DIỆU - HÀNH THỦY
A5: 13 | B5: THÁI ÂM- HÀNH THỦY | C5: THÁI BẠCH - HÀNH KIM
A6: 14 | B6: THỔ TÚ - HÀNH THỔ | C6: THÁI DƯƠNG - HÀNH HỎA
A7: 15 | B7: LA HẦU - HÀNH KIM | C7: VÂN HỚN - HÀNH HỎA
A8: 16 | B8: THÁI DƯƠNG - HÀNH HỎA | C8: KẾ ĐÔ - HÀNH THỔ
A9: 17 | B9: THÁI BẠCH - HÀNH KIM | C9: THÁI ÂM- HÀNH THỦY
A10: 18 | B10: THỦY DIỆU - HÀNH THỦY | C10: MỘC ĐỨC- HÀNH MỘC
A11: 19 | B11: KẾ ĐÔ - HÀNH THỔ | C11: LA HẦU - HÀNH KIM
A12: 20 | B12: VÂN HỚN - HÀNH HỎA | C12: THỔ TÚ - HÀNH THỔ
A13: 21 | B13: MỘC ĐỨC- HÀNH MỘC | C13: THỦY DIỆU - HÀNH THỦY
... A103: 111 | B103: MỘC ĐỨC- HÀNH MỘC | C103: THỦY DIỆU - HÀNH THỦY

Sheet Bảng Cân Xương Tính Số
A1: BẢNG TRA CÂN LƯỢNG THEO Năm SINH | B1: STT | C1: 60 Lục Thập Hoa Giáp | D1: Cân Lượng Theo Năm Sinh | E1: Quy Đổi | G1: BẢNG TRA CÂN LƯỢNG THEO THÁNG SINH | H1: STT | I1: Tháng Sinh | J1: Cân Lượng Theo Tháng Sinh | K1: Quy Đổi | M1: BẢNG TRA CÂN LƯỢNG THEO NGÀY SINH | N1: STT | O1: Ngày Sinh | P1: Cân Lượng Theo Ngày Sinh | Q1: Quy Đổi | S1: BẢNG TRA CÂN LƯỢNG THEO GIỜ SINH | T1: STT | U1: Giờ Sinh | V1: Cân Lượng Theo Giờ Sinh | W1: Quy Đổi
A2: Giáp Tý: 1 lượng 2 chỉ | B2: 1 | C2: Giáp Tý | D2: 1 lượng 2 chỉ | E2: 1.2 | G2: Tháng Giêng: 0 lượng 6 chỉ | H2: 1 | I2: Tháng Giêng | J2: 0 lượng 6 chỉ | K2: 0.6 | M2: Ngày mùng một: 0 lượng 5 chỉ | N2: 1 | O2: Ngày mùng một | P2: 0 lượng 5 chỉ | Q2: 0.5 | S2: Giờ Tý: 1 lượng 6 chỉ | T2: 1 | U2: Giờ Tý | V2: 1 lượng 6 chỉ | W2: 1.6
A3: Bính Tý: 1 lượng 6 chỉ | B3: 2 | C3: Bính Tý | D3: 1 lượng 6 chỉ | E3: 1.6 | G3: Tháng Hai: 0 lượng 7 chỉ | H3: 2 | I3: Tháng Hai | J3: 0 lượng 7 chỉ | K3: 0.7 | M3: Ngày mùng hai: 1 lượng 0 chỉ | N3: 2 | O3: Ngày mùng hai | P3: 1 lượng 0 chỉ | Q3: 1 | S3: Giờ Sửu: 0 lượng 6 chỉ | T3: 2 | U3: Giờ Sửu | V3: 0 lượng 6 chỉ | W3: 0.6
A4: Mậu Tý: 1 lượng 5 chỉ | B4: 3 | C4: Mậu Tý | D4: 1 lượng 5 chỉ | E4: 1.5 | G4: Tháng Ba: 1 lượng 8 chỉ | H4: 3 | I4: Tháng Ba | J4: 1 lượng 8 chỉ | K4: 1.8 | M4: Ngày mùng ba: 0 lượng 8 chỉ | N4: 3 | O4: Ngày mùng ba | P4: 0 lượng 8 chỉ | Q4: 0.8 | S4: Giờ Dần: 0 lượng 7 chỉ | T4: 3 | U4: Giờ Dần | V4: 0 lượng 7 chỉ | W4: 0.7
A5: Canh Tý: 0 lượng 7 chỉ | B5: 4 | C5: Canh Tý | D5: 0 lượng 7 chỉ | E5: 0.7 | G5: Tháng Tư: 0 lượng 9 chỉ | H5: 4 | I5: Tháng Tư | J5: 0 lượng 9 chỉ | K5: 0.9 | M5: Ngày mùng bốn: 1 lượng 5 chỉ | N5: 4 | O5: Ngày mùng bốn | P5: 1 lượng 5 chỉ | Q5: 1.5 | S5: Giờ Mão: 1 lượng 0 chỉ | T5: 4 | U5: Giờ Mão | V5: 1 lượng 0 chỉ | W5: 1
A6: Nhâm Tý: 0 lượng 5 chỉ | B6: 5 | C6: Nhâm Tý | D6: 0 lượng 5 chỉ | E6: 0.5 | G6: Tháng Năm: 0 lượng 5 chỉ | H6: 5 | I6: Tháng Năm | J6: 0 lượng 5 chỉ | K6: 0.5 | M6: Ngày mùng năm: 1 lượng 6 chỉ | N6: 5 | O6: Ngày mùng năm | P6: 1 lượng 6 chỉ | Q6: 1.6 | S6: Giờ Thìn: 0 lượng 9 chỉ | T6: 5 | U6: Giờ Thìn | V6: 0 lượng 9 chỉ | W6: 0.9
A7: Ất Sửu: 0 lượng 9 chỉ | B7: 6 | C7: Ất Sửu | D7: 0 lượng 9 chỉ | E7: 0.9 | G7: Tháng Sáu: 1 lượng 6 chỉ | H7: 6 | I7: Tháng Sáu | J7: 1 lượng 6 chỉ | K7: 1.6 | M7: Ngày mùng sáu: 1 lượng 5 chỉ | N7: 6 | O7: Ngày mùng sáu | P7: 1 lượng 5 chỉ | Q7: 1.5 | S7: Giờ Tỵ: 1 lượng 6 chỉ | T7: 6 | U7: Giờ Tỵ | V7: 1 lượng 6 chỉ | W7: 1.6
A8: Đinh Sửu: 0 lượng 8 chỉ | B8: 7 | C8: Đinh Sửu | D8: 0 lượng 8 chỉ | E8: 0.8 | G8: Tháng Bảy: 0 lượng 9 chỉ | H8: 7 | I8: Tháng Bảy | J8: 0 lượng 9 chỉ | K8: 0.9 | M8: Ngày mùng bảy: 0 lượng 8 chỉ | N8: 7 | O8: Ngày mùng bảy | P8: 0 lượng 8 chỉ | Q8: 0.8 | S8: Giờ Ngọ: 1 lượng 0 chỉ | T8: 7 | U8: Giờ Ngọ | V8: 1 lượng 0 chỉ | W8: 1
A9: Kỷ Sửu: 0 lượng 8 chỉ | B9: 8 | C9: Kỷ Sửu | D9: 0 lượng 8 chỉ | E9: 0.8 | G9: Tháng Tám: 1 lượng 5 chỉ | H9: 8 | I9: Tháng Tám | J9: 1 lượng 5 chỉ | K9: 1.5 | M9: Ngày mùng tám: 1 lượng 6 chỉ | N9: 8 | O9: Ngày mùng tám | P9: 1 lượng 6 chỉ | Q9: 1.6 | S9: Giờ Mùi: 0 lượng 8 chỉ | T9: 8 | U9: Giờ Mùi | V9: 0 lượng 8 chỉ | W9: 0.8
A10: Tân Sửu: 0 lượng 7 chỉ | B10: 9 | C10: Tân Sửu | D10: 0 lượng 7 chỉ | E10: 0.7 | G10: Tháng Chín: 1 lượng 8 chỉ | H10: 9 | I10: Tháng Chín | J10: 1 lượng 8 chỉ | K10: 1.8 | M10: Ngày mùng chín: 0 lượng 8 chỉ | N10: 9 | O10: Ngày mùng chín | P10: 0 lượng 8 chỉ | Q10: 0.8 | S10: Giờ Thân 0 lượng 8 chỉ | T10: 9 | U10: Giờ Thân | V10: 0 lượng 8 chỉ | W10: 0.8
A11: Quý Sửu: 0 lượng 5 chỉ | B11: 10 | C11: Quý Sửu | D11: 0 lượng 5 chỉ | E11: 0.5 | G11: Tháng Mười: 1 lượng 8 chỉ | H11: 10 | I11: Tháng Mười | J11: 1 lượng 8 chỉ | K11: 1.8 | M11: Ngày mùng mười: 1 lượng 6 chỉ | N11: 10 | O11: Ngày mùng mười | P11: 1 lượng 6 chỉ | Q11: 1.6 | S11: Giờ Dậu: 0 lượng 9 chỉ | T11: 10 | U11: Giờ Dậu | V11: 0 lượng 9 chỉ | W11: 0.9
A12: Bính Dần: 0 lượng 6 chỉ | B12: 11 | C12: Bính Dần | D12: 0 lượng 6 chỉ | E12: 0.6 | G12: Tháng Mười Một: 0 lượng 9 chỉ | H12: 11 | I12: Tháng Mười Một | J12: 0 lượng 9 chỉ | K12: 0.9 | M12: Ngày mười một: 0 lượng 9 chỉ | N12: 11 | O12: Ngày mười một | P12: 0 lượng 9 chỉ | Q12: 0.9 | S12: Giờ Tuất: 0 lượng 6 chỉ | T12: 11 | U12: Giờ Tuất | V12: 0 lượng 6 chỉ | W12: 0.6
A13: Mậu Dần: 0 lượng 8 chỉ | B13: 12 | C13: Mậu Dần | D13: 0 lượng 8 chỉ | E13: 0.8 | G13: Tháng Chạp: 0 lượng 5 chỉ | H13: 12 | I13: Tháng Chạp | J13: 0 lượng 5 chỉ | K13: 0.5 | M13: Ngày mười hai: 1 lượng 7 chỉ | N13: 12 | O13: Ngày mười hai | P13: 1 lượng 7 chỉ | Q13: 1.7 | S13: Giờ Hợi: 0 lượng 6 chỉ | T13: 12 | U13: Giờ Hợi | V13: 0 lượng 6 chỉ | W13: 0.6
A14: Canh Dần: 0 lượng 9 chỉ | B14: 13 | C14: Canh Dần | D14: 0 lượng 9 chỉ | E14: 0.9 | M14: Ngày mười ba: 0 lượng 8 chỉ | N14: 13 | O14: Ngày mười ba | P14: 0 lượng 8 chỉ | Q14: 0.8
A15: Nhâm Dần: 0 lượng 9 chỉ | B15: 14 | C15: Nhâm Dần | D15: 0 lượng 9 chỉ | E15: 0.9 | G15: Thời g | M15: Ngày mười bốn: 1 lượng 7 chỉ | N15: 14 | O15: Ngày mười bốn | P15: 1 lượng 7 chỉ | Q15: 1.7
A16: Giáp Dần: 1lượng 2 chỉ | B16: 15 | C16: Giáp Dần | D16: 1lượng 2 chỉ | E16: 0.9 | M16: Ngày rằm: 1 lượng 0 chỉ | N16: 15 | O16: Ngày mười năm | P16: 1 lượng 0 chỉ | Q16: 1
A17: Đinh Mão: 0 lượng 7 chỉ | B17: 16 | C17: Đinh Mão | D17: 0 lượng 7 chỉ | E17: 0.7 | M17: Ngày mười sáu: 0 lượng 8 chỉ | N17: 16 | O17: Ngày mười sáu | P17: 0 lượng 8 chỉ | Q17: 0.8
A18: Kỷ Mão: 1 lượng 9 chỉ | B18: 17 | C18: Kỷ Mão | D18: 1 lượng 9 chỉ | E18: 1.9 | M18: Ngày mười bảy: 0 lượng 9 chỉ | N18: 17 | O18: Ngày mười bảy | P18: 0 lượng 9 chỉ | Q18: 0.9
A19: Tân Mão: 1 lượng 2 chỉ | B19: 18 | C19: Tân Mão | D19: 1 lượng 2 chỉ | E19: 1.2 | M19: Ngày mười tám: 1 lượng 8 chỉ | N19: 18 | O19: Ngày mười tám | P19: 1 lượng 8 chỉ | Q19: 1.8
A20: Quý Mão: 1 lượng 2 chỉ | B20: 19 | C20: Quý Mão | D20: 1 lượng 2 chỉ | E20: 1.2 | M20: Ngày mười chín 0 lượng 5 chỉ | N20: 19 | O20: Ngày mười chín | P20: 0 lượng 5 chỉ | Q20: 0.5
A21: Ất Mão 0 lượng 8 chỉ | B21: 20 | C21: Ất Mão | D21: 0 lượng 8 chỉ | E21: 0.8 | M21: Ngày hai mươi: 1 lượng 5 chỉ | N21: 20 | O21: Ngày hai mươi | P21: 1 lượng 5 chỉ | Q21: 1.5
A22: Mậu Thìn: 1 lượng 2 chỉ | B22: 21 | C22: Mậu Thìn | D22: 1 lượng 2 chỉ | E22: 1.2 | M22: Ngày hai mươi mốt: 1 lượng 0 chỉ | N22: 21 | O22: Ngày hai mươi mốt | P22: 1 lượng 0 chỉ | Q22: 1
A23: Canh Thìn: 1 lượng 2 chỉ | B23: 22 | C23: Canh Thìn | D23: 1 lượng 2 chỉ | E23: 1.2 | M23: ngày hai mươi hai: 0 lượng 9 chỉ | N23: 22 | O23: ngày hai mươi hai | P23: 0 lượng 9 chỉ | Q23: 0.9
A24: Nhâm Thìn 1 lượng 0 chỉ | B24: 23 | C24: Nhâm Thìn | D24: 1 lượng 0 chỉ | E24: 1 | M24: Ngày hai mươi ba: 0 lượng 8 chỉ | N24: 23 | O24: Ngày hai mươi ba | P24: 0 lượng 8 chỉ | Q24: 0.8
A25: Giáp Thìn: 0 lượng 8 chỉ | B25: 24 | C25: Giáp Thìn | D25: 0 lượng 8 chỉ | E25: 0.8 | M25: Ngày hai mươi bốn: 0 lượng 9 chỉ | N25: 24 | O25: Ngày hai mươi bốn | P25: 0 lượng 9 chỉ | Q25: 0.9
A26: Bính Thìn: 0 lượng 8 chỉ | B26: 25 | C26: Bính Thìn | D26: 0 lượng 8 chỉ | E26: 0.8 | M26: Ngày hai mươi lăm: 1 lượng 5 chỉ | N26: 25 | O26: Ngày hai mươi lăm | P26: 1 lượng 5 chỉ | Q26: 1.5
A27: Kỷ Tỵ: 0 lượng 5 chỉ | B27: 26 | C27: Kỷ Tỵ | D27: 0 lượng 5 chỉ | E27: 0.5 | M27: Ngày hai mươi sáu: 1 lượng 8 chỉ | N27: 26 | O27: Ngày hai mươi sáu | P27: 1 lượng 8 chỉ | Q27: 1.8
... A29: Quý Tỵ: 0 lượng 7 chỉ | B29: 28 | C29: Quý Tỵ | D29: 0 lượng 7 chỉ | E29: 0.7 | M29: Ngày hai mươi tám: o lượng 8 chỉ | N29: 28 | O29: Ngày hai mươi tám | P29: 0 lượng 8 chỉ | Q29: 0.8
A30: Ất Tỵ: 0 lượng 7 chỉ | B30: 29 | C30: Ất Tỵ | D30: 0 lượng 7 chỉ | E30: 0.7 | G30: Tử v | M30: Ngày hai mươi chín: 1 lượng 6 chỉ | N30: 29 | O30: Ngày hai mươi chín | P30: 1 lượng 6 chỉ | Q30: 1.6
A31: Đinh Tỵ: 0 lượng 6 chỉ | B31: 30 | C31: Đinh Tỵ | D31: 0 lượng 6 chỉ | E31: 0.6 | M31: Ngày ba mươi: 0 lượng 6 chỉ | N31: 30 | O31: Ngày ba mươi | P31: 0 lượng 6 chỉ | Q31: 0.6
A32: Canh Ngọ: 0 lượng 9 chỉ | B32: 31 | C32: Canh Ngọ | D32: 0 lượng 9 chỉ | E32: 0.9
A33: Nhâm Ngọ: 0 lượng 8 chỉ | B33: 32 | C33: Nhâm Ngọ | D33: 0 lượng 8 chỉ | E33: 0.8 | M33: Sinh học
A34: Giáp Ngọ: 1 lượng 5 chỉ | B34: 33 | C34: Giáp Ngọ | D34: 1 lượng 5 chỉ | E34: 1.5
A35: Bính Ngọ: 1 lượng 3 chỉ | B35: 34 | C35: Bính Ngọ | D35: 1 lượng 3 chỉ | E35: 1.3
A36: Mậu Ngọ: 1 lượng 9 chỉ | B36: 35 | C36: Mậu Ngọ | D36: 1 lượng 9 chỉ | E36: 1.9
A37: Tân Mùi: 0 lượng 8 chỉ | B37: 36 | C37: Tân Mùi | D37: 0 lượng 8 chỉ | E37: 0.8
A38: Quý Mùi: 0 lượng 7 chỉ | B38: 37 | C38: Quý Mùi | D38: 0 lượng 7 chỉ | E38: 0.7
A39: Ất Mùi: 0 lượng 6 chỉ | B39: 38 | C39: Ất Mùi | D39: 0 lượng 6 chỉ | E39: 0.6
A40: Đinh Mùi: 0 lượng 5 chỉ | B40: 39 | C40: Đinh Mùi | D40: 0 lượng 5 chỉ | E40: 0.5
A41: Kỷ Mùi: 0 lượng 6 chỉ | B41: 40 | C41: Kỷ Mùi | D41: 0 lượng 6 chỉ | E41: 0.6
...

Sheet Màu Sắc Ngũ Hành
C2: Ngũ Hành | D2: Màu sắc | E2: Bảng màu
C3: Kim | D3: xám nhạt
C4: Mộc | D4: xanh
C5: Thủy | D5: đen
C6: Hỏa | D6: đỏ nhạt
C7: Thổ | D7: vàng

Sheet Xem Diễn biến vận hạn từng năm 

Sheet Định Hạn Trẻ Con(12 năm đầu)

Sheet Tính Tuổi Năm xem nằm Cung Nào

Sheet Trạng Thái M->H 14 Chính Tinh
A1: STT | B1: Nhóm chính tinh | C1: Sao Chính Tinh | D1: Miếu địa(M) | E1: Vượng Địa(V) | F1: Đắc Địa(Đ) | G1: Bình Hòa(B) | H1: Hãm Địa(H) | I1: Đặc Tính Sao | J1: Ý Nghĩa Sao | K1: Ngũ hành | L1: Đặc Tính Sao
A2: 1 | B2: Chòm Tử Vi | C2: Tử Vi | D2: Tỵ, Ngọ, Dần, Thân | E2: Thìn, Tuất | F2: Sửu, Mùi | G2: Hợi, Tý, Mão, Dậu | H2: Không có cung Hãm Địa | I2: Nam Bắc Đẩu Tinh | J2: (Đế Tinh) | K2: Dương Thổ(+)
A3: 2 | C3: Vũ Khúc | D3: Thìn, Tuất, Sửu, Mùi. | E3: Dần, Thân, Tý, Ngọ. | F3: Mão, Dậu. | G3: Không có cung Bình Hòa. | H3: Tỵ, Hợi. | I3: Bắc Đẩu Tinh | J3: (Tài Tinh) | K3: Âm Kim(-)
A4: 3 | C4: Liêm Trinh | D4: Thìn, Tuất. | E4: Tý, Ngọ, Dần, Thân. | F4: Sửu, Mùi. | G4: Không có cung Bình Hòa. | H4: Tỵ, Hợi, Mão, Dậu | I4: Bắc Đẩu Tinh | J4: (Tù Tinh) | K4: Âm Hỏa(-)
A5: 4 | C5: Thiên Phủ | D5: Dần, Thân, Tý, Ngọ. | E5: Thìn, Tuất. | F5: Tỵ, Hợi, Mùi. | G5: Mão, Dậu, Sửu. | H5: Không có cung Hãm Địa | I5: Nam Đẩu Tinh | J5: (Quyền Tinh, Tài Tinh) | K5: Âm Thổ(-)
A6: 5 | C6: Thái Âm | D6: Dậu, Tuất, Hợi. | E6: Thân, Tý. | F6: Sửu, Mùi. | G6: Không có cung Bình Hòa. | H6: Dần, Mão, Thìn, Tỵ, Ngọ. | I6: Bắc Đẩu Tinh | J6: (Phú Tinh) | K6: Âm Thủy(-)
A7: 6 | B7: Chòm Thiên Cơ | C7: Thiên Cơ | D7: Thìn, Tuất, Mão, Dậu. | E7: Tỵ, Thân. | F7: Tý, Ngọ, Sửu, Mùi. | G7: Không có cung Bình Hòa. | H7: Dần, Hợi. | I7: Nam Đẩu Tinh | J7: (Thiện Tinh) | K7: Âm Mộc(-)
A8: 7 | C8: Thái Dương | D8: Tỵ, Ngọ. | E8: Dần, Mão, Thìn. | F8: Sửu, Mùi. | G8: Không có cung Bình Hòa. | H8: Thận, Dậu, Tuất, Hợi, Tý. | I8: Nam Đẩu Tinh | J8: (QuýTinh) | K8: Dương Hỏa(+)
A9: 8 | C9: Thiên Đồng | D9: Dần, Thân. | E9: Tý. | F9: Mão,Tỵ, Hợi. | G9: Không có cung Bình Hòa. | H9: Ngọ, Dậu, Thìn, Tuất, Sửu, Mùi. | I9: Nam Đẩu Tinh | J9: (Phúc Tinh) | K9: Dương Thủy(+)
A10: 9 | C10: Cự Môn | D10: Mão, Dậu. | E10: Tý, Ngọ, Dần. | F10: Thận, Hợi. | G10: Không có cung Bình Hòa. | H10: Thìn, Tuất, Sửu, Mùi, Tỵ. | I10: Bắc Đẩu Tinh | J10: (Ám Tinh) | K10: Âm Thủy(-)
A11: 10 | B11: Chòm Thiên Tướng | C11: Thiên Tướng | D11: Dần, Thân. | E11: Thìn, Tuất, Tý, Ngọ. | F11: Sửu, Mùi, Tỵ, Hợi. | G11: Không có cung Bình Hòa. | H11: Mão, Dậu. | I11: Nam Đẩu Tinh | J11: (Quyền Tinh, Dũng Tinh) | K11: Dương Thủy(+)
A12: 11 | C12: Thiên Lương | D12: Ngọ, Thìn, Tuất. | E12: Tý, Mão, Dần, Thân. | F12: Sửu, Mùi. | G12: Không có cung Bình Hòa. | H12: Dậu, Tỵ, Hợi. | I12: Nam Đẩu Tinh | J12: (Thọ Tinh, ÁM Tinh) | K12: Âm Mộc(-)
A13: 12 | B13: Chòm Thất Sát | C13: Thất Sát | D13: Dần, Thân, Tý, Ngọ. | E13: TỴ, Hợi. | F13: Sửu, Mùi. | G13: Không có cung Bình Hòa. | H13: Mão, Dậu, Thìn, Tuất | I13: Nam Đẩu Tinh | J13: (Quyền Tinh, Dũng Tinh) | K13: Dương Kim (+)
A14: 13 | C14: Tham Lang | D14: Sửu, Mùi. | E14: Thìn, Tuất. | F14: Dần, Thân. | G14: Không có cung Bình Hòa. | H14: Tỵ, Hợi, Tý, Ngọ, Mão, Dậu. | I14: Bắc Đẩu Tinh | J14: (Hung Tinh, Dâm Tinh) | K14: Âm Thủy(-)
A15: 14 | C15: Phá Quân | D15: Tý, Ngọ. | E15: Sửu, Mùi. | F15: Thìn, Tuất. | G15: Không có cung Bình Hòa. | H15: Mão, Dậu, Dần, Thân, Tỵ, Hợi. | I15: Bắc Đẩu Tinh | J15: (Hung Tinh, Hao Tinh) | K15: Âm Thủy(-)
A18: Password | B18: Lá số Tử vi | C18: "Ngocanh sửa"

Sheet Trạng Thái Đắc Hãm, Ngũ hành 83
A1: STT | B1: Sao Cát tinh | C1: VỊ trí Miếu Địa(M) | D1: VỊ trí Vượng Địa(V) | E1: VỊ trí Đắc Địa(Đ) | F1: Vị Trí Bình Hòa | G1: Vị Trí Hãm Địa(H) | H1: Đặc Tính Sao | I1: Ý Nghĩa Sao | J1: Ngũ Hành Sao | K1: Sao Xấu | L1: VỊ trí Đắc Địa(Đ) | M1: Vị Trí Hãm Địa | N1: Đặc Tính Sao | O1: Ý Nghĩa Sao | P1: Ngũ Hành Sao | Q1: STT
A2: 1 | B2: Thiên Khôi | H2: Nam Đẩu Tinh | I2: Văn Tinh, Quý Tính | J2: Dương Hỏa Đới Kim | K2: Đại Hao | L2: Dần, Thân, Mão, Dậu. | M2: Tý, Sửu, Thìn, Tỵ, Ngọ, Mùi, Tuất, Hợi. | O2: Hao Tinh, Bại Tinh | P2: Hỏa | Q2: 47
A3: 2 | B3: Thiên Việt | H3: Nam Đẩu Tinh | I3: Văn Tinh, Quý Tính | J3: Âm Hỏa Đới Mộc | K3: Tiểu Hao | L3: Dần, Thân, Mão, Dậu. | M3: Tý, Sửu, Thìn, Tỵ, Ngọ, Mùi, Tuất, Hợi. | O3: Hao Tinh, Bại Tinh | P3: Hỏa | Q3: 48
A4: 3 | B4: Tả Phụ | H4: Bắc Đẩu Tinh | I4: Trợ Tinh, Phù Tinh | J4: Dương Thổ Đới Kim | K4: Đẩu Quân | O4: Hung Tinh | P4: Hỏa | Q4: 49
A5: 4 | B5: Hữu Bật | H5: Bắc Đẩu Tinh | I5: Trợ Tinh, Phù Tinh | J5: Dương Thủy Đới Thổ | K5: Lưu Hà | O5: Ác Tinh, Bại Tinh | P5: Thủy | Q5: 50
A6: 5 | B6: Hóa Quyền | D6: Tuất, Sửu, Mão. | E6: Thìn, Hợi, Tỵ, Ngọ, Dần, Mùi. | F6: Tý, Dậu, Thân. | I6: Văn Tinh, Phúc tinh, Quý Tinh | J6: Mộc Đới Thủy | K6: Hóa Kị | L6: Thìn, Tuất, Sửu, Mùi. | M6: Hợi, Dậu, Dần, Tỵ, Thân, Mão, Ngọ, Tý. | O6: Ám Tinh | P6: Thủy | Q6: 51
A7: 6 | B7: Hóa Khoa | D7: Thìn, Sửu, Tuất. | E7: Tý, Ngọ, Thân, Mùi, Dần, Hợi, Mão, Dậu, Tỵ | I7: Văn Tinh, Phúc tinh, Quý Tinh | J7: Mộc Đới Thủy | K7: Địa Không | L7: Dần, Thân, Tỵ, Hợi. | M7: Tý, Sửu, Mão, Thìn, Ngọ, Mùi, Dậu, Tuất. | O7: Sát Tinh | P7: Âm Hỏa | Q7: 52
A8: 7 | B8: Hóa Lộc | D8: Thìn, Sửu, Tuất. | E8: Mão, Dậu, Mùi, Thân, Dần, Hợi, Tỵ. | F8: TÝ, Ngọ. | I8: Văn Tinh, Phúc tinh, Quý Tinh | J8: Mộc Đới Thổ | K8: Địa Kiếp | L8: Dần, Thân, Tỵ, Hợi. | M8: Tý, Sửu, Mão, Thìn, Ngọ, Mùi, Dậu, Tuất. | O8: Sát Tinh | P8: Dương Hỏa | Q8: 53
A9: 8 | B9: Lực Sĩ | I9: Cát Tinh | J9: Hỏa | K9: Kình Dương | L9: Thìn, Tuất, Sửu, Mùi. | M9: Mão, Ngọ, Dậu, Tý, | N9: Bắc Đẩu Tinh | O9: Sát Tinh | P9: Dương Kim Đới Hỏa | Q9: 54
A10: 9 | B10: Lộc Tồn | C10: Tý, Mão, Ngọ, Dần. | E10: Tỵ, Hợi. | F10: Dậu, Thân. | H10: Bắc Đẩu Tinh | I10: Quý Tinh | J10: Dương Thổ Đới Thủy | K10: Đà La | L10: Thìn, Tuất, Sửu, Mùi. | M10: Dần, Tỵ, Thân, Hợi. | N10: Bắc Đẩu Tinh | O10: Sát Tinh | P10: Âm Kim Đới Hỏa | Q10: 55
A11: 10 | B11: Thiên Mã | E11: Tỵ, Dần. | G11: Thân, Hợi | J11: Hỏa | K11: Linh Tinh | L11: Dần, Mão, Thìn, Tỵ, Ngọ. | M11: Mùi, Thân, Dậu, Tuất, Hợi, Tý, Sửu | N11: Nam Đẩu Tinh | O11: Sát Tinh | P11: Âm Hỏa Đới Kim | Q11: 56
A12: 11 | B12: Hoa Cái | I12: Cát Tinh | J12: Kim | K12: Hỏa Tinh | L12: Dần, Mão, Thìn, Tỵ, Ngọ. | M12: Mùi, Thân, Dậu, Tuất, Hợi, Tý, Sửu | N12: Nam Đẩu Tinh | O12: Sát Tinh | P12: Dương Hỏa Đới Kim | Q12: 57
A13: 12 | B13: Thanh Long | I13: Thiện Tinh, Cát Tinh | J13: Thủy | K13: Quan Phù | O13: Hình Tinh, Hung Tinh, Bại Tinh | P13: Hỏa | Q13: 58
A14: 13 | B14: Long Trì | I14: Đài Các Tinh | J14: Thủy | K14: Quan phủ | O14: Hình Tinh, Hung Tinh, Bại Tinh | P14: Hỏa | Q14: 59
A15: 14 | B15: Phượng Các | I15: Đài Các Tinh | J15: Mộc Đới Thổ | K15: Phi Liêm | O15: Sát Tinh | P15: Hỏa | Q15: 60
A16: 15 | B16: Tấu Thư | I16: Văn Tinh | J16: Kim | K16: Bạch Hổ | L16: Dần, Thân, Mão, Dậu. | M16: Tý, Sửu, Thìn, Tỵ, Ngọ, Mùi, Tuất, Hợi. | O16: Sát Tinh, Bại Tinh | P16: Kim | Q16: 61
A17: 16 | B17: Văn Xương | C17: Tỵ, Dậu, Sửu | E17: Hợi, Tý, Thân, Thìn, Mùi, Mão | G17: Dần, Ngọ, Tuất | H17: Bắc Đẩu Tinh | I17: Văn Tinh | J17: Dương Kim Đới Thổ | K17: Tang Môn | L17: Dần, Thân, Mão, Dậu. | M17: Tý, Sửu, Thìn, Tỵ, Ngọ, Mùi, Tuất, Hợi. | O17: Bại Tinh | P17: Mộc | Q17: 62
A18: 17 | B18: Văn Khúc | C18: TÝ, Tỵ, Dậu, Sửu | D18: Hợi, Mùi | E18: Mão, Thân, Thìn | F18: Dần | G18: Ngọ, Tuất | H18: Nam Đẩu Tinh | I18: Văn Tinh | J18: Dương Thủy Đới Hỏa | K18: Cô Thần | O18: Ám Tinh | P18: Thổ | Q18: 63
A19: 18 | B19: Ln Văn Tinh | I19: Văn Tinh, Quý Tính | J19: Hỏa | K19: Quả Tú | O19: Ám Tinh | P19: Thổ | Q19: 64
A20: 19 | B20: Thiên Y | I20: Phúc Thiện, Cát Tinh | J20: Thủy | K20: Thiên Diêu | L20: Dần, Mão, Dậu, Tuất. | M20: Tý, Sửu, Thìn, Tị, Ngọ, Mùi, Thân, Hợi | O20: Dâm Tinh | P20: Thủy | Q20: 65
A21: 20 | B21: Ân Quang | I21: Phúc Thiện Tinh, Quý Tinh. | J21: Mộc | K21: Thiên Khốc | L21: TÝ, Ngọ, Mão, Dậu, Sửu, Mùi. | M21: Dần, Thân, Tỵ, Hợi, Thìn, Tuất. | O21: Bại Tinh | P21: Thủy | Q21: 66
A22: 21 | B22: Thiên Quý | I22: Phúc Thiện Tinh, Quý Tinh. | J22: Thổ | K22: Thiên Hư | L22: TÝ, Ngọ, Mão, Dậu, Sửu, Mùi. | M22: Dần, Thân, Tỵ, Hợi, Thìn, Tuất. | O22: Bại Tinh | P22: Thủy | Q22: 67
A23: 22 | B23: Tam Thai | I23: Quý Tinh, Trợ Tinh | J23: Thủy | K23: Thiên Thương | O23: Hung Tinh | P23: Thổ | Q23: 68
A24: 23 | B24: Bát Tọa | I24: Quý Tinh, Trợ Tinh | J24: Mộc | K24: Thiên Sứ | O24: Hung Tinh | P24: Thủy | Q24: 69
A25: 24 | B25: Thai Phụ | I25: Quý Tinh, Trợ Tinh | J25: Kim | K25: Thiên La | O25: Ám Tinh | P25: Thổ | Q25: 70
A26: 25 | B26: Phong Cáo | I26: Cát Tinh Trợ Tinh | J26: Thổ | K26: Địa Võng | O26: Ám Tinh | P26: Thổ | Q26: 71
A27: 26 | B27: Bác Sỹ | I27: Cát Tinh | J27: Thủy | K27: Thái Tuế | O27: Trung Tinh | P27: Hỏa | Q27: 72
A28: 27 | B28: Hỉ Thần | I28: Phúc Tinh, Hỷ Tinh | J28: Hỏa | K28: Tuế Phá | O28: Ám Tinh, Bại Tinh | P28: Hỏa | Q28: 73
A29: 28 | B29: Thiên Hỷ | I29: Thiện Tinh, Cát Tinh, Đào Hoa Tinh | J29: Thủy | K29: Phá Toái | O29: Hung Tinh, Hao Tinh | P29: Hỏa Đới Kim | Q29: 74
A30: 29 | B30: Đào Hoa | I30: Cát Tinh, Đào Hoa Tinh | J30: Mộc | K30: Thiên Không | O30: Bại Tinh, Hao Tinh | P30: Hỏa | Q30: 75
A31: 30 | B31: Hồng Loan | I31: Cát Tinh, Đào Hoa Tinh | J31: Thủy Đới Kim | K31: Kiếp Sát | O31: Hung Tinh, Ác Tinh. | P31: Hỏa | Q31: 76
A32: 31 | B32: Thiên Tài | I32: Phù Tinh, Ám Tinh | J32: Thổ | K32: Tử Phù | O32: Hung Tinh | P32: Hỏa | Q32: 77
A33: 32 | B33: Thiên Thọ | I33: Cát Tinh | J33: Thổ | K33: Trực Phù | O33: Hung Tinh | P33: Hỏa | Q33: 78
A34: 33 | B34: Thiên Đức | I34: Phúc Thiện, Cát Tinh | J34: Hỏa | K34: Bệnh Phù | O34: Bại Tinh, Hung Tinh | P34: Thổ Đới Mộc | Q34: 79
A35: 34 | B35: Nguyệt Đức | I35: Phúc Thiện, Cát Tinh | J35: Hỏa | K35: Điếu Khách | O35: Hung Tinh | P35: Hỏa | Q35: 80
A36: 35 | B36: Long Đức | I36: Quý Nhân, Cát Tinh | J36: Thủy
A37: 36 | B37: Phúc Đức | I37: Quý Nhân, Cát Tinh | J37: Thổ
A38: 37 | B38: Thiên Quan | I38: Phúc Thiện, Cát Tinh | J38: Hỏa
A39: 38 | B39: Thiên phúc | I39: Phúc Thiện, Cát Tinh | J39: Thổ
A40: 39 | B40: Thiên Giải | I40: Phúc Thiện, Cát Tinh | J40: Hỏa
...

Sheet Thứ Tự các Sao
A1: STT(Bên Trái) | B1: Sao Cát tinh | C1: Ngũ Hành Sao | D1: Sao Xấu | E1: Ngũ Hành Sao | F1: Ngũ Hành Sao | G1: STT | H1: STT(Bên Phải)
A2: 1 | B2: Thiên Khôi | C2: =+VLOOKUP(B2,'Trạng Thái Đắc Hãm, Ngũ hành 83'!B2:J50,9,0) -> Dương Hỏa Đới Kim | E2: Thái Tuế | G2: 47 | H2: 1
A3: 2 | B3: Thiên Việt | C3: =+VLOOKUP(B3,'Trạng Thái Đắc Hãm, Ngũ hành 83'!B3:J51,9,0) -> Âm Hỏa Đới Mộc | E3: Địa Không | G3: 48 | H3: 2
A4: 3 | B4: Tả Phụ | C4: =+VLOOKUP(B4,'Trạng Thái Đắc Hãm, Ngũ hành 83'!B4:J52,9,0) -> Dương Thổ Đới Kim | E4: Địa Kiếp | G4: 49 | H4: 3
A5: 4 | B5: Hữu Bật | C5: =+VLOOKUP(B5,'Trạng Thái Đắc Hãm, Ngũ hành 83'!B5:J53,9,0) -> Dương Thủy Đới Thổ | E5: Kình Dương | G5: 50 | H5: 4
A6: 5 | B6: Hóa Quyền | C6: =+VLOOKUP(B6,'Trạng Thái Đắc Hãm, Ngũ hành 83'!B6:J54,9,0) -> Mộc Đới Thủy | E6: Đà La | G6: 51 | H6: 5
A7: 6 | B7: Hóa Khoa | C7: =+VLOOKUP(B7,'Trạng Thái Đắc Hãm, Ngũ hành 83'!B7:J55,9,0) -> Mộc Đới Thủy | E7: Linh Tinh | G7: 52 | H7: 6
A8: 7 | B8: Hóa Lộc | C8: =+VLOOKUP(B8,'Trạng Thái Đắc Hãm, Ngũ hành 83'!B8:J56,9,0) -> Mộc Đới Thổ | E8: Hỏa Tinh | G8: 53 | H8: 7
A9: 8 | B9: Lộc Tồn | C9: =+VLOOKUP(B9,'Trạng Thái Đắc Hãm, Ngũ hành 83'!B9:J57,9,0) -> Dương Thổ Đới Thủy | E9: Hóa Kị | G9: 54 | H9: 8
A10: 9 | B10: Thiên Mã | C10: =+VLOOKUP(B10,'Trạng Thái Đắc Hãm, Ngũ hành 83'!B10:J58,9,0) -> Hỏa | E10: Bạch Hổ | G10: 55 | H10: 9
A11: 10 | B11: Văn Xương | C11: =+VLOOKUP(B11,'Trạng Thái Đắc Hãm, Ngũ hành 83'!B11:J59,9,0) -> Dương Kim Đới Thổ | E11: Thiên Hình | G11: 56 | H11: 10
A12: 11 | B12: Văn Khúc | C12: =+VLOOKUP(B12,'Trạng Thái Đắc Hãm, Ngũ hành 83'!B12:J60,9,0) -> Dương Thủy Đới Hỏa | E12: Kiếp Sát | G12: 57 | H12: 11
A13: 12 | B13: Hoa Cái | C13: =+VLOOKUP(B13,'Trạng Thái Đắc Hãm, Ngũ hành 83'!B13:J61,9,0) -> #N/A | E13: Thiên Không | G13: 58 | H13: 12
... A38: 37 | B38: Thiên Quan | C38: =+VLOOKUP(B38,'Trạng Thái Đắc Hãm, Ngũ hành 83'!B38:J86,9,0) -> Hỏa | E38: Trực Phù | G38: 83 | H38: 37
A39: 38 | B39: Thiên phúc | C39: =+VLOOKUP(B39,'Trạng Thái Đắc Hãm, Ngũ hành 83'!B39:J87,9,0) -> Thổ
A40: 39 | B40: Thiên Giải | C40: =+VLOOKUP(B40,'Trạng Thái Đắc Hãm, Ngũ hành 83'!B40:J88,9,0) -> Hỏa
A41: 40 | B41: Địa Giải | C41: =+VLOOKUP(B41,'Trạng Thái Đắc Hãm, Ngũ hành 83'!B41:J89,9,0) -> Thổ
A42: 41 | B42: Giải Thần | C42: =+VLOOKUP(B42,'Trạng Thái Đắc Hãm, Ngũ hành 83'!B42:J90,9,0) -> Mộc
A43: 42 | B43: Thiên Y | C43: =+VLOOKUP(B43,'Trạng Thái Đắc Hãm, Ngũ hành 83'!B43:J91,9,0) -> #N/A
A44: 43 | B44: Bác Sỹ | C44: =+VLOOKUP(B44,'Trạng Thái Đắc Hãm, Ngũ hành 83'!B44:J92,9,0) -> #N/A
A45: 44 | B45: Thiên Thọ | C45: =+VLOOKUP(B45,'Trạng Thái Đắc Hãm, Ngũ hành 83'!B45:J93,9,0) -> #N/A
A46: 45 | B46: Thiên Đức | C46: =+VLOOKUP(B46,'Trạng Thái Đắc Hãm, Ngũ hành 83'!B46:J94,9,0) -> #N/A
A47: 46 | B47: Thiên Trù | C47: =+VLOOKUP(B47,'Trạng Thái Đắc Hãm, Ngũ hành 83'!B47:J95,9,0) -> Thổ

Sheet An Lưu Đại Vận
A1: STT | B1: Can | C1: L. ĐVHoá Lộc | D1: L. ĐVHóa Quyền | E1: L. ĐVHóa Khoa | F1: L. ĐVHóa Kị
A2: 1 | B2: Giáp | C2: Liêm Trinh | D2: Phá Quân | E2: Vũ Khúc | F2: Thái Dương
A3: 2 | B3: Ất | C3: Thiên Cơ | D3: Thiên Lương | E3: Tử Vi | F3: Thái Âm
A4: 3 | B4: Bính | C4: Thiên Đồng | D4: Thiên Cơ | E4: Văn Xương | F4: Liêm Trinh
A5: 4 | B5: Đinh | C5: Thái Âm | D5: Thiên Đồng | E5: Thiên Cơ | F5: Cự Môn
A6: 5 | B6: Mậu | C6: Tham Lang | D6: Thái Âm | E6: Hữu Bật | F6: Thiên Cơ
A7: 6 | B7: Kỷ | C7: Vũ Khúc | D7: Tham Lang | E7: Thiên Lương | F7: Văn Khúc
A8: 7 | B8: Canh | C8: Thái Dương | D8: Vũ Khúc | E8: Thiên Đồng | F8: Thái Âm
A9: 8 | B9: Tân | C9: Cự Môn | D9: Thái Dương | E9: Văn Khúc | F9: Văn Xương
A10: 9 | B10: Nhâm | C10: Thiên Lương | D10: Tử Vi | E10: Thiên Phủ | F10: Vũ Khúc
A11: 10 | B11: Quý | C11: Phá Quân | D11: Cự Môn | E11: Thái Âm | F11: Tham Lang
A12: STT | B12: 11 Sao An | C12: 12 Can
C13: Giáp | D13: Ất | E13: Bính | F13: Đinh | G13: Mậu | H13: Kỷ | I13: Canh | J13: Tân | K13: Nhâm | L13: Quý
A14: 1 | B14: L. ĐVLộc Tồn | C14: Dần | D14: Mão | E14: Tỵ | F14: Ngọ | G14: Tỵ | H14: Ngọ | I14: Thân | J14: Dậu | K14: Hợi | L14: Tý
A15: 2 | B15: L. ĐVKình Dương | C15: Mão | D15: Thìn | E15: Ngọ | F15: Mùi | G15: Ngọ | H15: Mùi | I15: Dậu | J15: Tuất | K15: Tý | L15: Sửu
A16: 3 | B16: L. ĐVĐà La | C16: Sửu | D16: Dần | E16: Thìn | F16: Tỵ | G16: Thìn | H16: Tỵ | I16: Mùi | J16: Thân | K16: Tuất | L16: Hợi
A17: STT | B17: 18 Sao An | C17: Chi Năm
C18: TÝ | D18: Sửu | E18: Dần | F18: Mão | G18: Thìn | H18: Tỵ | I18: Ngọ | J18: Mùi | K18: Thân | L18: Dậu | M18: Tuất | N18: Hợi
A19: 4 | B19: L. ĐVThiên Mã | C19: Dần | D19: Hợi | E19: Thân | F19: Tỵ | G19: Dần | H19: Hợi | I19: Thân | J19: Tỵ | K19: Dần | L19: Hợi | M19: Thân | N19: Tỵ
A20: 5 | B20: L. ĐVThiên Khốc | C20: Ngọ | D20: Tỵ | E20: Thìn | F20: Mão | G20: Dần | H20: Sửu | I20: Tý | J20: Hợi | K20: Tuất | L20: Dậu | M20: Thân | N20: Mùi
A21: 6 | B21: L. ĐVThiên Hư | C21: Ngọ | D21: Mùi | E21: Thân | F21: Dậu | G21: Tuất | H21: Hợi | I21: Tý | J21: Sửu | K21: Dần | L21: Mão | M21: Thìn | N21: Tỵ
A23: 7 | B23: L. ĐVThái Tuế | C23: Lấy Năm An Đại Vận là năm An Sao L. ĐVThái Tuế
A24: 8 | B24: An 11 sao Lưu Đại Vận Chòm Thái Tuế | C24: Sau khi xác định được L. ĐVThái Tuế, an tiếp sao L. ĐV Thiếu Dương và các sao còn lại theo chiều thuận kim đồng hồ (cứ mỗi cung an 1 sao) theo thứ tự. Từ L. ĐVThái Tuế > L. ĐVThiếu Dương> L. ĐVTang Môn> L. ĐVThiếu Âm> L. ĐVQuan Phù >L. ĐVTử Phù>L. ĐVTuế Phá>L. ĐVLong Đức >L. ĐVBạch Hổ >L. ĐVPhúc Đức >L. ĐVĐiếu Khách >L. ĐVTrực Phù
A25: 9 | B25: An 11 sao Lưu Đại Vận Chòm Lộc Tồn | C25: Chòm Lộc Tồn: Sau Khi An Xong L. ĐVLộc Tồn thì an tiếp 11 sao Lưu Đại Vận Còn lại (cứ mỗi cung an 1 sao) theo Chiều Thuận Kim Đông Hồ(Dương Nam và Âm Nữ) và Chiều Nghịch Kim Đồng Hồ(Âm Nam và Dương Nữ). | R25: An Theo | S25: Chiều thuận (theo chiều kim đồng hồ): Áp dụng cho Dương Nam và Âm Nữ.
C26: L. ĐVLộc Tồn > L. ĐVLực Sĩ >L. ĐVThanh Long >L. ĐVTiểu Hao >L. ĐVTướng Quân > L. ĐVTấu Thư >L. ĐVPhi Liêm >L. ĐVHỉ Thần > L. ĐVBệnh Phù >L. ĐVĐại Hao >L. ĐVPhục Binh > L.Quan Phủ. | S26: Chiều nghịch (ngược chiều kim đồng hồ): Áp dụng cho Âm Nam và Dương Nữ.
A28: STT | B28: 11 Sao An | C28: 12 Can
C29: Giáp | D29: Ất | E29: Bính | F29: Đinh | G29: Mậu | H29: Kỷ | I29: Canh | J29: Tân | K29: Nhâm | L29: Quý
A30: 10 | B30: L. ĐVThiên Khôi | C30: Sửu | D30: Tý | E30: Hợi | F30: Hợi | G30: Sửu | H30: Tý | I30: Ngọ | J30: Ngọ | K30: Mão | L30: Mão
A31: 11 | B31: L. ĐVThiên Việt | C31: Mùi | D31: Thân | E31: Dậu | F31: Dậu | G31: Mùi | H31: Thân | I31: Dần | J31: Dần | K31: Tỵ | L31: Tỵ
A32: 12 | B32: L. ĐVLN Văn Tinh | C32: Tỵ | D32: Ngọ | E32: Thân | F32: Dậu | G32: Thân | H32: Dậu | I32: Hợi | J32: Tý | K32: Dần | L32: Mão
A36: 13 | B36: L. ĐVHồng Loan | C36: Mão | D36: Dần | E36: Sửu | F36: Tý | G36: Hợi | H36: Tuất | I36: Dậu | J36: Thân | K36: Mùi | L36: Ngọ | M36: Tỵ | N36: Thìn
A37: 14 | B37: L. ĐVThiên Hỷ | C37: Dậu | D37: Thân | E37: Mùi | F37: Ngọ | G37: Tỵ | H37: Thìn | I37: Mão | J37: Dần | K37: Sửu | L37: Tý | M37: Hợi | N37: Tuất
A38: 15 | B38: L. ĐVĐào Hoa | C38: Dậu | D38: Ngọ | E38: Mão | F38: Tý | G38: Dậu | H38: Ngọ | I38: Mão | J38: Tý | K38: Dậu | L38: Ngọ | M38: Mão | N38: Tý
A39: 16 | B39: L. ĐVCô Thần | C39: Dần | D39: Dần | E39: Tỵ | F39: Tỵ | G39: Tỵ | H39: Thân | I39: Thân | J39: Thân | K39: Hợi | L39: Hợi | M39: Hợi | N39: Dần
A40: 17 | B40: L. ĐVQuả Tú | C40: Tuất | D40: Tuất | E40: Sửu | F40: Sửu | G40: Sửu | H40: Thìn | I40: Thìn | J40: Thìn | K40: Mùi | L40: Mùi | M40: Mùi | N40: Tuất
A41: 18 | B41: L. ĐVKiếp Sát | C41: Tỵ | D41: Dần | E41: Hợi | F41: Thân | G41: Tỵ | H41: Dần | I41: Hợi | J41: Thân | K41: Tỵ | L41: Dần | M41: Hợi | N41: Thân
A42: 16 | B42: L. ĐVPhá Toái | C42: Tỵ | D42: Sửu | E42: Dậu | F42: Tỵ | G42: Sửu | H42: Dậu | I42: Tỵ | J42: Sửu | K42: Dậu | L42: Tỵ | M42: Sửu | N42: Dậu

Sheet An Sao Lưu
A1: STT | B1: Can | C1: L.Hoá Lộc | D1: L. Hóa Quyền | E1: L.Hóa Khoa | F1: L.Hóa Kị
A2: 1 | B2: Giáp | C2: Liêm Trinh | D2: Phá Quân | E2: Vũ Khúc | F2: Thái Dương
A3: 2 | B3: Ất | C3: Thiên Cơ | D3: Thiên Lương | E3: Tử Vi | F3: Thái Âm
A4: 3 | B4: Bính | C4: Thiên Đồng | D4: Thiên Cơ | E4: Văn Xương | F4: Liêm Trinh
A5: 4 | B5: Đinh | C5: Thái Âm | D5: Thiên Đồng | E5: Thiên Cơ | F5: Cự Môn
A6: 5 | B6: Mậu | C6: Tham Lang | D6: Thái Âm | E6: Hữu Bật | F6: Thiên Cơ
A7: 6 | B7: Kỷ | C7: Vũ Khúc | D7: Tham Lang | E7: Thiên Lương | F7: Văn Khúc
A8: 7 | B8: Canh | C8: Thái Dương | D8: Vũ Khúc | E8: Thiên Đồng | F8: Thái Âm
A9: 8 | B9: Tân | C9: Cự Môn | D9: Thái Dương | E9: Văn Khúc | F9: Văn Xương
A10: 9 | B10: Nhâm | C10: Thiên Lương | D10: Tử Vi | E10: Thiên Phủ | F10: Vũ Khúc
A11: 10 | B11: Quý | C11: Phá Quân | D11: Cự Môn | E11: Thái Âm | F11: Tham Lang
A12: STT | B12: 11 Sao An | C12: 12 Can
C13: Giáp | D13: Ất | E13: Bính | F13: Đinh | G13: Mậu | H13: Kỷ | I13: Canh | J13: Tân | K13: Nhâm | L13: Quý
A14: 1 | B14: L. Lộc Tồn | C14: Dần | D14: Mão | E14: Tỵ | F14: Ngọ | G14: Tỵ | H14: Ngọ | I14: Thân | J14: Dậu | K14: Hợi | L14: Tý
A15: 2 | B15: L. Kình Dương | C15: Mão | D15: Thìn | E15: Ngọ | F15: Mùi | G15: Ngọ | H15: Mùi | I15: Dậu | J15: Tuất | K15: Tý | L15: Sửu
A16: 3 | B16: L. Đà La | C16: Sửu | D16: Dần | E16: Thìn | F16: Tỵ | G16: Thìn | H16: Tỵ | I16: Mùi | J16: Thân | K16: Tuất | L16: Hợi
A17: STT | B17: 18 Sao An | C17: Chi Năm
C18: TÝ | D18: Sửu | E18: Dần | F18: Mão | G18: Thìn | H18: Tỵ | I18: Ngọ | J18: Mùi | K18: Thân | L18: Dậu | M18: Tuất | N18: Hợi
A19: 4 | B19: L. Thiên Mã | C19: Dần | D19: Hợi | E19: Thân | F19: Tỵ | G19: Dần | H19: Hợi | I19: Thân | J19: Tỵ | K19: Dần | L19: Hợi | M19: Thân | N19: Tỵ
A20: 5 | B20: L. Thiên Khốc | C20: Ngọ | D20: Tỵ | E20: Thìn | F20: Mão | G20: Dần | H20: Sửu | I20: Tý | J20: Hợi | K20: Tuất | L20: Dậu | M20: Thân | N20: Mùi
A21: 6 | B21: L. Thiên Hư | C21: Ngọ | D21: Mùi | E21: Thân | F21: Dậu | G21: Tuất | H21: Hợi | I21: Tý | J21: Sửu | K21: Dần | L21: Mão | M21: Thìn | N21: Tỵ
A23: 7 | B23: L. Thái Tuế | C23: Lấy Năm xem là năm An Sao L. Thái Tuế
A24: 8 | B24: An 11 sao Lưu Chòm Thái Tuế | C24: Sau khi xác định được Thái Tuế, an tiếp sao L Thiếu Dương và các sao còn lại theo chiều thuận kim đồng hồ (cứ mỗi cung an 1 sao) theo thứ tự. Từ L. Thái Tuế > L. Thiếu Dương> L. Tang Môn> L. Thiếu Âm> L. Quan Phù >L. Tử Phù>L. Tuế Phá>L. Long Đức >L. Bạch Hổ >L. Phúc Đức >L. Điếu Khách >L. Trực Phù
A25: 9 | B25: An 11 sao Lưu Chòm Lộc Tồn | C25: Chòm Lộc Tồn: Sau Khi An Xong L. Lộc Tồn thì an tiếp 11 sao Lưu Còn lại (cứ mỗi cung an 1 sao) theo Chiều Thuận Kim Đông Hồ(Dương Nam và Âm Nữ) và Chiều Nghịch Kim Đồng Hồ(Âm Nam và Dương Nữ). | R25: An Theo | S25: Chiều thuận (theo chiều kim đồng hồ): Áp dụng cho Dương Nam và Âm Nữ.
C26: L. Lộc Tồn > L. Lực Sĩ >L. Thanh Long >L.Tiểu Hao >L. Tướng Quân > L.Tấu Thư >L. Phi Liêm >L. Hỉ Thần > L. Bệnh Phù >L. Đại Hao >L. Phục Binh > L.Quan Phủ. | S26: Chiều nghịch (ngược chiều kim đồng hồ): Áp dụng cho Âm Nam và Dương Nữ.
A28: STT | B28: 11 Sao An | C28: 12 Can
C29: Giáp | D29: Ất | E29: Bính | F29: Đinh | G29: Mậu | H29: Kỷ | I29: Canh | J29: Tân | K29: Nhâm | L29: Quý
A30: 10 | B30: L. Thiên Khôi | C30: Sửu | D30: Tý | E30: Hợi | F30: Hợi | G30: Sửu | H30: Tý | I30: Ngọ | J30: Ngọ | K30: Mão | L30: Mão
A31: 11 | B31: L. Thiên Việt | C31: Mùi | D31: Thân | E31: Dậu | F31: Dậu | G31: Mùi | H31: Thân | I31: Dần | J31: Dần | K31: Tỵ | L31: Tỵ
A32: 12 | B32: LN Văn Tinh | C32: Tỵ | D32: Ngọ | E32: Thân | F32: Dậu | G32: Thân | H32: Dậu | I32: Hợi | J32: Tý | K32: Dần | L32: Mão
A36: 13 | B36: L. Hồng Loan | C36: Mão | D36: Dần | E36: Sửu | F36: Tý | G36: Hợi | H36: Tuất | I36: Dậu | J36: Thân | K36: Mùi | L36: Ngọ | M36: Tỵ | N36: Thìn
A37: 14 | B37: L. Thiên Hỷ | C37: Dậu | D37: Thân | E37: Mùi | F37: Ngọ | G37: Tỵ | H37: Thìn | I37: Mão | J37: Dần | K37: Sửu | L37: Tý | M37: Hợi | N37: Tuất
A38: 15 | B38: L. Đào Hoa | C38: Dậu | D38: Ngọ | E38: Mão | F38: Tý | G38: Dậu | H38: Ngọ | I38: Mão | J38: Tý | K38: Dậu | L38: Ngọ | M38: Mão | N38: Tý
A39: 16 | B39: L. Cô Thần | C39: Dần | D39: Dần | E39: Tỵ | F39: Tỵ | G39: Tỵ | H39: Thân | I39: Thân | J39: Thân | K39: Hợi | L39: Hợi | M39: Hợi | N39: Dần
A40: 17 | B40: L. Quả Tú | C40: Tuất | D40: Tuất | E40: Sửu | F40: Sửu | G40: Sửu | H40: Thìn | I40: Thìn | J40: Thìn | K40: Mùi | L40: Mùi | M40: Mùi | N40: Tuất
A41: 18 | B41: L. Kiếp Sát | C41: Tỵ | D41: Dần | E41: Hợi | F41: Thân | G41: Tỵ | H41: Dần | I41: Hợi | J41: Thân | K41: Tỵ | L41: Dần | M41: Hợi | N41: Thân
A42: 16 | B42: L. Phá Toái | C42: Tỵ | D42: Sửu | E42: Dậu | F42: Tỵ | G42: Sửu | H42: Dậu | I42: Tỵ | J42: Sửu | K42: Dậu | L42: Tỵ | M42: Sửu | N42: Dậu

Sheet An Tứ Hóa Theo Can Năm Sinh
A1: Can | B1: Lộc | C1: Quyền | D1: Khoa | E1: Kị | I1: Can | J1: L.Hoá Lộc | K1: L. Hóa Quyền | L1: L.Hóa Khoa | M1: L.Hóa Kị
A2: Giáp | B2: Liêm Trinh | C2: Phá Quân | D2: Vũ Khúc | E2: Thái Dương | I2: Giáp | J2: Liêm Trinh | K2: Phá Quân | L2: Vũ Khúc | M2: Thái Dương
A3: Ất | B3: Thiên Cơ | C3: Thiên Lương | D3: Tử Vi | E3: Thái Âm | G3: Tử Vi Đẩu Số toàn thư | I3: Ất | J3: Thiên Cơ | K3: Thiên Lương | L3: Tử Vi | M3: Thái Âm
A4: Bính | B4: Thiên Đồng | C4: Thiên Cơ | D4: Văn Xương | E4: Liêm Trinh | G4: - Mân phái (Thấu Thiên | I4: Bính | J4: Thiên Đồng | K4: Thiên Cơ | L4: Văn Xương | M4: Liêm Trinh
A5: Đinh | B5: Thái Âm | C5: Thiên Đồng | D5: Thiên Cơ | E5: Cự Môn | I5: Đinh | J5: Thái Âm | K5: Thiên Đồng | L5: Thiên Cơ | M5: Cự Môn
A6: Mậu | B6: Tham Lang | C6: Thái Âm | D6: Hữu Bật | E6: Thiên Cơ | I6: Mậu | J6: Tham Lang | K6: Thái Âm | L6: Hữu Bật | M6: Thiên Cơ
A7: Kỷ | B7: Vũ Khúc | C7: Tham Lang | D7: Thiên Lương | E7: Văn Khúc | I7: Kỷ | J7: Vũ Khúc | K7: Tham Lang | L7: Thiên Lương | M7: Văn Khúc
A8: Canh | B8: Thái Dương | C8: Vũ Khúc | D8: Thiên Đồng | E8: Thái Âm | I8: Canh | J8: Thái Dương | K8: Vũ Khúc | L8: Thiên Đồng | M8: Thái Âm
A9: Tân | B9: Cự Môn | C9: Thái Dương | D9: Văn Khúc | E9: Văn Xương | I9: Tân | J9: Cự Môn | K9: Thái Dương | L9: Văn Khúc | M9: Văn Xương
A10: Nhâm | B10: Thiên Lương | C10: Tử Vi | D10: Thiên Phủ | E10: Vũ Khúc | I10: Nhâm | J10: Thiên Lương | K10: Tử Vi | L10: Thiên Phủ | M10: Vũ Khúc
A11: Quý | B11: Phá Quân | C11: Cự Môn | D11: Thái Âm | E11: Tham Lang | I11: Quý | J11: Phá Quân | K11: Cự Môn | L11: Thái Âm | M11: Tham Lang
A14: Bảng anh Tứ Hóa theo các phái khác nhau để các bạn tham khảo.
A15: Thiên can | B15: - Tử vi đẩu số toàn tập | C15: - Tử Vi Đẩu Số toàn thư | D15: - Trung Châu phái Vương Đình Chi | E15: - Tử Vi Đẩu Số toàn thư.
B16: - Trung châu phái Lục Bân Triệu | C16: - Mân phái (Thấu Thiên) | E16: - Một số chi lưu thuộc Bắc Phái
B17: - Khâm Thiên môn
A18: Giáp | B18: Liêm Phá Vũ Dương | C18: Liêm Phá Vũ Dương | D18: Liêm Phá Vũ Dương | E18: Liêm Phá Vũ Dương
A19: Ất | B19: Cơ Lương Tử Âm | C19: Cơ Lương Tử Âm | D19: Cơ Lương Tử Âm | E19: Cơ Lương Tử Âm
A20: Bính | B20: Đồng Cơ Xương Liêm | C20: Đồng Cơ Xương Liêm | D20: Đồng Cơ Xương Liêm | E20: Đồng Cơ Xương Liêm
A21: Đinh | B21: Âm Đồng Cơ Cự | C21: Âm Đồng Cơ Cự | D21: Âm Đồng Cơ Cự | E21: Âm Đồng Cơ Cự
A22: Mậu | B22: Tham Âm Bật Cơ | C22: Tham Âm Bật Cơ | D22: Tham Âm Dương Cơ | E22: Tham Âm Bật Cơ
A23: Kỷ | B23: Vũ Tham Lương Khúc | C23: Vũ Tham Lương Khúc | D23: Vũ Tham Lương Khúc | E23: Vũ Tham Lương Khúc
A24: Canh | B24: Dương Vũ Âm Đồng | C24: Dương Vũ Đồng Âm | D24: Dương Vũ Phủ Đồng | E24: Dương Vũ Đồng Tướng
A25: Tân | B25: Cự Dương Khúc Xương | C25: Cự Dương Khúc Xương | D25: Cự Dương Khúc Xương | E25: Cự Dương Khúc Xương
A26: Nhâm | B26: Lương Tử Phụ Vũ | C26: Lương Tử Phủ Vũ | D26: Lương Tử Phủ Vũ | E26: Lương Tử Phụ Vũ
A27: Quý | B27: Phá Cự Âm Tham | C27: Phá Cự Âm Tham | D27: Phá Cự Âm Tham | E27: Phá Cự Âm Tham

Sheet An Phi Hóa tới Các Cung,Ý Nghĩa
A19: Phi hóa lộc
A20: Phi hóa quyền
A21: Phi hóa khoa
A22: Phi hóa kỵ
A24: Cung mệnh tự Hóa Lộc:
A25: Tự hóa, tức là can của bán cung khiến cho sao trong bản cung xảy ra hiện tượng tứ hóa. Phàm người cung mệnh có tự hóa, hầu hết không thế chịu được thử thách, hành sự chỉ nóng được có năm phút, hay tha thứ cho mình, luôn tim ra được một cái cớ để thoái thác. Cung mệnh tự Hóa Lộc là người có khẩu tài, nói chuyện có kĩ thuật, trắng đen gì nói cũng có lí, biết cách ứng phó, không bao giờ xúc phạm hay làm người khác phiền lòng; lịch sự và nhã nhặn, có chừng mực, có duyên với người chung quanh, không thô tục; có khiếu thường thức nghệ thuật, thông minh lanh lợi, khá đa tình, dễ bị cảm động, dễ khóc; y thực không thiếu, tiêu xài tiền rất nhanh, làm việc không chuyên tâm, thường hay quên những điều mình hứa hẹn với người khác. (Xin xem thêm mục liên quan trong chương 6)
A27: Cung mệnh phi Hóa Lộc nhập cung huynh đệ:
A28: Tình cảm với anh chị em khá tốt, có thể nhờ anh em giúp đỡ mà thành công, giao tế nhiều, có duyên với người chung quanh; đối với mọi người rất nhiệt tình, nhưng sẽ không nỗ lực vì người ta; cho người ta lợi ích nhưng không cầu báo đáp, rộng lượng và hào phóng; hướng ngoại, có nhiều cơ hội kiếm tiền, muốn làm ăn ở nơi đông đúc, thích hợp với những nghề nghiệp như nghệ thuật biểu diễn, ngành giải trí; sinh kế gia đình sung túc, cũng dễ bị người ta giật tiền, bể hụi.
A29: Cung mệnh phi Hóa Lộc nhập cung phu thê:
A30: Phối ngẫu là người thông minh, có trợ giúp cho sự nghiệp của mệnh tạo, sau kết hôn sự nghiệp của mệnh tạo khá thuận lợi; mệnh tạo trưởng thành sớm, rất duyên với người khác, nên cũng dê kết hôn sớm, có tình thâm với người phối ngẫu; mệnh tạo rất códuyên với người chung quanh. Nếu chuyển phi Hóa Kị nhập cung phúc đức, là muốn kết hôn nhưng không được thuận lợi hoặc hôn nhàn không thành.
A31: Cung mệnh phi Hóa Lộc nhập cung tử nữ:
A32: Nặng quan niệm gia đình, phần nhiều sau khi sinh con sẽ dễ kiếm tiền hơn; quan hệ với con cái rất tốt, rất thương yêu con cái, có thể được quý tử. Có thể mở tiệm hoặc kinh doanh bất động sản, cũng có thể hợp tác làm ăn (nhưng vẫn cần phải xem phối hợp với cung nô bộc, cung quan lộc ) dễ có đào hoa, năng lực tính dục tốt.
... A124: (Trung Châu Tử Vi – Tứ Hóa Phái- Nguyễn Anh Vũ Dịch, tập 1)

Sheet An Theo Giờ Sinh(6 Sao)
A1: Stt | B1: Giờ Sinh | C1: Văn Xương | D1: Văn Khúc | E1: Thai Phụ | F1: Phong Cáo | G1: Địa Không | H1: Địa Kiếp
A2: 1 | B2: Tý | C2: Tuất | D2: Thìn | E2: Ngọ | F2: Dần | G2: Hợi | H2: Hợi
A3: 2 | B3: Sửu | C3: Dậu | D3: Tỵ | E3: Mùi | F3: Mão | G3: Tuất | H3: Tý
A4: 3 | B4: Dần | C4: Thân | D4: Ngọ | E4: Thân | F4: Thìn | G4: Dậu | H4: Sửu
A5: 4 | B5: Mão | C5: Mùi | D5: Mùi | E5: Dậu | F5: Tỵ | G5: Thân | H5: Dần
A6: 5 | B6: Thìn | C6: Ngọ | D6: Thân | E6: Tuất | F6: Ngọ | G6: Mùi | H6: Mão
A7: 6 | B7: Tỵ | C7: Tỵ | D7: Dậu | E7: Hợi | F7: Mùi | G7: Ngọ | H7: Thìn
A8: 7 | B8: Ngọ | C8: Thìn | D8: Tuất | E8: Tý | F8: Thân | G8: Tỵ | H8: Tỵ
A9: 8 | B9: Mùi | C9: Mão | D9: Hợi | E9: Sửu | F9: Dậu | G9: Thìn | H9: Ngọ
A10: 9 | B10: Thân | C10: Dần | D10: Tý | E10: Dần | F10: Tuất | G10: Mão | H10: Mùi
A11: 10 | B11: Dậu | C11: Sửu | D11: Sửu | E11: Mão | F11: Hợi | G11: Dần | H11: Thân
A12: 11 | B12: Tuất | C12: TÝ | D12: Dần | E12: Thìn | F12: Tý | G12: Sửu | H12: Dậu
A13: 12 | B13: Hợi | C13: Hợi | D13: Mão | E13: Tỵ | F13: Sửu | G13: Tý | H13: Tuất

Sheet An Theo Tháng Sinh(7 Sao)
A1: Tháng Sinh | B1: Tả Phụ | C1: Hữu Bật | D1: Thiên Hình | E1: Thiên Riêu | F1: Thiên Y | G1: Thiên Giải | H1: Địa Giải
A2: 1 | B2: Thìn | C2: Tuất | D2: Dậu | E2: Sửu | F2: Sứu | G2: Thân | H2: Mùi
A3: 2 | B3: Tỵ | C3: Dậu | D3: Tuất | E3: Dần | F3: Dần | G3: Dậu | H3: Thân
A4: 3 | B4: Ngọ | C4: Thân | D4: Hợi | E4: Mão | F4: Mão | G4: Tuất | H4: Dậu
A5: 4 | B5: Mùi | C5: Mùi | D5: Tý | E5: Thìn | F5: Thìn | G5: Hợi | H5: Tuất
A6: 5 | B6: Thân | C6: Ngọ | D6: Sửu | E6: Tỵ | F6: Tỵ | G6: Tý | H6: Hợi
A7: 6 | B7: Dậu | C7: Tỵ | D7: Dần | E7: Ngọ | F7: Ngọ | G7: Sửu | H7: Tý
A8: 7 | B8: Tuất | C8: Thìn | D8: Mão | E8: Mùi | F8: Mùi | G8: Dần | H8: Sửu
A9: 8 | B9: Hợi | C9: Mão | D9: Thìn | E9: Thân | F9: Thân | G9: Mão | H9: Dần
A10: 9 | B10: Tý | C10: Dần | D10: Tỵ | E10: Dậu | F10: Dậu | G10: Thìn | H10: Mão
A11: 10 | B11: Sửu | C11: Sửu | D11: Ngọ | E11: Tuất | F11: Tuất | G11: TỴ | H11: Thìn
A12: 11 | B12: Dần | C12: Tý | D12: Mùi | E12: Hợi | F12: Hợi | G12: Ngọ | H12: Tỵ
A13: 12 | B13: Mão | C13: Hợi | D13: Thân | E13: Tý | F13: Tý | G13: Mùi | H13: Ngọ

Sheet An Chi Năm Sinh(18 Sao)
A1: STT | B1: 18 Sao An | C1: Chi Năm
C2: TÝ | D2: Sửu | E2: Dần | F2: Mão | G2: Thìn | H2: Tỵ | I2: Ngọ | J2: Mùi | K2: Thân | L2: Dậu | M2: Tuất | N2: Hợi
A3: 1 | B3: Long Trì | C3: Thìn | D3: Tỵ | E3: Ngọ | F3: Mùi | G3: Thân | H3: Dậu | I3: Tuất | J3: Hợi | K3: Tý | L3: Sửu | M3: Dần | N3: Mão
A4: 2 | B4: Phượng Các | C4: Tuất | D4: Dậu | E4: Thân | F4: Mùi | G4: Ngọ | H4: Tý | I4: Thìn | J4: Mão | K4: Dần | L4: Sửu | M4: Tý | N4: Hợi
A5: 3 | B5: Giải Thần | C5: Tuất | D5: Dậu | E5: Thân | F5: Mùi | G5: Ngọ | H5: Tỵ | I5: Thìn | J5: Mão | K5: Dần | L5: Sửu | M5: Tý | N5: Hợi
A6: 4 | B6: Thiên Khốc | C6: Ngọ | D6: Tỵ | E6: Thìn | F6: Mão | G6: Dần | H6: Sửu | I6: Tý | J6: Hợi | K6: Tuất | L6: Dậu | M6: Thân | N6: Mùi
A7: 5 | B7: Thiên Hư | C7: Ngọ | D7: Mùi | E7: Thân | F7: Dậu | G7: Tuất | H7: Hợi | I7: Tý | J7: Sửu | K7: Dần | L7: Mão | M7: Thìn | N7: Tỵ
A8: 6 | B8: Thiên Đức | C8: Dậu | D8: Tuất | E8: Hợi | F8: Tý | G8: Sửu | H8: Dần | I8: Mão | J8: Thìn | K8: Tỵ | L8: Ngọ | M8: Mùi | N8: Thân
A9: 7 | B9: Nguyệt Đức | C9: Tỵ | D9: Ngọ | E9: Mùi | F9: Thân | G9: Dậu | H9: Tuất | I9: Hợi | J9: Tý | K9: Sửu | L9: Dần | M9: Mão | N9: Thìn
A10: 8 | B10: Hồng Loan | C10: Mão | D10: Dần | E10: Sửu | F10: Tý | G10: Hợi | H10: Tuất | I10: Dậu | J10: Thân | K10: Mùi | L10: Ngọ | M10: Tỵ | N10: Thìn
A11: 9 | B11: Thiên Hỷ | C11: Dậu | D11: Thân | E11: Mùi | F11: Ngọ | G11: Tỵ | H11: Thìn | I11: Mão | J11: Dần | K11: Sửu | L11: Tý | M11: Hợi | N11: Tuất
A12: 10 | B12: Cô Thần | C12: Dần | D12: Dần | E12: Tỵ | F12: Tỵ | G12: Tỵ | H12: Thân | I12: Thân | J12: Thân | K12: Hợi | L12: Hợi | M12: Hợi | N12: Dần
A13: 11 | B13: Quả Tú | C13: Tuất | D13: Tuất | E13: Sửu | F13: Sửu | G13: Sửu | H13: Thìn | I13: Thìn | J13: Thìn | K13: Mùi | L13: Mùi | M13: Mùi | N13: Tuất
A14: 12 | B14: Đào Hoa | C14: Dậu | D14: Ngọ | E14: Mão | F14: Tý | G14: Dậu | H14: Ngọ | I14: Mão | J14: Tý | K14: Dậu | L14: Ngọ | M14: Mão | N14: Tý
... A20: 18 | B20: Long Đức | C20: Mùi | D20: Thân | E20: Dậu | F20: Tuất | G20: Hợi | H20: Tý | I20: Sửu | J20: Dần | K20: Mão | L20: Thìn | M20: Tỵ | N20: Ngọ

Sheet An Theo Can Năm Sinh(12 Sao)
A1: STT | B1: 11 Sao An | C1: 12 Can
C2: Giáp | D2: Ất | E2: Bính | F2: Đinh | G2: Mậu | H2: Kỷ | I2: Canh | J2: Tân | K2: Nhâm | L2: Quý
A3: 1 | B3: Lộc Tồn | C3: Dần | D3: Mão | E3: Tỵ | F3: Ngọ | G3: Tỵ | H3: Ngọ | I3: Thân | J3: Dậu | K3: Hợi | L3: Tý
A4: 2 | B4: Kình Dương | C4: Mão | D4: Thìn | E4: Ngọ | F4: Mùi | G4: Ngọ | H4: Mùi | I4: Dậu | J4: Tuất | K4: Tý | L4: Sửu
A5: 3 | B5: Đà La | C5: Sửu | D5: Dần | E5: Thìn | F5: Tỵ | G5: Thìn | H5: Tỵ | I5: Mùi | J5: Thân | K5: Tuất | L5: Hợi
A6: 4 | B6: Quốc Ấn | C6: Tuất | D6: Hợi | E6: Sửu | F6: Dần | G6: Sửu | H6: Dần | I6: Thìn | J6: Tỵ | K6: Mùi | L6: Thân
A7: 5 | B7: Đường Phù | C7: Mùi | D7: Thân | E7: Tuất | F7: Hợi | G7: Tuất | H7: Hợi | I7: Sửu | J7: Dần | K7: Thìn | L7: Tỵ
A8: 6 | B8: Thiên Khôi | C8: Sửu | D8: Tý | E8: Hợi | F8: Hợi | G8: Sửu | H8: Tý | I8: Ngọ | J8: Ngọ | K8: Mão | L8: Mão
A9: 7 | B9: Thiên Việt | C9: Mùi | D9: Thân | E9: Dậu | F9: Dậu | G9: Mùi | H9: Thân | I9: Dần | J9: Dần | K9: Tỵ | L9: Tỵ
A10: 8 | B10: Thiên Quan | C10: Mùi | D10: Thìn | E10: Tỵ | F10: Dần | G10: Mão | H10: Dậu | I10: Hợi | J10: Dậu | K10: Tuất | L10: Ngọ
A11: 9 | B11: Thiên Phúc | C11: Dậu | D11: Thân | E11: Tý | F11: Hợi | G11: Mão | H11: Dần | I11: Ngọ | J11: Tỵ | K11: Ngọ | L11: Tỵ
A12: 10 | B12: Lưu Hà | C12: Dậu | D12: Tuất | E12: Mùi | F12: Thìn | G12: Tỵ | H12: Ngọ | I12: Thân | J12: Mão | K12: Hợi | L12: Dần
A13: 11 | B13: Thiên Trù | C13: Tỵ | D13: Ngọ | E13: Tý | F13: Tỵ | G13: Ngọ | H13: Thân | I13: Dần | J13: Ngọ | K13: Dậu | L13: Tuất
A14: 12 | B14: LN Văn Tinh | C14: Tỵ | D14: Ngọ | E14: Thân | F14: Dậu | G14: Thân | H14: Dậu | I14: Hợi | J14: Tý | K14: Dần | L14: Mão
O20: 11
O21: 18
O22: 7
O23: 6
O24: 4
O25: =+SUM(O20:O24) -> 46
O26: =83-O25 -> 37

Sheet  An Đặc Biêt (36 Sao)
A1: STT | B1: Các Sao An | E1: Chòm Lộc Tồn | T1: An Theo | U1: Chiều thuận (theo chiều kim đồng hồ): Áp dụng cho Dương Nam và Âm Nữ.
A2: 1 | B2: Tiểu Hao | E2: Lộc Tồn > Lực Sĩ > Thanh Long > Tiểu Hao > Tướng Quân > Tấu Thư > Phi Liêm > Hỉ Thần > Bệnh Phù > Đại Hao > Phục Binh > Quan Phủ. | U2: Chiều nghịch (ngược chiều kim đồng hồ): Áp dụng cho Âm Nam và Dương Nữ.
A3: 2 | B3: Đại Hao
A4: 3 | B4: Thiếu Âm
A5: 4 | B5: Thiếu Dương
A6: 5 | B6: Thiên La | C6: Cung Thìn | E6: Chòm Thái Tuế | T6: An Theo | U6: Sau khi xác định được Thái Tuế, an tiếp 11 sao còn lại theo chiều thuận kim đồng hồ (cứ mỗi cung an 1 sao) theo thứ tự Từ Thái Tuế > Thiếu Dương> Tang Môn> Thiếu Âm> Quan Phù >Tử Phù> Tuế Phá> Long Đức > Bạch Hổ > Phúc Đức >Điếu Khách > Trực Phù
A7: 6 | B7: Địa Võng | C7: Cung Tuất | E7: Thái Tuế, Thiếu Dương, Tang Môn, Thiếu Âm, Quan Phù, Tử phù, Tuế Phá, Long Đức, Bạch Hổ, Phúc Đức, Điếu Khách và Trực Phù.
A8: 7 | B8: Thiên Thương | C8: Cung Nô Bộc
A9: 8 | B9: Thiên Sứ | C9: Cung Tật Ách
A10: 9 | B10: Bạch Hổ
A11: 10 | B11: Phi Liêm
A12: 11 | B12: Thanh Long
A13: 12 | B13: Ân Quang | C13: Xem Văn Xương ở cung nào kể cung ấy là mồng một, bắt đầu đếm theo chiều thuận Kim Đồng Hồ đến ngày sinh, lùi lại 1 cung an Ân Quang.
