Workbook
Name DayNumber: #REF!
Name DayNumber: #REF!
Name diff: INT(('Form Mẫu Lá Số Tử Vi(Admin)'!jd_DayNumber - 'Form Mẫu Lá Số Tử Vi(Admin)'!jd_a11) / 29)
Name diff: INT((jd_DayNumber - jd_a11) / 29)
Name dr: PI()/180
Name jd_a11: INT(IF(l_a11>=monthStart,DATE(Year-1,12,20)-TEXT(DATE(Year-1,12,20),"[$-0011042A]dd"),l_a11)+2415018.5)
Name jd_DayNumber: INT(#REF!+2415018.5)
Name jd_DayNumber: INT(#REF!+2415018.5)
Name l_a11: #REF!
Name l_a11: #REF!
Name LeapMonthDiff: #REF!
Name LeapMonthDiff: #REF!
Name LeapYear: #REF!
Name LeapYear: #REF!
Name listcheck: 'AN CÁC SAO CHÍNH TINH'!$AN:$AO
Name LunarDay: TEXT('Form Mẫu Lá Số Tử Vi(Admin)'!DayNumber,"[$-0011042A]dd")
Name LunarDay: TEXT(DayNumber,"[$-0011042A]dd")
Name LunarMonth: IF(AND(LeapYear,diff>=LeapMonthDiff),diff+10,diff+ 11)
Name LunarMonth2: TEXT(IF('Form Mẫu Lá Số Tử Vi(Admin)'!LunarMonth>12,MOD('Form Mẫu Lá Số Tử Vi(Admin)'!LunarMonth,12),'Form Mẫu Lá Số Tử Vi(Admin)'!LunarMonth),"00")
Name LunarMonth2: TEXT(IF(LunarMonth>12,MOD(LunarMonth,12),LunarMonth),"00")
Name monthStart: IF(EDATE(DayNumber,1)-TEXT(EDATE(DayNumber,1),"[$-0011042A]dd")+1>DayNumber,DayNumber-TEXT(DayNumber,"[$-0011042A]dd")+1,EDATE(DayNumber,1)-TEXT(EDATE(DayNumber,1),"[$-0011042A]dd")+1)
Name NAMLIST: #REF!
Name NAMLIST: #REF!
Name Year: #REF!
Name Year: #REF!

Sheet AN CÁC SAO CHÍNH TINH
E1: =CONCATENATE("THÁI TUẾ",J2,'TẠO LÁ SỐ'!$L$35,'TẠO LÁ SỐ'!L30) -> THÁI TUẾDẬU7THÂN | F1: =CONCATENATE("THÁNG-",'TẠO LÁ SỐ'!L35) -> THÁNG-7 | G1: =CONCATENATE("GIỜ-",'TẠO LÁ SỐ'!L30) -> GIỜ-THÂN | H1: =CONCATENATE($I$2,M85) -> QUÝTHAM LANG | I1: =CONCATENATE('TẠO LÁ SỐ'!$L$30,"-",'TẠO LÁ SỐ'!L35) -> THÂN-7 | J1: ='TẠO LÁ SỐ'!B1 -> 1993 | O1: =CONCATENATE('TẠO LÁ SỐ'!L38,'TẠO LÁ SỐ'!L30,'AN CÁC SAO CHÍNH TINH'!J2) -> ÂM NỮTHÂNDẬU | P1: =CONCATENATE(L43,M43,'TẠO LÁ SỐ'!$L$36) -> TẢ PHÙTuất6 | Q1: =CONCATENATE(L56,M56,'TẠO LÁ SỐ'!L36) -> VĂN XƯƠNGDần6 | Y1: =CONCATENATE('TẠO LÁ SỐ'!$L$37,'TẠO LÁ SỐ'!$G$1) -> NỮDẬU | Z1: ='TẠO LÁ SỐ'!M32 -> QUÝ DẬU | BA1: =BL1 -> #REF! | BB1: 1 | BF1: LƯU TIEUR HẠN | BG1: tháng sinh | BH1: giờ sinh | BI1: =VLOOKUP($AB$52,$M$3:$O$14,3,0) -> #REF! | BJ1: =BI1-VLOOKUP(BG2,$BA$16:$BB$27,2,0) -> #REF! | BK1: =IF(BJ1+VLOOKUP(BH2,$BE$3:$BG$14,2,0)>$O$14,VLOOKUP(BJ1+VLOOKUP(BH2,$BE$3:$BG$14,2,0),$G$3:$MF$14,9,0),BJ1+VLOOKUP(BH2,$BE$3:$BG$14,2,0)) -> #REF! | BL1: =VLOOKUP(BK1,$O$2:$Q$14,3,0) -> #REF! | BN1: ='TẠO LÁ SỐ'!L46 -> 2025 | BO1: =VLOOKUP(BN1,'NGŨ HÀNH'!$A:$I,4,0) -> Ất Tỵ | BP1: GIỜ KIM THIẾT | BQ1: TUẤT | BR1: NĂM SINH | BS1: THÁNG SINH | BT1: NGÀY SINH | BU1: GIỜ SINH | BV1: GIỚI TÍNH | BX1: NĂM | CA1: tháng | CB1: =$BQ$3 -> MÙI | CC1: 1 | CD1: =$BQ$4 -> SỬU | CE1: 1 | CF1: =$BQ$5 -> NGỌ | CG1: 1 | CJ1: AN MỆNH CHỦ | CT1: ='TẠO LÁ SỐ'!L38 -> ÂM NỮ | CU1: tính tháng trong năm xem | CV1: tháng sinh | CW1: giờ sinh | CZ1: =CU2 -> HỢI | DA1: 1 | DD1: =$CU$3 -> TỴ | DE1: =VALUE(0) -> 0
A2: GIỜ SINH-THÁNG SINH | B2: CUNG | C2: AN TẠI | D2: d | F2: =CONCATENATE('TẠO LÁ SỐ'!L39,'TẠO LÁ SỐ'!L36) -> KIM 4 CỤC6 | G2: =CONCATENATE('TẠO LÁ SỐ'!$L$38,"-",I2) -> ÂM NỮ-QUÝ | H2: =VLOOKUP($J$1,'NGŨ HÀNH'!$A:$I,4,0) -> Quý Dậu | I2: =VLOOKUP($J$1,'NGŨ HÀNH'!$A:$I,2,0) -> QUÝ | J2: =VLOOKUP($J$1,'NGŨ HÀNH'!$A:$I,3,0) -> DẬU | L2: CUNG | M2: AN TAIJ | N2: an các cung trong lá số | O2: =CONCATENATE(L3,M3,'TẠO LÁ SỐ'!L30) -> CUNG MỆNHTÝTHÂN | P2: =CONCATENATE(L44,M44,'TẠO LÁ SỐ'!$L$36) -> HỮU BẬTThìn6 | Q2: =CONCATENATE(L57,M57,'TẠO LÁ SỐ'!L36) -> VĂN KHÚCTÝ6 | R2: =CONCATENATE($L$3,$M$3,$J$2) -> CUNG MỆNHTÝDẬU | U2: TÍNH CHẤT | V2: SAO | W2: CUNG | Y2: =CONCATENATE('TẠO LÁ SỐ'!L37,'TẠO LÁ SỐ'!G1,'TẠO LÁ SỐ'!G2) -> NỮDẬUTỴ | Z2: =CONCATENATE('TẠO LÁ SỐ'!$L$38,'TẠO LÁ SỐ'!$L$39) -> ÂM NỮKIM 4 CỤC | AE2: TUẦN-TRIỆT | AF2: TUẦN-TRIỆT | AH2: TUỔI | AI2: NỮ | AJ2: NAM | AN2: tứ hóa | AO2: vượngđắc | AZ2: CUNG | BC2: =MAX($BG$3:$BG$14) -> #REF! | BE2: CUNG | BF2: =$AB$52 -> HỢI | BG2: ='TẠO LÁ SỐ'!L35 -> 7 | BH2: ='TẠO LÁ SỐ'!L30 -> THÂN | BI2: cách tính | BN2: ='TẠO LÁ SỐ'!M32 -> QUÝ DẬU | BO2: ='TẠO LÁ SỐ'!L38 -> ÂM NỮ | BP2: ='TẠO LÁ SỐ'!L37 -> NỮ | BQ2: =VLOOKUP(BQ1,$M$2:$O$14,3,0) -> #REF! | BR2: =VLOOKUP('TẠO LÁ SỐ'!L32,'NGŨ HÀNH'!$A:$I,3,0) -> DẬU | BS2: ='TẠO LÁ SỐ'!L35 -> 7 | BT2: =VLOOKUP('TẠO LÁ SỐ'!L36,LƯU!$CG$2:$CH$31,2,0) -> 6 | BU2: ='TẠO LÁ SỐ'!L30 -> THÂN | BV2: =IFERROR(VLOOKUP(CONCATENATE($BP$2," ",$BQ$6),LƯU!$BV$15:$BW$1048576,2,0),"") | BX2: TÝ | BY2: TUẤT | BZ2: =IF(CA2=$CB$1,$CC$1,BZ13+1) -> 9 | CA2: HỢI | CD2: =IF(CE2=$CD$1,$CE$1,CD13+1) -> 12 | CE2: TÝ | CF2: HỢI | CG2: =IF(CF2=$CF$1,$CG$1,CG13+1) -> 8 | CJ2: Mệnh Chủ được an theo Địa chi của Mệnh Cung, | CL2: năm | CM2: AN CHỦ MỆNH | CP2: NĂM | CQ2: AN CHỦ THÂN | CT2: TỪ CUNG TIỂU HẠN TRONG THIÊN BÀN | CU2: =$AB$52 -> HỢI | CV2: ='TẠO LÁ SỐ'!L35 -> 7 | CW2: ='TẠO LÁ SỐ'!L30 -> THÂN | CY2: =IF(CZ2=$CZ$1,$DA$1,CY13+1) -> 1 | CZ2: HỢI | DC2: TÝ | DD2: =IF($DC2=$DD$1,$DE$1,DD13+10) -> 70 | DE2: =IF($DC2=$DD$1,$DE$1,DE13-10) -> -70 | DG2: 1 | DH2: TÝ | DJ2: =CONCATENATE(DK2,DL2) -> TÝTÝ | DK2: TÝ | DL2: TÝ | DM2: TÝ | DO2: các sao | DR2: NĂM TUỔI | DS2: TÍNH HẠN
A3: TÝ-1 | B3: CUNG MỆNH | C3: DẦN | E3: =IF(LEFT($Z$1,FIND(" ",$Z$1)-1)=LEFT($P3,FIND(" ",$P3)-1),"LAI NHÂN CUNG","") | F3: =$O$4+10 -> #REF! | G3: =O14+10 -> #REF! | H3: =CONCATENATE(IF(LEN(IFERROR(VLOOKUP(N3,'TẠO LÁ SỐ'!$K$40:$M$40,3,0),""))=VALUE(8),CONCATENATE(IFERROR(VLOOKUP(N3,'TẠO LÁ SỐ'!$K$40:$M$40,3,0),""),M3),0),$J$2) -> 0DẬU | I3: =CONCATENATE("CUNG MỆNH",M3) -> CUNG MỆNHTÝ | J3: AN CÁC CUNG DỰA VÀO GIỜ SINH VÀ THÁNG SINH | K3: =MATCH($I$1,OFFSET('AN CÁC SAO CHÍNH TINH'!$A$1,'AN CÁC SAO CHÍNH TINH'!K2,0,1000000),0)+'AN CÁC SAO CHÍNH TINH'!K2 -> 105 | L3: {=INDEX($B:$B,K3)} -> CUNG MỆNH | M3: {=INDEX($C:$C,K3)} -> TÝ | N3: =L3 -> CUNG MỆNH | O3: =IF(OR('TẠO LÁ SỐ'!$L$38="DƯƠNG NAM",'TẠO LÁ SỐ'!$L$38="ÂM NỮ"),VLOOKUP('AN CÁC SAO CHÍNH TINH'!$N3,#REF!,2,0),VLOOKUP('AN CÁC SAO CHÍNH TINH'!$N3,#REF!,3,0)) -> #REF! | P3: =VLOOKUP(M3,$AB$20:$AC$34,2,0) -> Giáp Tý | Q3: =M3 -> TÝ | R3: =O3 -> #REF! | S3: =VLOOKUP(R3,$O$3:$Q$14,3,0) -> #REF! | U3: DƯƠNG NAMTHỦY 2 CỤC | V3: TRƯỜNG SINH | W3: THÂN | Z3: AN SAO VÒNG TRƯỜNG SINH | AA3: =MATCH($Z$2,OFFSET($U$1,'AN CÁC SAO CHÍNH TINH'!AA2,0,1000000),0)+'AN CÁC SAO CHÍNH TINH'!AA2 -> 159 | AB3: {=INDEX($W:$W,AA3)} -> TỴ | AC3: {=INDEX($V:$V,AA3)} -> TRƯỜNG SINH | AD3: =VLOOKUP(AB3,$M$3:$N$14,2,0) -> CUNG NÔ BỘC | AE3: TUẦN | AF3: TUẦN | AH3: 10 | AI3: KẾ ĐÔ - HÀNH THỔ | AJ3: LA HẦU - HÀNH KIM | AN3: Đ.V.HÓA QUYỀNTHÌN | AO3: Đ.V.HÓA QUYỀN-V | AR3: =CONCATENATE(AS3,AU3) -> TỬ VITÝ | AS3: TỬ VI | AT3: B | AU3: TÝ | AV3: =CONCATENATE(AS3," ",AT3) -> TỬ VI B | AX3: =CONCATENATE("L.",AN3) -> L.Đ.V.HÓA QUYỀNTHÌN | AY3: =CONCATENATE("L.",AO3) -> L.Đ.V.HÓA QUYỀN-V | AZ3: TÝ | BA3: =IF(AZ3=$BA$1,$BB$1,BA14+1) -> #REF! | BC3: =BD3+120 -> #REF! | BD3: =BG3 -> #REF! | BE3: TÝ | BG3: =VLOOKUP(BE3,$M$3:$O$14,3,0) -> #REF! | BH3: 0 | BP3: TỪ CUNG TUẤT KHỞI THUẬN ĐẾN NĂM SINH | BQ3: =VLOOKUP(BR2,$BX$2:$BY$13,2,0) -> MÙI | BX3: SỬU | BY3: HỢI | BZ3: =IF(CA3=$CB$1,$CC$1,BZ2+1) -> 10 | CA3: TUẤT | CD3: =IF(CE3=$CD$1,$CE$1,CD2+1) -> 1 | CE3: SỬU | CF3: TUẤT | CG3: =IF(CF3=$CF$1,$CG$1,CG2+1) -> 9 | CJ3: MỆNH CUNG / MỆNH CHỦ | CL3: TÝ | CM3: THAM LANG | CP3: TÝ | CQ3: LINH TINH | CT3: ĐẾM NGHỊCH ĐẾN THÁNG SINH | CU3: =VLOOKUP(CV2,$CY$2:$CZ$13,2,0) -> TỴ | CV3: =VLOOKUP(CU3,$M$3:$O$14,3,0) -> #REF! | CX3: =CW3+CV3 -> #REF! | CY3: =IF(CZ3=$CZ$1,$DA$1,CY2+1) -> 2 | CZ3: TUẤT | DC3: SỬU | DD3: =IF(DC3=$DD$1,$DE$1,DD2+10) -> 80 | DE3: =IF($DC3=$DD$1,$DE$1,DE2-10) -> -80 | DG3: 2 | DH3: SỬU | DJ3: =CONCATENATE(DK3,DL3) -> TÝSỬU | DK3: TÝ | DL3: SỬU | DM3: SỬU | DO3: ÂN QUANG | DR3: 1 | DS3: CUNG MỆNH | DT3: 1
A4: TÝ-2 | B4: CUNG MỆNH | C4: MÃO | E4: =IF(LEFT($Z$1,FIND(" ",$Z$1)-1)=LEFT($P4,FIND(" ",$P4)-1),"LAI NHÂN CUNG","") | F4: =O4+120 -> #REF! | G4: =G3+10 -> #REF! | H4: =CONCATENATE(IF(LEN(IFERROR(VLOOKUP(N4,'TẠO LÁ SỐ'!$K$40:$M$40,3,0),""))=VALUE(8),CONCATENATE(IFERROR(VLOOKUP(N4,'TẠO LÁ SỐ'!$K$40:$M$40,3,0),""),M4),0),$J$2) -> 0DẬU | J4: AN CÁC CUNG DỰA VÀO GIỜ SINH VÀ THÁNG SINH | K4: =MATCH($I$1,OFFSET('AN CÁC SAO CHÍNH TINH'!$A$1,'AN CÁC SAO CHÍNH TINH'!K3,0,1000000),0)+'AN CÁC SAO CHÍNH TINH'!K3 -> 249 | L4: {=INDEX($B:$B,K4)} -> CUNG PHỤ MẪU | M4: {=INDEX($C:$C,K4)} -> SỬU | N4: =L4 -> CUNG PHỤ MẪU | O4: =IF(OR('TẠO LÁ SỐ'!$L$38="DƯƠNG NAM",'TẠO LÁ SỐ'!$L$38="ÂM NỮ"),VLOOKUP('AN CÁC SAO CHÍNH TINH'!$N4,#REF!,2,0),VLOOKUP('AN CÁC SAO CHÍNH TINH'!$N4,#REF!,3,0)) -> #REF! | P4: =VLOOKUP(M4,$AB$20:$AC$34,2,0) -> Ất Sửu | Q4: =M4 -> SỬU | R4: =O14 -> #REF! | S4: =VLOOKUP(R4,$O$3:$Q$14,3,0) -> #REF! | U4: DƯƠNG NAMTHỦY 2 CỤC | V4: DƯỠNG | W4: MÙI | Z4: AN SAO VÒNG TRƯỜNG SINH | AA4: =MATCH($Z$2,OFFSET($U$1,'AN CÁC SAO CHÍNH TINH'!AA3,0,1000000),0)+'AN CÁC SAO CHÍNH TINH'!AA3 -> 160 | AB4: {=INDEX($W:$W,AA4)} -> THÌN | AC4: {=INDEX($V:$V,AA4)} -> DƯỠNG | AD4: =VLOOKUP(AB4,$M$3:$N$14,2,0) -> CUNG QUAN LỘC | AE4: TRIỆT | AF4: TRIỆT | AH4: 11 | AI4: VÂN HỚN - HÀNH HỎA | AJ4: THỔ TÚ - HÀNH THỔ | AN4: Đ.V.HÓA QUYỀNTUẤT | AO4: Đ.V.HÓA QUYỀN-V | AR4: =CONCATENATE(AS4,AU4) -> TỬ VISỬU | AS4: TỬ VI | AT4: Đ | AU4: SỬU | AV4: =CONCATENATE(AS4," ",AT4) -> TỬ VI Đ | AX4: =CONCATENATE("L.",AN4) -> L.Đ.V.HÓA QUYỀNTUẤT | AY4: =CONCATENATE("L.",AO4) -> L.Đ.V.HÓA QUYỀN-V | AZ4: SỬU | BA4: =IF(AZ4=$BA$1,$BB$1,BA3+1) -> #REF! | BC4: =BD4+120 -> #REF! | BD4: =BG4 -> #REF! | BE4: SỬU | BF4: 10 | BG4: =VLOOKUP(BE4,$M$3:$O$14,3,0) -> #REF! | BH4: -10 | BI4: =VLOOKUP($AB$52,$M$3:$O$14,3,0) -> #REF! | BJ4: =IF(BI4-VLOOKUP($BG$2,$BA$16:$BC$27,3,0)<0,BI4+VLOOKUP($BG$2,$BA$16:$BB$27,2,0),BI4-VLOOKUP($BG$2,$BA$16:$BC$27,3,0)) -> #REF! | BK4: =BJ4+VLOOKUP(BH2,$BE$3:$BH$14,4,0) -> #REF! | BL4: =IF(BK4>$O$4,VLOOKUP(BK4,$F$3:$M$14,8,0),VLOOKUP(BK4,$O$3:$Q$14,3,0)) -> #REF! | BP4: KHỞI NGHỊCH ĐẾN THÁNG SINH | BQ4: =VLOOKUP(BS2,$BZ$2:$CA$13,2,0) -> SỬU | BX4: DẦN | BY4: TÝ | BZ4: =IF(CA4=$CB$1,$CC$1,BZ3+1) -> 11 | CA4: DẬU | CD4: =IF(CE4=$CD$1,$CE$1,CD3+1) -> 2 | CE4: DẦN | CF4: DẬU | CG4: =IF(CF4=$CF$1,$CG$1,CG3+1) -> 10 | CJ4: TÝ.........THAM LANG | CL4: SỬU | CM4: CỰ MÔN | CP4: SỬU | CQ4: THIÊN TƯỚNG | CT4: THUẬN ĐẾN GIỜ SINH | CU4: =VLOOKUP(CONCATENATE($CU$3,$CW$2),$DJ$2:$DM$145,4,0) -> SỬU | CY4: =IF(CZ4=$CZ$1,$DA$1,CY3+1) -> 3 | CZ4: DẬU | DC4: DẦN | DD4: =IF(DC4=$DD$1,$DE$1,DD3+10) -> 90 | DE4: =IF($DC4=$DD$1,$DE$1,DE3-10) -> -90 | DG4: 3 | DH4: DẦN | DJ4: =CONCATENATE(DK4,DL4) -> TÝDẦN | DK4: TÝ | DL4: DẦN | DM4: DẦN | DO4: BÁC SỸ | DR4: 2 | DS4: CUNG TÀI BẠCH | DT4: 2
A5: TÝ-3 | B5: CUNG MỆNH | C5: THÌN | E5: =IF(LEFT($Z$1,FIND(" ",$Z$1)-1)=LEFT($P5,FIND(" ",$P5)-1),"LAI NHÂN CUNG","") | F5: =O5+120 -> #REF! | G5: =G4+10 -> #REF! | H5: =CONCATENATE(IF(LEN(IFERROR(VLOOKUP(N5,'TẠO LÁ SỐ'!$K$40:$M$40,3,0),""))=VALUE(8),CONCATENATE(IFERROR(VLOOKUP(N5,'TẠO LÁ SỐ'!$K$40:$M$40,3,0),""),M5),0),$J$2) -> 0DẬU | J5: AN CÁC CUNG DỰA VÀO GIỜ SINH VÀ THÁNG SINH | K5: =MATCH($I$1,OFFSET('AN CÁC SAO CHÍNH TINH'!$A$1,'AN CÁC SAO CHÍNH TINH'!K4,0,1000000),0)+'AN CÁC SAO CHÍNH TINH'!K4 -> 393 | L5: {=INDEX($B:$B,K5)} -> CUNG PHÚC ĐỨC | M5: {=INDEX($C:$C,K5)} -> DẦN | N5: =L5 -> CUNG PHÚC ĐỨC | O5: =IF(OR('TẠO LÁ SỐ'!$L$38="DƯƠNG NAM",'TẠO LÁ SỐ'!$L$38="ÂM NỮ"),VLOOKUP('AN CÁC SAO CHÍNH TINH'!$N5,#REF!,2,0),VLOOKUP('AN CÁC SAO CHÍNH TINH'!$N5,#REF!,3,0)) -> #REF! | P5: =VLOOKUP(M5,$AB$20:$AC$34,2,0) -> Giáp Dần | Q5: =M5 -> DẦN | R5: =O13 -> #REF! | S5: =VLOOKUP(R5,$O$3:$Q$14,3,0) -> #REF! | U5: DƯƠNG NAMTHỦY 2 CỤC | V5: THAI | W5: NGỌ | Z5: AN SAO VÒNG TRƯỜNG SINH | AA5: =MATCH($Z$2,OFFSET($U$1,'AN CÁC SAO CHÍNH TINH'!AA4,0,1000000),0)+'AN CÁC SAO CHÍNH TINH'!AA4 -> 161 | AB5: {=INDEX($W:$W,AA5)} -> MÃO | AC5: {=INDEX($V:$V,AA5)} -> THAI | AD5: =VLOOKUP(AB5,$M$3:$N$14,2,0) -> CUNG ĐIỀN TRẠCH | AH5: 12 | AI5: MỘC ĐỨC- HÀNH MỘC- HÀNH MỘC | AJ5: THỦY DIỆU - HÀNH THỦY | AN5: Đ.V.HÓA QUYỀNSỬU | AO5: Đ.V.HÓA QUYỀN-V | AR5: =CONCATENATE(AS5,AU5) -> TỬ VIDẦN | AS5: TỬ VI | AT5: M | AU5: DẦN | AV5: =CONCATENATE(AS5," ",AT5) -> TỬ VI M | AX5: =CONCATENATE("L.",AN5) -> L.Đ.V.HÓA QUYỀNSỬU | AY5: =CONCATENATE("L.",AO5) -> L.Đ.V.HÓA QUYỀN-V | AZ5: DẦN | BA5: =IF(AZ5=$BA$1,$BB$1,BA4+1) -> #REF! | BC5: =BD5+120 -> #REF! | BD5: =BG5 -> #REF! | BE5: DẦN | BF5: 20 | BG5: =VLOOKUP(BE5,$M$3:$O$14,3,0) -> #REF! | BH5: -20 | BP5: KHỞI THUẬN ĐẾN NGÀY SINH | BQ5: =VLOOKUP(BT2,$CD$2:$CE$13,2,0) -> NGỌ | BR5: =VLOOKUP(BQ5,$BE$3:$BG$14,3,0) -> #REF! | BS5: =IF(OR($BO$2="DƯƠNG NAM",$BO$2="ÂM NỮ"),VLOOKUP($BU$2,$BE$3:$BH$14,4,0),VLOOKUP($BU$2,$BE$3:$BF$14,2,0)) -> 40 | BT5: =BR5+BS5 -> #REF! | BX5: MÃO | BY5: SỬU | BZ5: =IF(CA5=$CB$1,$CC$1,BZ4+1) -> 12 | CA5: THÂN | CD5: =IF(CE5=$CD$1,$CE$1,CD4+1) -> 3 | CE5: MÃO | CF5: THÂN | CG5: =IF(CF5=$CF$1,$CG$1,CG4+1) -> 11 | CJ5: SỬU........CỰ | CL5: DẦN | CM5: LỘC TỒN | CP5: DẦN | CQ5: THIÊN LƯƠNG | CY5: =IF(CZ5=$CZ$1,$DA$1,CY4+1) -> 4 | CZ5: THÂN | DC5: MÃO | DD5: =IF(DC5=$DD$1,$DE$1,DD4+10) -> 100 | DE5: =IF($DC5=$DD$1,$DE$1,DE4-10) -> -100 | DG5: 4 | DH5: MÃO | DJ5: =CONCATENATE(DK5,DL5) -> TÝMÃO | DK5: TÝ | DL5: MÃO | DM5: MÃO | DO5: BẠCH HỔ | DR5: 3 | DS5: CUNG TẬT ÁCH | DT5: 3
A6: TÝ-4 | B6: CUNG MỆNH | C6: TỴ | E6: =IF(LEFT($Z$1,FIND(" ",$Z$1)-1)=LEFT($P6,FIND(" ",$P6)-1),"LAI NHÂN CUNG","") | F6: =O6+120 -> #REF! | G6: =G5+10 -> #REF! | H6: =CONCATENATE(IF(LEN(IFERROR(VLOOKUP(N6,'TẠO LÁ SỐ'!$K$40:$M$40,3,0),""))=VALUE(8),CONCATENATE(IFERROR(VLOOKUP(N6,'TẠO LÁ SỐ'!$K$40:$M$40,3,0),""),M6),0),$J$2) -> 0DẬU | J6: AN CÁC CUNG DỰA VÀO GIỜ SINH VÀ THÁNG SINH | K6: =MATCH($I$1,OFFSET('AN CÁC SAO CHÍNH TINH'!$A$1,'AN CÁC SAO CHÍNH TINH'!K5,0,1000000),0)+'AN CÁC SAO CHÍNH TINH'!K5 -> 537 | L6: {=INDEX($B:$B,K6)} -> CUNG ĐIỀN TRẠCH | M6: {=INDEX($C:$C,K6)} -> MÃO | N6: =L6 -> CUNG ĐIỀN TRẠCH | O6: =IF(OR('TẠO LÁ SỐ'!$L$38="DƯƠNG NAM",'TẠO LÁ SỐ'!$L$38="ÂM NỮ"),VLOOKUP('AN CÁC SAO CHÍNH TINH'!$N6,#REF!,2,0),VLOOKUP('AN CÁC SAO CHÍNH TINH'!$N6,#REF!,3,0)) -> #REF! | P6: =VLOOKUP(M6,$AB$20:$AC$34,2,0) -> Ất Mão | Q6: =M6 -> MÃO | R6: =O12 -> #REF! | S6: =VLOOKUP(R6,$O$3:$Q$14,3,0) -> #REF! | U6: DƯƠNG NAMTHỦY 2 CỤC | V6: TUYỆT | W6: TỴ | Z6: AN SAO VÒNG TRƯỜNG SINH | AA6: =MATCH($Z$2,OFFSET($U$1,'AN CÁC SAO CHÍNH TINH'!AA5,0,1000000),0)+'AN CÁC SAO CHÍNH TINH'!AA5 -> 162 | AB6: {=INDEX($W:$W,AA6)} -> DẦN | AC6: {=INDEX($V:$V,AA6)} -> TUYỆT | AD6: =VLOOKUP(AB6,$M$3:$N$14,2,0) -> CUNG PHÚC ĐỨC | AH6: 13 | AI6: THÁI ÂM- HÀNH THỦY | AJ6: THÁI BẠCH - HÀNH KIM | AN6: Đ.V.HÓA QUYỀNMÙI | AO6: Đ.V.HÓA QUYỀN-V | AR6: =CONCATENATE(AS6,AU6) -> TỬ VIMÃO | AS6: TỬ VI | AT6: B | AU6: MÃO | AV6: =CONCATENATE(AS6," ",AT6) -> TỬ VI B | AX6: =CONCATENATE("L.",AN6) -> L.Đ.V.HÓA QUYỀNMÙI | AY6: =CONCATENATE("L.",AO6) -> L.Đ.V.HÓA QUYỀN-V | AZ6: MÃO | BA6: =IF(AZ6=$BA$1,$BB$1,BA5+1) -> #REF! | BC6: =BD6+120 -> #REF! | BD6: =BG6 -> #REF! | BE6: MÃO | BF6: 30 | BG6: =VLOOKUP(BE6,$M$3:$O$14,3,0) -> #REF! | BH6: 90 | BP6: KHỞI NGHỊCH ĐẾN GIỜ SINH | BQ6: =IF(BT5>$BC$2,VLOOKUP(BT5,$BC$3:$BE$14,3,0),VLOOKUP(BT5,$BD$3:$BE$14,2,0)) -> #REF! | BX6: THÌN | BY6: DẦN | BZ6: =IF(CA6=$CB$1,$CC$1,BZ5+1) -> 1 | CA6: MÙI | CD6: =IF(CE6=$CD$1,$CE$1,CD5+1) -> 4 | CE6: THÌN | CF6: MÙI | CG6: =IF(CF6=$CF$1,$CG$1,CG5+1) -> 12 | CJ6: DẦN........LỘC TỒN | CL6: MÃO | CM6: VĂN KHÚC | CP6: MÃO | CQ6: THIÊN ĐỒNG | CY6: =IF(CZ6=$CZ$1,$DA$1,CY5+1) -> 5 | CZ6: MÙI | DC6: THÌN | DD6: =IF(DC6=$DD$1,$DE$1,DD5+10) -> 110 | DE6: =IF($DC6=$DD$1,$DE$1,DE5-10) -> -110 | DG6: 5 | DH6: THÌN | DJ6: =CONCATENATE(DK6,DL6) -> TÝTHÌN | DK6: TÝ | DL6: THÌN | DM6: THÌN | DO6: BÁT TỌA | DR6: 4 | DS6: CUNG PHU/THÊ | DT6: 4
A7: TÝ-5 | B7: CUNG MỆNH | C7: NGỌ | E7: =IF(LEFT($Z$1,FIND(" ",$Z$1)-1)=LEFT($P7,FIND(" ",$P7)-1),"LAI NHÂN CUNG","") | F7: =O7+120 -> #REF! | G7: =G6+10 -> #REF! | H7: =CONCATENATE(IF(LEN(IFERROR(VLOOKUP(N7,'TẠO LÁ SỐ'!$K$40:$M$40,3,0),""))=VALUE(8),CONCATENATE(IFERROR(VLOOKUP(N7,'TẠO LÁ SỐ'!$K$40:$M$40,3,0),""),M7),0),$J$2) -> ( THÂN )THÌNDẬU | J7: AN CÁC CUNG DỰA VÀO GIỜ SINH VÀ THÁNG SINH | K7: =MATCH($I$1,OFFSET('AN CÁC SAO CHÍNH TINH'!$A$1,'AN CÁC SAO CHÍNH TINH'!K6,0,1000000),0)+'AN CÁC SAO CHÍNH TINH'!K6 -> 681 | L7: {=INDEX($B:$B,K7)} -> CUNG QUAN LỘC | M7: {=INDEX($C:$C,K7)} -> THÌN | N7: =L7 -> CUNG QUAN LỘC | O7: =IF(OR('TẠO LÁ SỐ'!$L$38="DƯƠNG NAM",'TẠO LÁ SỐ'!$L$38="ÂM NỮ"),VLOOKUP('AN CÁC SAO CHÍNH TINH'!$N7,#REF!,2,0),VLOOKUP('AN CÁC SAO CHÍNH TINH'!$N7,#REF!,3,0)) -> #REF! | P7: =VLOOKUP(M7,$AB$20:$AC$34,2,0) -> Bính Thìn | Q7: =M7 -> THÌN | R7: =O11 -> #REF! | S7: =VLOOKUP(R7,$O$3:$Q$14,3,0) -> #REF! | U7: DƯƠNG NAMTHỦY 2 CỤC | V7: MỘ | W7: THÌN | Z7: AN SAO VÒNG TRƯỜNG SINH | AA7: =MATCH($Z$2,OFFSET($U$1,'AN CÁC SAO CHÍNH TINH'!AA6,0,1000000),0)+'AN CÁC SAO CHÍNH TINH'!AA6 -> 163 | AB7: {=INDEX($W:$W,AA7)} -> SỬU | AC7: {=INDEX($V:$V,AA7)} -> MỘ | AD7: =VLOOKUP(AB7,$M$3:$N$14,2,0) -> CUNG PHỤ MẪU | AH7: 14 | AI7: THỔ TÚ - HÀNH THỔ | AJ7: THÁI DƯƠNG - HÀNH HỎA | AN7: Đ.V.HÓA KHOADẦN | AO7: Đ.V.HÓA KHOA-Đ | AR7: =CONCATENATE(AS7,AU7) -> TỬ VITHÌN | AS7: TỬ VI | AT7: V | AU7: THÌN | AV7: =CONCATENATE(AS7," ",AT7) -> TỬ VI V | AX7: =CONCATENATE("L.",AN7) -> L.Đ.V.HÓA KHOADẦN | AY7: =CONCATENATE("L.",AO7) -> L.Đ.V.HÓA KHOA-Đ | AZ7: THÌN | BA7: =IF(AZ7=$BA$1,$BB$1,BA6+1) -> #REF! | BC7: =BD7+120 -> #REF! | BD7: =BG7 -> #REF! | BE7: THÌN | BF7: 40 | BG7: =VLOOKUP(BE7,$M$3:$O$14,3,0) -> #REF! | BH7: 80 | BX7: TỴ | BY7: MÃO | BZ7: =IF(CA7=$CB$1,$CC$1,BZ6+1) -> 2 | CA7: NGỌ | CD7: =IF(CE7=$CD$1,$CE$1,CD6+1) -> 5 | CE7: TỴ | CF7: NGỌ | CG7: =IF(CF7=$CF$1,$CG$1,CG6+1) -> 1 | CJ7: MÃO........VĂN KHÚC | CL7: THÌN | CM7: LIÊM TRINH | CP7: THÌN | CQ7: VĂN XƯƠNG | CY7: =IF(CZ7=$CZ$1,$DA$1,CY6+1) -> 6 | CZ7: NGỌ | DC7: TỴ | DD7: =IF(DC7=$DD$1,$DE$1,DD6+10) -> 0 | DE7: =IF($DC7=$DD$1,$DE$1,DE6-10) -> 0 | DG7: 6 | DH7: TỴ | DJ7: =CONCATENATE(DK7,DL7) -> TÝTỴ | DK7: TÝ | DL7: TỴ | DM7: TỴ | DO7: BỆNH PHÙ | DR7: 5 | DS7: CUNG PHÚC ĐỨC | DT7: 5
A8: TÝ-6 | B8: CUNG MỆNH | C8: MÙI | E8: =IF(LEFT($Z$1,FIND(" ",$Z$1)-1)=LEFT($P8,FIND(" ",$P8)-1),"LAI NHÂN CUNG","") | F8: =O8+120 -> #REF! | G8: =G7+10 -> #REF! | H8: =CONCATENATE(IF(LEN(IFERROR(VLOOKUP(N8,'TẠO LÁ SỐ'!$K$40:$M$40,3,0),""))=VALUE(8),CONCATENATE(IFERROR(VLOOKUP(N8,'TẠO LÁ SỐ'!$K$40:$M$40,3,0),""),M8),0),$J$2) -> 0DẬU | J8: AN CÁC CUNG DỰA VÀO GIỜ SINH VÀ THÁNG SINH | K8: =MATCH($I$1,OFFSET('AN CÁC SAO CHÍNH TINH'!$A$1,'AN CÁC SAO CHÍNH TINH'!K7,0,1000000),0)+'AN CÁC SAO CHÍNH TINH'!K7 -> 825 | L8: {=INDEX($B:$B,K8)} -> CUNG NÔ BỘC | M8: {=INDEX($C:$C,K8)} -> TỴ | N8: =L8 -> CUNG NÔ BỘC | O8: =IF(OR('TẠO LÁ SỐ'!$L$38="DƯƠNG NAM",'TẠO LÁ SỐ'!$L$38="ÂM NỮ"),VLOOKUP('AN CÁC SAO CHÍNH TINH'!$N8,#REF!,2,0),VLOOKUP('AN CÁC SAO CHÍNH TINH'!$N8,#REF!,3,0)) -> #REF! | P8: =VLOOKUP(M8,$AB$20:$AC$34,2,0) -> Đinh Tỵ | Q8: =M8 -> TỴ | R8: =O10 -> #REF! | S8: =VLOOKUP(R8,$O$3:$Q$14,3,0) -> #REF! | U8: DƯƠNG NAMTHỦY 2 CỤC | V8: TỬ | W8: MÃO | Z8: AN SAO VÒNG TRƯỜNG SINH | AA8: =MATCH($Z$2,OFFSET($U$1,'AN CÁC SAO CHÍNH TINH'!AA7,0,1000000),0)+'AN CÁC SAO CHÍNH TINH'!AA7 -> 164 | AB8: {=INDEX($W:$W,AA8)} -> TÝ | AC8: {=INDEX($V:$V,AA8)} -> TỬ | AD8: =VLOOKUP(AB8,$M$3:$N$14,2,0) -> CUNG MỆNH | AH8: 15 | AI8: LA HẦU - HÀNH KIM | AJ8: VÂN HỚN - HÀNH HỎA | AN8: Đ.V.HÓA KHOATHÂN | AO8: Đ.V.HÓA KHOA-Đ | AR8: =CONCATENATE(AS8,AU8) -> TỬ VITỴ | AS8: TỬ VI | AT8: M | AU8: TỴ | AV8: =CONCATENATE(AS8," ",AT8) -> TỬ VI M | AX8: =CONCATENATE("L.",AN8) -> L.Đ.V.HÓA KHOATHÂN | AY8: =CONCATENATE("L.",AO8) -> L.Đ.V.HÓA KHOA-Đ | AZ8: TỴ | BA8: =IF(AZ8=$BA$1,$BB$1,BA7+1) -> #REF! | BC8: =BD8+120 -> #REF! | BD8: =BG8 -> #REF! | BE8: TỴ | BF8: 50 | BG8: =VLOOKUP(BE8,$M$3:$O$14,3,0) -> #REF! | BH8: 70 | BX8: NGỌ | BY8: THÌN | BZ8: =IF(CA8=$CB$1,$CC$1,BZ7+1) -> 3 | CA8: TỴ | CD8: =IF(CE8=$CD$1,$CE$1,CD7+1) -> 6 | CE8: NGỌ | CF8: TỴ | CG8: =IF(CF8=$CF$1,$CG$1,CG7+1) -> 2 | CJ8: THÌN.......LIÊM | CL8: TỴ | CM8: VŨ KHÚC | CP8: TỴ | CQ8: THIÊN CƠ | CY8: =IF(CZ8=$CZ$1,$DA$1,CY7+1) -> 7 | CZ8: TỴ | DC8: NGỌ | DD8: =IF(DC8=$DD$1,$DE$1,DD7+10) -> 10 | DE8: =IF($DC8=$DD$1,$DE$1,DE7-10) -> -10 | DG8: 7 | DH8: NGỌ | DJ8: =CONCATENATE(DK8,DL8) -> TÝNGỌ | DK8: TÝ | DL8: NGỌ | DM8: NGỌ | DO8: CÔ THẦN | DR8: 6 | DS8: CUNG QUAN LỘC | DT8: 6
A9: TÝ-7 | B9: CUNG MỆNH | C9: THÂN | E9: =IF(LEFT($Z$1,FIND(" ",$Z$1)-1)=LEFT($P9,FIND(" ",$P9)-1),"LAI NHÂN CUNG","") | F9: =O9+120 -> #REF! | G9: =G8+10 -> #REF! | H9: =CONCATENATE(IF(LEN(IFERROR(VLOOKUP(N9,'TẠO LÁ SỐ'!$K$40:$M$40,3,0),""))=VALUE(8),CONCATENATE(IFERROR(VLOOKUP(N9,'TẠO LÁ SỐ'!$K$40:$M$40,3,0),""),M9),0),$J$2) -> 0DẬU | J9: AN CÁC CUNG DỰA VÀO GIỜ SINH VÀ THÁNG SINH | K9: =MATCH($I$1,OFFSET('AN CÁC SAO CHÍNH TINH'!$A$1,'AN CÁC SAO CHÍNH TINH'!K8,0,1000000),0)+'AN CÁC SAO CHÍNH TINH'!K8 -> 969 | L9: {=INDEX($B:$B,K9)} -> CUNG THIÊN DI | M9: {=INDEX($C:$C,K9)} -> NGỌ | N9: =L9 -> CUNG THIÊN DI | O9: =IF(OR('TẠO LÁ SỐ'!$L$38="DƯƠNG NAM",'TẠO LÁ SỐ'!$L$38="ÂM NỮ"),VLOOKUP('AN CÁC SAO CHÍNH TINH'!$N9,#REF!,2,0),VLOOKUP('AN CÁC SAO CHÍNH TINH'!$N9,#REF!,3,0)) -> #REF! | P9: =VLOOKUP(M9,$AB$20:$AC$34,2,0) -> Mậu Ngọ | Q9: =M9 -> NGỌ | R9: =O9 -> #REF! | S9: =VLOOKUP(R9,$O$3:$Q$14,3,0) -> #REF! | U9: DƯƠNG NAMTHỦY 2 CỤC | V9: BỆNH | W9: DẦN | Z9: AN SAO VÒNG TRƯỜNG SINH | AA9: =MATCH($Z$2,OFFSET($U$1,'AN CÁC SAO CHÍNH TINH'!AA8,0,1000000),0)+'AN CÁC SAO CHÍNH TINH'!AA8 -> 165 | AB9: {=INDEX($W:$W,AA9)} -> HỢI | AC9: {=INDEX($V:$V,AA9)} -> BỆNH | AD9: =VLOOKUP(AB9,$M$3:$N$14,2,0) -> CUNG HUYNH ĐỆ | AH9: 16 | AI9: THÁI DƯƠNG - HÀNH HỎA | AJ9: KẾ ĐÔ - HÀNH THỔ | AN9: Đ.V.HÓA KHOAHỢI | AO9: Đ.V.HÓA KHOA-Đ | AR9: =CONCATENATE(AS9,AU9) -> TỬ VINGỌ | AS9: TỬ VI | AT9: M | AU9: NGỌ | AV9: =CONCATENATE(AS9," ",AT9) -> TỬ VI M | AX9: =CONCATENATE("L.",AN9) -> L.Đ.V.HÓA KHOAHỢI | AY9: =CONCATENATE("L.",AO9) -> L.Đ.V.HÓA KHOA-Đ | AZ9: NGỌ | BA9: =IF(AZ9=$BA$1,$BB$1,BA8+1) -> #REF! | BC9: =BD9+120 -> #REF! | BD9: =BG9 -> #REF! | BE9: NGỌ | BF9: 60 | BG9: =VLOOKUP(BE9,$M$3:$O$14,3,0) -> #REF! | BH9: 60 | BX9: MÙI | BY9: TỴ | BZ9: =IF(CA9=$CB$1,$CC$1,BZ8+1) -> 4 | CA9: THÌN | CD9: =IF(CE9=$CD$1,$CE$1,CD8+1) -> 7 | CE9: MÙI | CF9: THÌN | CG9: =IF(CF9=$CF$1,$CG$1,CG8+1) -> 3 | CJ9: TỴ.........VŨ | CL9: NGỌ | CM9: PHÁ QUÂN | CP9: NGỌ | CQ9: HỎA TINH | CY9: =IF(CZ9=$CZ$1,$DA$1,CY8+1) -> 8 | CZ9: THÌN | DC9: MÙI | DD9: =IF(DC9=$DD$1,$DE$1,DD8+10) -> 20 | DE9: =IF($DC9=$DD$1,$DE$1,DE8-10) -> -20 | DG9: 8 | DH9: MÙI | DJ9: =CONCATENATE(DK9,DL9) -> TÝMÙI | DK9: TÝ | DL9: MÙI | DM9: MÙI | DO9: CỰ MÔN | DR9: 7 | DS9: CUNG NÔ BỘC | DT9: 7
A10: TÝ-8 | B10: CUNG MỆNH | C10: DẬU | E10: =IF(LEFT($Z$1,FIND(" ",$Z$1)-1)=LEFT($P10,FIND(" ",$P10)-1),"LAI NHÂN CUNG","") | F10: =O10+120 -> #REF! | G10: =G9+10 -> #REF! | H10: =CONCATENATE(IF(LEN(IFERROR(VLOOKUP(N10,'TẠO LÁ SỐ'!$K$40:$M$40,3,0),""))=VALUE(8),CONCATENATE(IFERROR(VLOOKUP(N10,'TẠO LÁ SỐ'!$K$40:$M$40,3,0),""),M10),0),$J$2) -> 0DẬU | J10: AN CÁC CUNG DỰA VÀO GIỜ SINH VÀ THÁNG SINH | K10: =MATCH($I$1,OFFSET('AN CÁC SAO CHÍNH TINH'!$A$1,'AN CÁC SAO CHÍNH TINH'!K9,0,1000000),0)+'AN CÁC SAO CHÍNH TINH'!K9 -> 1113 | L10: {=INDEX($B:$B,K10)} -> CUNG TẬT ÁCH | M10: {=INDEX($C:$C,K10)} -> MÙI | N10: =L10 -> CUNG TẬT ÁCH | O10: =IF(OR('TẠO LÁ SỐ'!$L$38="DƯƠNG NAM",'TẠO LÁ SỐ'!$L$38="ÂM NỮ"),VLOOKUP('AN CÁC SAO CHÍNH TINH'!$N10,#REF!,2,0),VLOOKUP('AN CÁC SAO CHÍNH TINH'!$N10,#REF!,3,0)) -> #REF! | P10: =VLOOKUP(M10,$AB$20:$AC$34,2,0) -> Kỷ Mùi | Q10: =M10 -> MÙI | R10: =O8 -> #REF! | S10: =VLOOKUP(R10,$O$3:$Q$14,3,0) -> #REF! | U10: DƯƠNG NAMTHỦY 2 CỤC | V10: SUY | W10: SỬU | Z10: AN SAO VÒNG TRƯỜNG SINH | AA10: =MATCH($Z$2,OFFSET($U$1,'AN CÁC SAO CHÍNH TINH'!AA9,0,1000000),0)+'AN CÁC SAO CHÍNH TINH'!AA9 -> 166 | AB10: {=INDEX($W:$W,AA10)} -> TUẤT | AC10: {=INDEX($V:$V,AA10)} -> SUY | AD10: =VLOOKUP(AB10,$M$3:$N$14,2,0) -> CUNG PHU/THÊ | AH10: 17 | AI10: THÁI BẠCH - HÀNH KIM | AJ10: THÁI ÂM- HÀNH THỦY | AN10: Đ.V.HÓA LỘCTHÌN | AO10: Đ.V.HÓA LỘC-V | AR10: =CONCATENATE(AS10,AU10) -> TỬ VIMÙI | AS10: TỬ VI | AT10: Đ | AU10: MÙI | AV10: =CONCATENATE(AS10," ",AT10) -> TỬ VI Đ | AX10: =CONCATENATE("L.",AN10) -> L.Đ.V.HÓA LỘCTHÌN | AY10: =CONCATENATE("L.",AO10) -> L.Đ.V.HÓA LỘC-V | AZ10: MÙI | BA10: =IF(AZ10=$BA$1,$BB$1,BA9+1) -> #REF! | BC10: =BD10+120 -> #REF! | BD10: =BG10 -> #REF! | BE10: MÙI | BF10: 70 | BG10: =VLOOKUP(BE10,$M$3:$O$14,3,0) -> #REF! | BH10: 50 | BX10: THÂN | BY10: NGỌ | BZ10: =IF(CA10=$CB$1,$CC$1,BZ9+1) -> 5 | CA10: MÃO | CD10: =IF(CE10=$CD$1,$CE$1,CD9+1) -> 8 | CE10: THÂN | CF10: MÃO | CG10: =IF(CF10=$CF$1,$CG$1,CG9+1) -> 4 | CJ10: NGỌ........PHÁ | CL10: MÙI | CM10: VŨ KHÚC | CP10: MÙI | CQ10: THIÊN TƯỚNG | CY10: =IF(CZ10=$CZ$1,$DA$1,CY9+1) -> 9 | CZ10: MÃO | DC10: THÂN | DD10: =IF(DC10=$DD$1,$DE$1,DD9+10) -> 30 | DE10: =IF($DC10=$DD$1,$DE$1,DE9-10) -> -30 | DG10: 9 | DH10: THÂN | DJ10: =CONCATENATE(DK10,DL10) -> TÝTHÂN | DK10: TÝ | DL10: THÂN | DM10: THÂN | DO10: ĐÀ LA | DR10: 8 | DS10: CUNG THIÊN DI | DT10: 8
A11: TÝ-9 | B11: CUNG MỆNH | C11: TUẤT | E11: =IF(LEFT($Z$1,FIND(" ",$Z$1)-1)=LEFT($P11,FIND(" ",$P11)-1),"LAI NHÂN CUNG","") | F11: =O11+120 -> #REF! | G11: =G10+10 -> #REF! | H11: =CONCATENATE(IF(LEN(IFERROR(VLOOKUP(N11,'TẠO LÁ SỐ'!$K$40:$M$40,3,0),""))=VALUE(8),CONCATENATE(IFERROR(VLOOKUP(N11,'TẠO LÁ SỐ'!$K$40:$M$40,3,0),""),M11),0),$J$2) -> 0DẬU | J11: AN CÁC CUNG DỰA VÀO GIỜ SINH VÀ THÁNG SINH | K11: =MATCH($I$1,OFFSET('AN CÁC SAO CHÍNH TINH'!$A$1,'AN CÁC SAO CHÍNH TINH'!K10,0,1000000),0)+'AN CÁC SAO CHÍNH TINH'!K10 -> 1257 | L11: {=INDEX($B:$B,K11)} -> CUNG TÀI BẠCH | M11: {=INDEX($C:$C,K11)} -> THÂN | N11: =L11 -> CUNG TÀI BẠCH | O11: =IF(OR('TẠO LÁ SỐ'!$L$38="DƯƠNG NAM",'TẠO LÁ SỐ'!$L$38="ÂM NỮ"),VLOOKUP('AN CÁC SAO CHÍNH TINH'!$N11,#REF!,2,0),VLOOKUP('AN CÁC SAO CHÍNH TINH'!$N11,#REF!,3,0)) -> #REF! | P11: =VLOOKUP(M11,$AB$20:$AC$34,2,0) -> Canh Thân | Q11: =M11 -> THÂN | R11: =O7 -> #REF! | S11: =VLOOKUP(R11,$O$3:$Q$14,3,0) -> #REF! | U11: DƯƠNG NAMTHỦY 2 CỤC | V11: ĐẾ VƯỢNG | W11: TÝ | Z11: AN SAO VÒNG TRƯỜNG SINH | AA11: =MATCH($Z$2,OFFSET($U$1,'AN CÁC SAO CHÍNH TINH'!AA10,0,1000000),0)+'AN CÁC SAO CHÍNH TINH'!AA10 -> 167 | AB11: {=INDEX($W:$W,AA11)} -> DẬU | AC11: {=INDEX($V:$V,AA11)} -> ĐẾ VƯỢNG | AD11: =VLOOKUP(AB11,$M$3:$N$14,2,0) -> CUNG TỬ TỨC | AH11: 18 | AI11: THỦY DIỆU - HÀNH THỦY | AJ11: MỘC ĐỨC- HÀNH MỘC | AN11: Đ.V.HÓA LỘCTUẤT | AO11: Đ.V.HÓA LỘC-V | AR11: =CONCATENATE(AS11,AU11) -> TỬ VITHÂN | AS11: TỬ VI | AT11: M | AU11: THÂN | AV11: =CONCATENATE(AS11," ",AT11) -> TỬ VI M | AX11: =CONCATENATE("L.",AN11) -> L.Đ.V.HÓA LỘCTUẤT | AY11: =CONCATENATE("L.",AO11) -> L.Đ.V.HÓA LỘC-V | AZ11: THÂN | BA11: =IF(AZ11=$BA$1,$BB$1,BA10+1) -> #REF! | BC11: =BD11+120 -> #REF! | BD11: =BG11 -> #REF! | BE11: THÂN | BF11: 80 | BG11: =VLOOKUP(BE11,$M$3:$O$14,3,0) -> #REF! | BH11: 40 | BX11: DẬU | BY11: MÙI | BZ11: =IF(CA11=$CB$1,$CC$1,BZ10+1) -> 6 | CA11: DẦN | CD11: =IF(CE11=$CD$1,$CE$1,CD10+1) -> 9 | CE11: DẬU | CF11: DẦN | CG11: =IF(CF11=$CF$1,$CG$1,CG10+1) -> 5 | CJ11: MÙI........VŨ | CL11: THÂN | CM11: LIÊM TRINH | CP11: THÂN | CQ11: THIÊN LƯƠNG | CY11: =IF(CZ11=$CZ$1,$DA$1,CY10+1) -> 10 | CZ11: DẦN | DC11: DẬU | DD11: =IF(DC11=$DD$1,$DE$1,DD10+10) -> 40 | DE11: =IF($DC11=$DD$1,$DE$1,DE10-10) -> -40 | DG11: 10 | DH11: DẬU | DJ11: =CONCATENATE(DK11,DL11) -> TÝDẬU | DK11: TÝ | DL11: DẬU | DM11: DẬU | DO11: ĐẠI HAO | DR11: 9 | DS11: CUNG TỬ TỨC | DT11: 9
A12: TÝ-10 | B12: CUNG MỆNH | C12: HỢI | E12: =IF(LEFT($Z$1,FIND(" ",$Z$1)-1)=LEFT($P12,FIND(" ",$P12)-1),"LAI NHÂN CUNG","") | F12: =O12+120 -> #REF! | G12: =G11+10 -> #REF! | H12: =CONCATENATE(IF(LEN(IFERROR(VLOOKUP(N12,'TẠO LÁ SỐ'!$K$40:$M$40,3,0),""))=VALUE(8),CONCATENATE(IFERROR(VLOOKUP(N12,'TẠO LÁ SỐ'!$K$40:$M$40,3,0),""),M12),0),$J$2) -> 0DẬU | J12: AN CÁC CUNG DỰA VÀO GIỜ SINH VÀ THÁNG SINH | K12: =MATCH($I$1,OFFSET('AN CÁC SAO CHÍNH TINH'!$A$1,'AN CÁC SAO CHÍNH TINH'!K11,0,1000000),0)+'AN CÁC SAO CHÍNH TINH'!K11 -> 1401 | L12: {=INDEX($B:$B,K12)} -> CUNG TỬ TỨC | M12: {=INDEX($C:$C,K12)} -> DẬU | N12: =L12 -> CUNG TỬ TỨC | O12: =IF(OR('TẠO LÁ SỐ'!$L$38="DƯƠNG NAM",'TẠO LÁ SỐ'!$L$38="ÂM NỮ"),VLOOKUP('AN CÁC SAO CHÍNH TINH'!$N12,#REF!,2,0),VLOOKUP('AN CÁC SAO CHÍNH TINH'!$N12,#REF!,3,0)) -> #REF! | P12: =VLOOKUP(M12,$AB$20:$AC$34,2,0) -> Tân Dậu | Q12: =M12 -> DẬU | R12: =O6 -> #REF! | S12: =VLOOKUP(R12,$O$3:$Q$14,3,0) -> #REF! | U12: DƯƠNG NAMTHỦY 2 CỤC | V12: LÂM QUAN | W12: HỢI | Z12: AN SAO VÒNG TRƯỜNG SINH | AA12: =MATCH($Z$2,OFFSET($U$1,'AN CÁC SAO CHÍNH TINH'!AA11,0,1000000),0)+'AN CÁC SAO CHÍNH TINH'!AA11 -> 168 | AB12: {=INDEX($W:$W,AA12)} -> THÂN | AC12: {=INDEX($V:$V,AA12)} -> LÂM QUAN | AD12: =VLOOKUP(AB12,$M$3:$N$14,2,0) -> CUNG TÀI BẠCH | AH12: 19 | AI12: KẾ ĐÔ - HÀNH THỔ | AJ12: LA HẦU - HÀNH KIM | AN12: Đ.V.HÓA LỘCSỬU | AO12: Đ.V.HÓA LỘC-V | AR12: =CONCATENATE(AS12,AU12) -> TỬ VIDẬU | AS12: TỬ VI | AT12: B | AU12: DẬU | AV12: =CONCATENATE(AS12," ",AT12) -> TỬ VI B | AX12: =CONCATENATE("L.",AN12) -> L.Đ.V.HÓA LỘCSỬU | AY12: =CONCATENATE("L.",AO12) -> L.Đ.V.HÓA LỘC-V | AZ12: DẬU | BA12: =IF(AZ12=$BA$1,$BB$1,BA11+1) -> #REF! | BC12: =BD12+120 -> #REF! | BD12: =BG12 -> #REF! | BE12: DẬU | BF12: 90 | BG12: =VLOOKUP(BE12,$M$3:$O$14,3,0) -> #REF! | BH12: 30 | BX12: TUẤT | BY12: THÂN | BZ12: =IF(CA12=$CB$1,$CC$1,BZ11+1) -> 7 | CA12: SỬU | CD12: =IF(CE12=$CD$1,$CE$1,CD11+1) -> 10 | CE12: TUẤT | CF12: SỬU | CG12: =IF(CF12=$CF$1,$CG$1,CG11+1) -> 6 | CJ12: THÂN.......LIÊM | CL12: DẬU | CM12: VĂN KHÚC | CP12: DẬU | CQ12: THIÊN ĐỒNG | CY12: =IF(CZ12=$CZ$1,$DA$1,CY11+1) -> 11 | CZ12: SỬU | DC12: TUẤT | DD12: =IF(DC12=$DD$1,$DE$1,DD11+10) -> 50 | DE12: =IF($DC12=$DD$1,$DE$1,DE11-10) -> -50 | DG12: 11 | DH12: TUẤT | DJ12: =CONCATENATE(DK12,DL12) -> TÝTUẤT | DK12: TÝ | DL12: TUẤT | DM12: TUẤT | DO12: ĐÀO HOA | DR12: 10 | DS12: CUNG HUYNH ĐỆ | DT12: 10
A13: TÝ-11 | B13: CUNG MỆNH | C13: TÝ | E13: =IF(LEFT($Z$1,FIND(" ",$Z$1)-1)=LEFT($P13,FIND(" ",$P13)-1),"LAI NHÂN CUNG","") | F13: =O13+120 -> #REF! | G13: =G12+10 -> #REF! | H13: =CONCATENATE(IF(LEN(IFERROR(VLOOKUP(N13,'TẠO LÁ SỐ'!$K$40:$M$40,3,0),""))=VALUE(8),CONCATENATE(IFERROR(VLOOKUP(N13,'TẠO LÁ SỐ'!$K$40:$M$40,3,0),""),M13),0),$J$2) -> 0DẬU | J13: AN CÁC CUNG DỰA VÀO GIỜ SINH VÀ THÁNG SINH | K13: =MATCH($I$1,OFFSET('AN CÁC SAO CHÍNH TINH'!$A$1,'AN CÁC SAO CHÍNH TINH'!K12,0,1000000),0)+'AN CÁC SAO CHÍNH TINH'!K12 -> 1545 | L13: {=INDEX($B:$B,K13)} -> CUNG PHU/THÊ | M13: {=INDEX($C:$C,K13)} -> TUẤT | N13: =L13 -> CUNG PHU/THÊ | O13: =IF(OR('TẠO LÁ SỐ'!$L$38="DƯƠNG NAM",'TẠO LÁ SỐ'!$L$38="ÂM NỮ"),VLOOKUP('AN CÁC SAO CHÍNH TINH'!$N13,#REF!,2,0),VLOOKUP('AN CÁC SAO CHÍNH TINH'!$N13,#REF!,3,0)) -> #REF! | P13: =VLOOKUP(M13,$AB$20:$AC$34,2,0) -> Nhâm Tuất | Q13: =M13 -> TUẤT | R13: =O5 -> #REF! | S13: =VLOOKUP(R13,$O$3:$Q$14,3,0) -> #REF! | U13: DƯƠNG NAMTHỦY 2 CỤC | V13: QUAN ĐỚI | W13: TUẤT | Z13: AN SAO VÒNG TRƯỜNG SINH | AA13: =MATCH($Z$2,OFFSET($U$1,'AN CÁC SAO CHÍNH TINH'!AA12,0,1000000),0)+'AN CÁC SAO CHÍNH TINH'!AA12 -> 169 | AB13: {=INDEX($W:$W,AA13)} -> MÙI | AC13: {=INDEX($V:$V,AA13)} -> QUAN ĐỚI | AD13: =VLOOKUP(AB13,$M$3:$N$14,2,0) -> CUNG TẬT ÁCH | AH13: 20 | AI13: VÂN HỚN - HÀNH HỎA | AJ13: THỔ TÚ - HÀNH THỔ | AN13: Đ.V.HÓA LỘCMÙI | AO13: Đ.V.HÓA LỘC-V | AR13: =CONCATENATE(AS13,AU13) -> TỬ VITUẤT | AS13: TỬ VI | AT13: V | AU13: TUẤT | AV13: =CONCATENATE(AS13," ",AT13) -> TỬ VI V | AX13: =CONCATENATE("L.",AN13) -> L.Đ.V.HÓA LỘCMÙI | AY13: =CONCATENATE("L.",AO13) -> L.Đ.V.HÓA LỘC-V | AZ13: TUẤT | BA13: =IF(AZ13=$BA$1,$BB$1,BA12+1) -> #REF! | BC13: =BD13+120 -> #REF! | BD13: =BG13 -> #REF! | BE13: TUẤT | BF13: 100 | BG13: =VLOOKUP(BE13,$M$3:$O$14,3,0) -> #REF! | BH13: 20 | BX13: HỢI | BY13: DẬU | BZ13: =IF(CA13=$CB$1,$CC$1,BZ12+1) -> 8 | CA13: TÝ | CD13: =IF(CE13=$CD$1,$CE$1,CD12+1) -> 11 | CE13: HỢI | CF13: TÝ | CG13: =IF(CF13=$CF$1,$CG$1,CG12+1) -> 7 | CJ13: DẬU........VĂN KHÚC | CL13: TUẤT | CM13: LỘC TỒN | CP13: TUẤT | CQ13: VĂN XƯƠNG | CY13: =IF(CZ13=$CZ$1,$DA$1,CY12+1) -> 12 | CZ13: TÝ | DC13: HỢI | DD13: =IF(DC13=$DD$1,$DE$1,DD12+10) -> 60 | DE13: =IF($DC13=$DD$1,$DE$1,DE12-10) -> -60 | DG13: 12 | DH13: HỢI | DJ13: =CONCATENATE(DK13,DL13) -> TÝHỢI | DK13: TÝ | DL13: HỢI | DM13: HỢI | DO13: ĐẨU QUÂN | DR13: 11 | DS13: CUNG PHỤ MẪU | DT13: 11
A14: TÝ-12 | B14: CUNG MỆNH | C14: SỬU | E14: =IF(LEFT($Z$1,FIND(" ",$Z$1)-1)=LEFT($P14,FIND(" ",$P14)-1),"LAI NHÂN CUNG","") -> LAI NHÂN CUNG | F14: =O14+120 -> #REF! | G14: =G13+10 -> #REF! | H14: =CONCATENATE(IF(LEN(IFERROR(VLOOKUP(N14,'TẠO LÁ SỐ'!$K$40:$M$40,3,0),""))=VALUE(8),CONCATENATE(IFERROR(VLOOKUP(N14,'TẠO LÁ SỐ'!$K$40:$M$40,3,0),""),M14),0),$J$2) -> 0DẬU | J14: AN CÁC CUNG DỰA VÀO GIỜ SINH VÀ THÁNG SINH | K14: =MATCH($I$1,OFFSET('AN CÁC SAO CHÍNH TINH'!$A$1,'AN CÁC SAO CHÍNH TINH'!K13,0,1000000),0)+'AN CÁC SAO CHÍNH TINH'!K13 -> 1689 | L14: {=INDEX($B:$B,K14)} -> CUNG HUYNH ĐỆ | M14: {=INDEX($C:$C,K14)} -> HỢI | N14: =L14 -> CUNG HUYNH ĐỆ | O14: =IF(OR('TẠO LÁ SỐ'!$L$38="DƯƠNG NAM",'TẠO LÁ SỐ'!$L$38="ÂM NỮ"),VLOOKUP('AN CÁC SAO CHÍNH TINH'!$N14,#REF!,2,0),VLOOKUP('AN CÁC SAO CHÍNH TINH'!$N14,#REF!,3,0)) -> #REF! | P14: =VLOOKUP(M14,$AB$20:$AC$34,2,0) -> Quý Hợi | Q14: =M14 -> HỢI | R14: =O4 -> #REF! | S14: =VLOOKUP(R14,$O$3:$Q$14,3,0) -> #REF! | U14: DƯƠNG NAMTHỦY 2 CỤC | V14: MỘC DỤC | W14: DẬU | Z14: AN SAO VÒNG TRƯỜNG SINH | AA14: =MATCH($Z$2,OFFSET($U$1,'AN CÁC SAO CHÍNH TINH'!AA13,0,1000000),0)+'AN CÁC SAO CHÍNH TINH'!AA13 -> 170 | AB14: {=INDEX($W:$W,AA14)} -> NGỌ | AC14: {=INDEX($V:$V,AA14)} -> MỘC DỤC | AD14: =VLOOKUP(AB14,$M$3:$N$14,2,0) -> CUNG THIÊN DI | AH14: 21 | AI14: MỘC ĐỨC- HÀNH MỘC | AJ14: THỦY DIỆU - HÀNH THỦY | AN14: Đ.V.HÓA LỘCDẦN | AO14: Đ.V.HÓA LỘC-V | AR14: =CONCATENATE(AS14,AU14) -> TỬ VIHỢI | AS14: TỬ VI | AT14: B | AU14: HỢI | AV14: =CONCATENATE(AS14," ",AT14) -> TỬ VI B | AX14: =CONCATENATE("L.",AN14) -> L.Đ.V.HÓA LỘCDẦN | AY14: =CONCATENATE("L.",AO14) -> L.Đ.V.HÓA LỘC-V | AZ14: HỢI | BA14: =IF(AZ14=$BA$1,$BB$1,BA13+1) -> #REF! | BC14: =BD14+120 -> #REF! | BD14: =BG14 -> #REF! | BE14: HỢI | BF14: 110 | BG14: =VLOOKUP(BE14,$M$3:$O$14,3,0) -> #REF! | BH14: 10 | CJ14: TUẤT.......LỘC TỒN | CL14: HỢI | CM14: CỰ MÔN | CP14: HỢI | CQ14: THIÊN CƠ | DJ14: =CONCATENATE(DK14,DL14) -> SỬUTÝ | DK14: SỬU | DL14: TÝ | DM14: SỬU | DO14: ĐỊA GIẢI | DR14: 12 | DS14: CUNG ĐIỀN TRẠCH | DT14: 12
A15: SỬU-1 | B15: CUNG MỆNH | C15: SỬU | U15: DƯƠNG NAMTHỔ 5 CỤC | V15: TRƯỜNG SINH | W15: THÂN | Z15: AN SAO VÒNG TRƯỜNG SINH | AA15: =MATCH($Z$2,OFFSET($U$1,'AN CÁC SAO CHÍNH TINH'!AA14,0,1000000),0)+'AN CÁC SAO CHÍNH TINH'!AA14 -> #N/A | AB15: {=INDEX($W:$W,AA15)} -> #N/A | AC15: {=INDEX($V:$V,AA15)} -> #N/A | AH15: 22 | AI15: THÁI ÂM- HÀNH THỦY | AJ15: THÁI BẠCH - HÀNH KIM | AN15: Đ.V.HÓA LỘCMÃO | AO15: Đ.V.HÓA LỘC-V | AR15: =CONCATENATE(AS15,AU15) -> LIÊM TRINHTHÌN | AS15: LIÊM TRINH | AT15: M | AU15: THÌN | AV15: =CONCATENATE(AS15," ",AT15) -> LIÊM TRINH M | AX15: =CONCATENATE("L.",AN15) -> L.Đ.V.HÓA LỘCMÃO | AY15: =CONCATENATE("L.",AO15) -> L.Đ.V.HÓA LỘC-V | CJ15: HỢI........CỰ | DJ15: =CONCATENATE(DK15,DL15) -> SỬUSỬU | DK15: SỬU | DL15: SỬU | DM15: DẦN | DO15: ĐỊA KHÔNG
A16: SỬU-2 | B16: CUNG MỆNH | C16: DẦN | I16: =IF(LEFT(RIGHT(L16,2))="-",LEFT(L16,LEN(L16)-LEN(RIGHT(L16,2))),L16) -> TỬ VI | J16: =CONCATENATE(L16,"-",M16) -> TỬ VI-TỴ | K16: =MATCH($F$2,OFFSET('AN CÁC SAO CHÍNH TINH'!$A$1,'AN CÁC SAO CHÍNH TINH'!K15,0,1000000),0)+'AN CÁC SAO CHÍNH TINH'!K15 -> 3236 | L16: {=INDEX($B:$B,K16)} -> TỬ VI | M16: {=INDEX($C:$C,K16)} -> TỴ | N16: =VLOOKUP(M16,$M$3:$N$14,2,0) -> CUNG NÔ BỘC | O16: CHÍNH TINH | U16: DƯƠNG NAMTHỔ 5 CỤC | V16: DƯỠNG | W16: MÙI | Z16: AN SAO VÒNG TRƯỜNG SINH | AA16: =MATCH($Z$2,OFFSET($U$1,'AN CÁC SAO CHÍNH TINH'!AA15,0,1000000),0)+'AN CÁC SAO CHÍNH TINH'!AA15 -> #N/A | AB16: {=INDEX($W:$W,AA16)} -> #N/A | AC16: {=INDEX($V:$V,AA16)} -> #N/A | AH16: 23 | AI16: THỔ TÚ - HÀNH THỔ | AJ16: THÁI DƯƠNG - HÀNH HỎA | AN16: Đ.V.HÓA KỴTHÌN | AO16: Đ.V.HÓA KỴ-Đ | AR16: =CONCATENATE(AS16,AU16) -> LIÊM TRINHTUẤT | AS16: LIÊM TRINH | AT16: M | AU16: TUẤT | AV16: =CONCATENATE(AS16," ",AT16) -> LIÊM TRINH M | AX16: =CONCATENATE("L.",AN16) -> L.Đ.V.HÓA KỴTHÌN | AY16: =CONCATENATE("L.",AO16) -> L.Đ.V.HÓA KỴ-Đ | AZ16: tháng | BA16: 1 | BB16: 0 | BC16: 0 | DJ16: =CONCATENATE(DK16,DL16) -> SỬUDẦN | DK16: SỬU | DL16: DẦN | DM16: MÃO | DO16: ĐỊA KIẾP
A17: SỬU-3 | B17: CUNG MỆNH | C17: MÃO | K17: =MATCH($F$2,OFFSET('AN CÁC SAO CHÍNH TINH'!$A$1,'AN CÁC SAO CHÍNH TINH'!K16,0,1000000),0)+'AN CÁC SAO CHÍNH TINH'!K16 -> #N/A | L17: {=INDEX($B:$B,K17)} -> #N/A | M17: {=INDEX($C:$C,K17)} -> #N/A | N17: =VLOOKUP(M17,$M$3:$N$14,2,0) -> #N/A | U17: DƯƠNG NAMTHỔ 5 CỤC | V17: THAI | W17: NGỌ | Z17: AN SAO VÒNG TRƯỜNG SINH | AA17: =MATCH($Z$2,OFFSET($U$1,'AN CÁC SAO CHÍNH TINH'!AA16,0,1000000),0)+'AN CÁC SAO CHÍNH TINH'!AA16 -> #N/A | AB17: {=INDEX($W:$W,AA17)} -> #N/A | AC17: {=INDEX($V:$V,AA17)} -> #N/A | AH17: 24 | AI17: LA HẦU - HÀNH KIM | AJ17: VÂN HỚN - HÀNH HỎA | AN17: Đ.V.HÓA KỴTUẤT | AO17: Đ.V.HÓA KỴ-Đ | AR17: =CONCATENATE(AS17,AU17) -> LIÊM TRINHTÝ | AS17: LIÊM TRINH | AT17: V | AU17: TÝ | AV17: =CONCATENATE(AS17," ",AT17) -> LIÊM TRINH V | AX17: =CONCATENATE("L.",AN17) -> L.Đ.V.HÓA KỴTUẤT | AY17: =CONCATENATE("L.",AO17) -> L.Đ.V.HÓA KỴ-Đ | BA17: 2 | BB17: 10 | BC17: 110 | DJ17: =CONCATENATE(DK17,DL17) -> SỬUMÃO | DK17: SỬU | DL17: MÃO | DM17: THÌN | DO17: ĐIẾU KHÁCH
A18: SỬU-4 | B18: CUNG MỆNH | C18: THÌN | N18: =VLOOKUP(M18,$M$3:$N$14,2,0) -> #N/A | U18: DƯƠNG NAMTHỔ 5 CỤC | V18: TUYỆT | W18: TỴ | AH18: 25 | AI18: THÁI DƯƠNG - HÀNH HỎA | AJ18: KẾ ĐÔ - HÀNH THỔ | AN18: Đ.V.HÓA KỴSỬU | AO18: Đ.V.HÓA KỴ-Đ | AR18: =CONCATENATE(AS18,AU18) -> LIÊM TRINHNGỌ | AS18: LIÊM TRINH | AT18: V | AU18: NGỌ | AV18: =CONCATENATE(AS18," ",AT18) -> LIÊM TRINH V | AX18: =CONCATENATE("L.",AN18) -> L.Đ.V.HÓA KỴSỬU | AY18: =CONCATENATE("L.",AO18) -> L.Đ.V.HÓA KỴ-Đ | BA18: 3 | BB18: 20 | BC18: 100 | DJ18: =CONCATENATE(DK18,DL18) -> SỬUTHÌN | DK18: SỬU | DL18: THÌN | DM18: TỴ | DO18: ĐƯỜNG PHÙ
A19: SỬU-5 | B19: CUNG MỆNH | C19: TỴ | N19: =VLOOKUP(M19,$M$3:$N$14,2,0) -> #N/A | U19: DƯƠNG NAMTHỔ 5 CỤC | V19: MỘ | W19: THÌN | AH19: 26 | AI19: THÁI BẠCH - HÀNH KIM | AJ19: THÁI ÂM- HÀNH THỦY | AN19: Đ.V.HÓA KỴMÙI | AO19: Đ.V.HÓA KỴ-Đ | AR19: =CONCATENATE(AS19,AU19) -> LIÊM TRINHDẦN | AS19: LIÊM TRINH | AT19: V | AU19: DẦN | AV19: =CONCATENATE(AS19," ",AT19) -> LIÊM TRINH V | AX19: =CONCATENATE("L.",AN19) -> L.Đ.V.HÓA KỴMÙI | AY19: =CONCATENATE("L.",AO19) -> L.Đ.V.HÓA KỴ-Đ | BA19: 4 | BB19: 30 | BC19: 90 | DJ19: =CONCATENATE(DK19,DL19) -> SỬUTỴ | DK19: SỬU | DL19: TỴ | DM19: NGỌ | DO19: GIẢI THẦN
A20: SỬU-6 | B20: CUNG MỆNH | C20: NGỌ | I20: =IF(LEFT(RIGHT(L20,2))="-",LEFT(L20,LEN(L20)-LEN(RIGHT(L20,2))),L20) -> LIÊM TRINH | J20: AN CHÍNH TINH DỰA VÀO SAO TỬ VI | K20: =MATCH($J$16,OFFSET('AN CÁC SAO CHÍNH TINH'!$A$1,'AN CÁC SAO CHÍNH TINH'!K19,0,1000000),0)+'AN CÁC SAO CHÍNH TINH'!K19 -> 3326 | L20: {=INDEX($B:$B,K20)} -> LIÊM TRINH | M20: {=INDEX($C:$C,K20)} -> Dậu | N20: =VLOOKUP(M20,$M$3:$N$14,2,0) -> CUNG TỬ TỨC | O20: CHÍNH TINH | U20: DƯƠNG NAMTHỔ 5 CỤC | V20: TỬ | W20: MÃO | Z20: AN TÊN CÁC CUNG AN TRONG NĂM SINH | AA20: =MATCH($Z$1,OFFSET($U$1,'AN CÁC SAO CHÍNH TINH'!AA19,0,1000000),0)+'AN CÁC SAO CHÍNH TINH'!AA19 -> 387 | AB20: {=INDEX($W:$W,AA20)} -> DẦN | AC20: {=INDEX($V:$V,AA20)} -> Giáp Dần | AH20: 27 | AI20: THỦY DIỆU - HÀNH THỦY | AJ20: MỘC ĐỨC- HÀNH MỘC | AN20: L.HÓA QUYỀNTHÌN | AO20: L.HÓA QUYỀN-V | AR20: =CONCATENATE(AS20,AU20) -> LIÊM TRINHTHÂN | AS20: LIÊM TRINH | AT20: V | AU20: THÂN | AV20: =CONCATENATE(AS20," ",AT20) -> LIÊM TRINH V | AX20: =CONCATENATE("L.",AN20) -> L.L.HÓA QUYỀNTHÌN | AY20: =CONCATENATE("L.",AO20) -> L.L.HÓA QUYỀN-V | BA20: 5 | BB20: 40 | BC20: 80 | DJ20: =CONCATENATE(DK20,DL20) -> SỬUNGỌ | DK20: SỬU | DL20: NGỌ | DM20: MÙI | DO20: HOA CÁI
A21: SỬU-7 | B21: CUNG MỆNH | C21: MÙI | I21: =IF(LEFT(RIGHT(L21,2))="-",LEFT(L21,LEN(L21)-LEN(RIGHT(L21,2))),L21) -> THIÊN ĐỒNG | J21: AN CHÍNH TINH DỰA VÀO SAO TỬ VI | K21: =MATCH($J$16,OFFSET('AN CÁC SAO CHÍNH TINH'!$A$1,'AN CÁC SAO CHÍNH TINH'!K20,0,1000000),0)+'AN CÁC SAO CHÍNH TINH'!K20 -> 3338 | L21: {=INDEX($B:$B,K21)} -> THIÊN ĐỒNG | M21: {=INDEX($C:$C,K21)} -> TÝ | N21: =VLOOKUP(M21,$M$3:$N$14,2,0) -> CUNG MỆNH | O21: CHÍNH TINH | U21: DƯƠNG NAMTHỔ 5 CỤC | V21: BỆNH | W21: DẦN | Z21: AN TÊN CÁC CUNG AN TRONG NĂM SINH | AA21: =MATCH($Z$1,OFFSET($U$1,'AN CÁC SAO CHÍNH TINH'!AA20,0,1000000),0)+'AN CÁC SAO CHÍNH TINH'!AA20 -> 388 | AB21: {=INDEX($W:$W,AA21)} -> MÃO | AC21: {=INDEX($V:$V,AA21)} -> Ất Mão | AH21: 28 | AI21: KẾ ĐÔ - HÀNH THỔ | AJ21: LA HẦU - HÀNH KIM | AN21: L.HÓA QUYỀNTUẤT | AO21: L.HÓA QUYỀN-V | AR21: =CONCATENATE(AS21,AU21) -> LIÊM TRINHSỬU | AS21: LIÊM TRINH | AT21: Đ | AU21: SỬU | AV21: =CONCATENATE(AS21," ",AT21) -> LIÊM TRINH Đ | AX21: =CONCATENATE("L.",AN21) -> L.L.HÓA QUYỀNTUẤT | AY21: =CONCATENATE("L.",AO21) -> L.L.HÓA QUYỀN-V | BA21: 6 | BB21: 50 | BC21: 70 | DJ21: =CONCATENATE(DK21,DL21) -> SỬUMÙI | DK21: SỬU | DL21: MÙI | DM21: THÂN | DO21: HÓA KHOA
A22: SỬU-8 | B22: CUNG MỆNH | C22: THÂN | I22: =IF(LEFT(RIGHT(L22,2))="-",LEFT(L22,LEN(L22)-LEN(RIGHT(L22,2))),L22) -> VŨ KHÚC | J22: AN CHÍNH TINH DỰA VÀO SAO TỬ VI | K22: =MATCH($J$16,OFFSET('AN CÁC SAO CHÍNH TINH'!$A$1,'AN CÁC SAO CHÍNH TINH'!K21,0,1000000),0)+'AN CÁC SAO CHÍNH TINH'!K21 -> 3350 | L22: {=INDEX($B:$B,K22)} -> VŨ KHÚC | M22: {=INDEX($C:$C,K22)} -> SỬU | N22: =VLOOKUP(M22,$M$3:$N$14,2,0) -> CUNG PHỤ MẪU | O22: CHÍNH TINH | U22: DƯƠNG NAMTHỔ 5 CỤC | V22: SUY | W22: SỬU | Z22: AN TÊN CÁC CUNG AN TRONG NĂM SINH | AA22: =MATCH($Z$1,OFFSET($U$1,'AN CÁC SAO CHÍNH TINH'!AA21,0,1000000),0)+'AN CÁC SAO CHÍNH TINH'!AA21 -> 389 | AB22: {=INDEX($W:$W,AA22)} -> THÌN | AC22: {=INDEX($V:$V,AA22)} -> Bính Thìn | AH22: 29 | AI22: VÂN HỚN - HÀNH HỎA | AJ22: THỔ TÚ - HÀNH THỔ | AN22: L.HÓA QUYỀNSỬU | AO22: L.HÓA QUYỀN-V | AR22: =CONCATENATE(AS22,AU22) -> LIÊM TRINHMÙI | AS22: LIÊM TRINH | AT22: Đ | AU22: MÙI | AV22: =CONCATENATE(AS22," ",AT22) -> LIÊM TRINH Đ | AX22: =CONCATENATE("L.",AN22) -> L.L.HÓA QUYỀNSỬU | AY22: =CONCATENATE("L.",AO22) -> L.L.HÓA QUYỀN-V | BA22: 7 | BB22: 60 | BC22: 60 | DJ22: =CONCATENATE(DK22,DL22) -> SỬUTHÂN | DK22: SỬU | DL22: THÂN | DM22: DẬU | DO22: HÓA KỴ
A23: SỬU-9 | B23: CUNG MỆNH | C23: DẬU | I23: =IF(LEFT(RIGHT(L23,2))="-",LEFT(L23,LEN(L23)-LEN(RIGHT(L23,2))),L23) -> THÁI DƯƠNG | J23: AN CHÍNH TINH DỰA VÀO SAO TỬ VI | K23: =MATCH($J$16,OFFSET('AN CÁC SAO CHÍNH TINH'!$A$1,'AN CÁC SAO CHÍNH TINH'!K22,0,1000000),0)+'AN CÁC SAO CHÍNH TINH'!K22 -> 3362 | L23: {=INDEX($B:$B,K23)} -> THÁI DƯƠNG | M23: {=INDEX($C:$C,K23)} -> Dần | N23: =VLOOKUP(M23,$M$3:$N$14,2,0) -> CUNG PHÚC ĐỨC | O23: CHÍNH TINH | U23: DƯƠNG NAMTHỔ 5 CỤC | V23: ĐẾ VƯỢNG | W23: TÝ | Z23: AN TÊN CÁC CUNG AN TRONG NĂM SINH | AA23: =MATCH($Z$1,OFFSET($U$1,'AN CÁC SAO CHÍNH TINH'!AA22,0,1000000),0)+'AN CÁC SAO CHÍNH TINH'!AA22 -> 390 | AB23: {=INDEX($W:$W,AA23)} -> TỴ | AC23: {=INDEX($V:$V,AA23)} -> Đinh Tỵ | AH23: 30 | AI23: MỘC ĐỨC- HÀNH MỘC | AJ23: THỦY DIỆU - HÀNH THỦY | AN23: L.HÓA QUYỀNMÙI | AO23: L.HÓA QUYỀN-V | AR23: =CONCATENATE(AS23,AU23) -> LIÊM TRINHTỴ | AS23: LIÊM TRINH | AT23: H | AU23: TỴ | AV23: =CONCATENATE(AS23," ",AT23) -> LIÊM TRINH H | AX23: =CONCATENATE("L.",AN23) -> L.L.HÓA QUYỀNMÙI | AY23: =CONCATENATE("L.",AO23) -> L.L.HÓA QUYỀN-V | BA23: 8 | BB23: 70 | BC23: 50 | DJ23: =CONCATENATE(DK23,DL23) -> SỬUDẬU | DK23: SỬU | DL23: DẬU | DM23: TUẤT | DO23: HÓA LỘC
A24: SỬU-10 | B24: CUNG MỆNH | C24: TUẤT | I24: =IF(LEFT(RIGHT(L24,2))="-",LEFT(L24,LEN(L24)-LEN(RIGHT(L24,2))),L24) -> THIÊN CƠ | J24: AN CHÍNH TINH DỰA VÀO SAO TỬ VI | K24: =MATCH($J$16,OFFSET('AN CÁC SAO CHÍNH TINH'!$A$1,'AN CÁC SAO CHÍNH TINH'!K23,0,1000000),0)+'AN CÁC SAO CHÍNH TINH'!K23 -> 3374 | L24: {=INDEX($B:$B,K24)} -> THIÊN CƠ | M24: {=INDEX($C:$C,K24)} -> THÌN | N24: =VLOOKUP(M24,$M$3:$N$14,2,0) -> CUNG QUAN LỘC | O24: CHÍNH TINH | U24: DƯƠNG NAMTHỔ 5 CỤC | V24: LÂM QUAN | W24: HỢI | Z24: AN TÊN CÁC CUNG AN TRONG NĂM SINH | AA24: =MATCH($Z$1,OFFSET($U$1,'AN CÁC SAO CHÍNH TINH'!AA23,0,1000000),0)+'AN CÁC SAO CHÍNH TINH'!AA23 -> 391 | AB24: {=INDEX($W:$W,AA24)} -> NGỌ | AC24: {=INDEX($V:$V,AA24)} -> Mậu Ngọ | AH24: 31 | AI24: THÁI ÂM- HÀNH THỦY | AJ24: THÁI BẠCH - HÀNH KIM | AN24: L.HÓA KHOADẦN | AO24: L.HÓA KHOA-Đ | AR24: =CONCATENATE(AS24,AU24) -> LIÊM TRINHHỢI | AS24: LIÊM TRINH | AT24: H | AU24: HỢI | AV24: =CONCATENATE(AS24," ",AT24) -> LIÊM TRINH H | AX24: =CONCATENATE("L.",AN24) -> L.L.HÓA KHOADẦN | AY24: =CONCATENATE("L.",AO24) -> L.L.HÓA KHOA-Đ | BA24: 9 | BB24: 80 | BC24: 40 | DJ24: =CONCATENATE(DK24,DL24) -> SỬUTUẤT | DK24: SỬU | DL24: TUẤT | DM24: HỢI | DO24: HÓA QUYỀN
A25: SỬU-11 | B25: CUNG MỆNH | C25: HỢI | I25: =IF(LEFT(RIGHT(L25,2))="-",LEFT(L25,LEN(L25)-LEN(RIGHT(L25,2))),L25) -> THIÊN PHỦ | J25: AN CHÍNH TINH DỰA VÀO SAO TỬ VI | K25: =MATCH($J$16,OFFSET('AN CÁC SAO CHÍNH TINH'!$A$1,'AN CÁC SAO CHÍNH TINH'!K24,0,1000000),0)+'AN CÁC SAO CHÍNH TINH'!K24 -> 3386 | L25: {=INDEX($B:$B,K25)} -> THIÊN PHỦ | M25: {=INDEX($C:$C,K25)} -> Hợi | N25: =VLOOKUP(M25,$M$3:$N$14,2,0) -> CUNG HUYNH ĐỆ | O25: CHÍNH TINH | U25: DƯƠNG NAMTHỔ 5 CỤC | V25: QUAN ĐỚI | W25: TUẤT | Z25: AN TÊN CÁC CUNG AN TRONG NĂM SINH | AA25: =MATCH($Z$1,OFFSET($U$1,'AN CÁC SAO CHÍNH TINH'!AA24,0,1000000),0)+'AN CÁC SAO CHÍNH TINH'!AA24 -> 392 | AB25: {=INDEX($W:$W,AA25)} -> MÙI | AC25: {=INDEX($V:$V,AA25)} -> Kỷ Mùi | AH25: 32 | AI25: THỔ TÚ - HÀNH THỔ | AJ25: THÁI DƯƠNG - HÀNH HỎA | AN25: L.HÓA KHOATHÂN | AO25: L.HÓA KHOA-Đ | AR25: =CONCATENATE(AS25,AU25) -> LIÊM TRINHMÃO | AS25: LIÊM TRINH | AT25: H | AU25: MÃO | AV25: =CONCATENATE(AS25," ",AT25) -> LIÊM TRINH H | AX25: =CONCATENATE("L.",AN25) -> L.L.HÓA KHOATHÂN | AY25: =CONCATENATE("L.",AO25) -> L.L.HÓA KHOA-Đ | BA25: 10 | BB25: 90 | BC25: 30 | DJ25: =CONCATENATE(DK25,DL25) -> SỬUHỢI | DK25: SỬU | DL25: HỢI | DM25: TÝ | DO25: HỎA TINH
A26: SỬU-12 | B26: CUNG MỆNH | C26: TÝ | I26: =IF(LEFT(RIGHT(L26,2))="-",LEFT(L26,LEN(L26)-LEN(RIGHT(L26,2))),L26) -> THÁI ÂM | J26: AN CHÍNH TINH DỰA VÀO SAO TỬ VI | K26: =MATCH($J$16,OFFSET('AN CÁC SAO CHÍNH TINH'!$A$1,'AN CÁC SAO CHÍNH TINH'!K25,0,1000000),0)+'AN CÁC SAO CHÍNH TINH'!K25 -> 3398 | L26: {=INDEX($B:$B,K26)} -> THÁI ÂM | M26: {=INDEX($C:$C,K26)} -> TÝ | N26: =VLOOKUP(M26,$M$3:$N$14,2,0) -> CUNG MỆNH | O26: CHÍNH TINH | U26: DƯƠNG NAMTHỔ 5 CỤC | V26: MỘC DỤC | W26: DẬU | Z26: AN TÊN CÁC CUNG AN TRONG NĂM SINH | AA26: =MATCH($Z$1,OFFSET($U$1,'AN CÁC SAO CHÍNH TINH'!AA25,0,1000000),0)+'AN CÁC SAO CHÍNH TINH'!AA25 -> 393 | AB26: {=INDEX($W:$W,AA26)} -> THÂN | AC26: {=INDEX($V:$V,AA26)} -> Canh Thân | AH26: 33 | AI26: LA HẦU - HÀNH KIM | AJ26: VÂN HỚN - HÀNH HỎA | AN26: L.HÓA KHOAHỢI | AO26: L.HÓA KHOA-Đ | AR26: =CONCATENATE(AS26,AU26) -> LIÊM TRINHDẬU | AS26: LIÊM TRINH | AT26: H | AU26: DẬU | AV26: =CONCATENATE(AS26," ",AT26) -> LIÊM TRINH H | AX26: =CONCATENATE("L.",AN26) -> L.L.HÓA KHOAHỢI | AY26: =CONCATENATE("L.",AO26) -> L.L.HÓA KHOA-Đ | BA26: 11 | BB26: 100 | BC26: 20 | DJ26: =CONCATENATE(DK26,DL26) -> DẦNTÝ | DK26: DẦN | DL26: TÝ | DM26: DẦN | DO26: HỒNG LOAN
A27: DẦN-1 | B27: CUNG MỆNH | C27: TÝ | I27: =IF(LEFT(RIGHT(L27,2))="-",LEFT(L27,LEN(L27)-LEN(RIGHT(L27,2))),L27) -> THAM LANG | J27: AN CHÍNH TINH DỰA VÀO SAO TỬ VI | K27: =MATCH($J$16,OFFSET('AN CÁC SAO CHÍNH TINH'!$A$1,'AN CÁC SAO CHÍNH TINH'!K26,0,1000000),0)+'AN CÁC SAO CHÍNH TINH'!K26 -> 3410 | L27: {=INDEX($B:$B,K27)} -> THAM LANG | M27: {=INDEX($C:$C,K27)} -> SỬU | N27: =VLOOKUP(M27,$M$3:$N$14,2,0) -> CUNG PHỤ MẪU | O27: CHÍNH TINH | U27: DƯƠNG NAMHỎA 6 CỤC | V27: TRƯỜNG SINH | W27: DẦN | Z27: AN TÊN CÁC CUNG AN TRONG NĂM SINH | AA27: =MATCH($Z$1,OFFSET($U$1,'AN CÁC SAO CHÍNH TINH'!AA26,0,1000000),0)+'AN CÁC SAO CHÍNH TINH'!AA26 -> 394 | AB27: {=INDEX($W:$W,AA27)} -> DẬU | AC27: {=INDEX($V:$V,AA27)} -> Tân Dậu | AH27: 34 | AI27: THÁI DƯƠNG - HÀNH HỎA | AJ27: KẾ ĐÔ - HÀNH THỔ | AN27: L.HÓA LỘCTHÌN | AO27: L.HÓA LỘC-V | AR27: =CONCATENATE(AS27,AU27) -> THIÊN ĐỒNGDẦN | AS27: THIÊN ĐỒNG | AT27: M | AU27: DẦN | AV27: =CONCATENATE(AS27," ",AT27) -> THIÊN ĐỒNG M | AX27: =CONCATENATE("L.",AN27) -> L.L.HÓA LỘCTHÌN | AY27: =CONCATENATE("L.",AO27) -> L.L.HÓA LỘC-V | BA27: 12 | BB27: 110 | BC27: 10 | DJ27: =CONCATENATE(DK27,DL27) -> DẦNSỬU | DK27: DẦN | DL27: SỬU | DM27: MÃO | DO27: HỮU BẬT
A28: DẦN-2 | B28: CUNG MỆNH | C28: SỬU | I28: =IF(LEFT(RIGHT(L28,2))="-",LEFT(L28,LEN(L28)-LEN(RIGHT(L28,2))),L28) -> CỰ MÔN | J28: AN CHÍNH TINH DỰA VÀO SAO TỬ VI | K28: =MATCH($J$16,OFFSET('AN CÁC SAO CHÍNH TINH'!$A$1,'AN CÁC SAO CHÍNH TINH'!K27,0,1000000),0)+'AN CÁC SAO CHÍNH TINH'!K27 -> 3422 | L28: {=INDEX($B:$B,K28)} -> CỰ MÔN | M28: {=INDEX($C:$C,K28)} -> Dần | N28: =VLOOKUP(M28,$M$3:$N$14,2,0) -> CUNG PHÚC ĐỨC | O28: CHÍNH TINH | U28: DƯƠNG NAMHỎA 6 CỤC | V28: DƯỠNG | W28: SỬU | Z28: AN TÊN CÁC CUNG AN TRONG NĂM SINH | AA28: =MATCH($Z$1,OFFSET($U$1,'AN CÁC SAO CHÍNH TINH'!AA27,0,1000000),0)+'AN CÁC SAO CHÍNH TINH'!AA27 -> 395 | AB28: {=INDEX($W:$W,AA28)} -> TUẤT | AC28: {=INDEX($V:$V,AA28)} -> Nhâm Tuất | AH28: 35 | AI28: THÁI BẠCH - HÀNH KIM | AJ28: THÁI ÂM- HÀNH THỦY | AN28: L.HÓA LỘCTUẤT | AO28: L.HÓA LỘC-V | AR28: =CONCATENATE(AS28,AU28) -> THIÊN ĐỒNGTHÂN | AS28: THIÊN ĐỒNG | AT28: M | AU28: THÂN | AV28: =CONCATENATE(AS28," ",AT28) -> THIÊN ĐỒNG M | AX28: =CONCATENATE("L.",AN28) -> L.L.HÓA LỘCTUẤT | AY28: =CONCATENATE("L.",AO28) -> L.L.HÓA LỘC-V | DJ28: =CONCATENATE(DK28,DL28) -> DẦNDẦN | DK28: DẦN | DL28: DẦN | DM28: THÌN | DO28: HỶ THẦN
A29: DẦN-3 | B29: CUNG MỆNH | C29: DẦN | I29: =IF(LEFT(RIGHT(L29,2))="-",LEFT(L29,LEN(L29)-LEN(RIGHT(L29,2))),L29) -> THIÊN TƯỚNG | J29: AN CHÍNH TINH DỰA VÀO SAO TỬ VI | K29: =MATCH($J$16,OFFSET('AN CÁC SAO CHÍNH TINH'!$A$1,'AN CÁC SAO CHÍNH TINH'!K28,0,1000000),0)+'AN CÁC SAO CHÍNH TINH'!K28 -> 3434 | L29: {=INDEX($B:$B,K29)} -> THIÊN TƯỚNG | M29: {=INDEX($C:$C,K29)} -> MÃO | N29: =VLOOKUP(M29,$M$3:$N$14,2,0) -> CUNG ĐIỀN TRẠCH | O29: CHÍNH TINH | U29: DƯƠNG NAMHỎA 6 CỤC | V29: THAI | W29: TÝ | Z29: AN TÊN CÁC CUNG AN TRONG NĂM SINH | AA29: =MATCH($Z$1,OFFSET($U$1,'AN CÁC SAO CHÍNH TINH'!AA28,0,1000000),0)+'AN CÁC SAO CHÍNH TINH'!AA28 -> 396 | AB29: {=INDEX($W:$W,AA29)} -> HỢI | AC29: {=INDEX($V:$V,AA29)} -> Quý Hợi | AH29: 36 | AI29: THỦY DIỆU - HÀNH THỦY | AJ29: MỘC ĐỨC- HÀNH MỘC | AN29: L.HÓA LỘCSỬU | AO29: L.HÓA LỘC-V | AR29: =CONCATENATE(AS29,AU29) -> THIÊN ĐỒNGTÝ | AS29: THIÊN ĐỒNG | AT29: V | AU29: TÝ | AV29: =CONCATENATE(AS29," ",AT29) -> THIÊN ĐỒNG V | AX29: =CONCATENATE("L.",AN29) -> L.L.HÓA LỘCSỬU | AY29: =CONCATENATE("L.",AO29) -> L.L.HÓA LỘC-V | DJ29: =CONCATENATE(DK29,DL29) -> DẦNMÃO | DK29: DẦN | DL29: MÃO | DM29: TỴ | DO29: KIẾP SÁT
A30: DẦN-4 | B30: CUNG MỆNH | C30: MÃO | I30: =IF(LEFT(RIGHT(L30,2))="-",LEFT(L30,LEN(L30)-LEN(RIGHT(L30,2))),L30) -> THIÊN LƯƠNG | J30: AN CHÍNH TINH DỰA VÀO SAO TỬ VI | K30: =MATCH($J$16,OFFSET('AN CÁC SAO CHÍNH TINH'!$A$1,'AN CÁC SAO CHÍNH TINH'!K29,0,1000000),0)+'AN CÁC SAO CHÍNH TINH'!K29 -> 3446 | L30: {=INDEX($B:$B,K30)} -> THIÊN LƯƠNG | M30: {=INDEX($C:$C,K30)} -> THÌN | N30: =VLOOKUP(M30,$M$3:$N$14,2,0) -> CUNG QUAN LỘC | O30: CHÍNH TINH | U30: DƯƠNG NAMHỎA 6 CỤC | V30: TUYỆT | W30: HỢI | Z30: AN TÊN CÁC CUNG AN TRONG NĂM SINH | AA30: =MATCH($Z$1,OFFSET($U$1,'AN CÁC SAO CHÍNH TINH'!AA29,0,1000000),0)+'AN CÁC SAO CHÍNH TINH'!AA29 -> 397 | AB30: {=INDEX($W:$W,AA30)} -> TÝ | AC30: {=INDEX($V:$V,AA30)} -> Giáp Tý | AH30: 37 | AI30: KẾ ĐÔ - HÀNH THỔ | AJ30: LA HẦU - HÀNH KIM | AN30: L.HÓA LỘCMÙI | AO30: L.HÓA LỘC-V | AR30: =CONCATENATE(AS30,AU30) -> THIÊN ĐỒNGMÃO | AS30: THIÊN ĐỒNG | AT30: Đ | AU30: MÃO | AV30: =CONCATENATE(AS30," ",AT30) -> THIÊN ĐỒNG Đ | AX30: =CONCATENATE("L.",AN30) -> L.L.HÓA LỘCMÙI | AY30: =CONCATENATE("L.",AO30) -> L.L.HÓA LỘC-V | DJ30: =CONCATENATE(DK30,DL30) -> DẦNTHÌN | DK30: DẦN | DL30: THÌN | DM30: NGỌ | DO30: KÌNH DƯƠNG
A31: DẦN-5 | B31: CUNG MỆNH | C31: THÌN | I31: =IF(LEFT(RIGHT(L31,2))="-",LEFT(L31,LEN(L31)-LEN(RIGHT(L31,2))),L31) -> THẤT SÁT | J31: AN CHÍNH TINH DỰA VÀO SAO TỬ VI | K31: =MATCH($J$16,OFFSET('AN CÁC SAO CHÍNH TINH'!$A$1,'AN CÁC SAO CHÍNH TINH'!K30,0,1000000),0)+'AN CÁC SAO CHÍNH TINH'!K30 -> 3458 | L31: {=INDEX($B:$B,K31)} -> THẤT SÁT | M31: {=INDEX($C:$C,K31)} -> TỴ | N31: =VLOOKUP(M31,$M$3:$N$14,2,0) -> CUNG NÔ BỘC | O31: CHÍNH TINH | U31: DƯƠNG NAMHỎA 6 CỤC | V31: MỘ | W31: TUẤT | Z31: AN TÊN CÁC CUNG AN TRONG NĂM SINH | AA31: =MATCH($Z$1,OFFSET($U$1,'AN CÁC SAO CHÍNH TINH'!AA30,0,1000000),0)+'AN CÁC SAO CHÍNH TINH'!AA30 -> 398 | AB31: {=INDEX($W:$W,AA31)} -> SỬU | AC31: {=INDEX($V:$V,AA31)} -> Ất Sửu | AH31: 38 | AI31: VÂN HỚN - HÀNH HỎA | AJ31: THỔ TÚ - HÀNH THỔ | AN31: L.HÓA LỘCDẦN | AO31: L.HÓA LỘC-V | AR31: =CONCATENATE(AS31,AU31) -> THIÊN ĐỒNGTỴ | AS31: THIÊN ĐỒNG | AT31: Đ | AU31: TỴ | AV31: =CONCATENATE(AS31," ",AT31) -> THIÊN ĐỒNG Đ | AX31: =CONCATENATE("L.",AN31) -> L.L.HÓA LỘCDẦN | AY31: =CONCATENATE("L.",AO31) -> L.L.HÓA LỘC-V | DJ31: =CONCATENATE(DK31,DL31) -> DẦNTỴ | DK31: DẦN | DL31: TỴ | DM31: MÙI | DO31: LIÊM TRINH
A32: DẦN-6 | B32: CUNG MỆNH | C32: TỴ | I32: =IF(LEFT(RIGHT(L32,2))="-",LEFT(L32,LEN(L32)-LEN(RIGHT(L32,2))),L32) -> PHÁ QUÂN | J32: AN CHÍNH TINH DỰA VÀO SAO TỬ VI | K32: =MATCH($J$16,OFFSET('AN CÁC SAO CHÍNH TINH'!$A$1,'AN CÁC SAO CHÍNH TINH'!K31,0,1000000),0)+'AN CÁC SAO CHÍNH TINH'!K31 -> 3470 | L32: {=INDEX($B:$B,K32)} -> PHÁ QUÂN | M32: {=INDEX($C:$C,K32)} -> Dậu | N32: =VLOOKUP(M32,$M$3:$N$14,2,0) -> CUNG TỬ TỨC | O32: CHÍNH TINH | U32: DƯƠNG NAMHỎA 6 CỤC | V32: TỬ | W32: DẬU | Z32: AN TÊN CÁC CUNG AN TRONG NĂM SINH | AA32: =MATCH($Z$1,OFFSET($U$1,'AN CÁC SAO CHÍNH TINH'!AA31,0,1000000),0)+'AN CÁC SAO CHÍNH TINH'!AA31 -> #N/A | AB32: {=INDEX($W:$W,AA32)} -> #N/A | AC32: {=INDEX($V:$V,AA32)} -> #N/A | AH32: 39 | AI32: MỘC ĐỨC- HÀNH MỘC | AJ32: THỦY DIỆU - HÀNH THỦY | AN32: L.HÓA LỘCMÃO | AO32: L.HÓA LỘC-V | AR32: =CONCATENATE(AS32,AU32) -> THIÊN ĐỒNGHỢI | AS32: THIÊN ĐỒNG | AT32: Đ | AU32: HỢI | AV32: =CONCATENATE(AS32," ",AT32) -> THIÊN ĐỒNG Đ | AX32: =CONCATENATE("L.",AN32) -> L.L.HÓA LỘCMÃO | AY32: =CONCATENATE("L.",AO32) -> L.L.HÓA LỘC-V | DJ32: =CONCATENATE(DK32,DL32) -> DẦNNGỌ | DK32: DẦN | DL32: NGỌ | DM32: THÂN | DO32: LINH TINH
A33: DẦN-7 | B33: CUNG MỆNH | C33: NGỌ | I33: =IF(LEFT(RIGHT(L33,2))="-",LEFT(L33,LEN(L33)-LEN(RIGHT(L33,2))),L33) -> #N/A | J33: AN CHÍNH TINH DỰA VÀO SAO TỬ VI | K33: =MATCH($J$16,OFFSET('AN CÁC SAO CHÍNH TINH'!$A$1,'AN CÁC SAO CHÍNH TINH'!K32,0,1000000),0)+'AN CÁC SAO CHÍNH TINH'!K32 -> #N/A | L33: {=INDEX($B:$B,K33)} -> #N/A | M33: {=INDEX($C:$C,K33)} -> #N/A | N33: =VLOOKUP(M33,$M$3:$N$14,2,0) -> #N/A | U33: DƯƠNG NAMHỎA 6 CỤC | V33: BỆNH | W33: THÂN | Z33: AN TÊN CÁC CUNG AN TRONG NĂM SINH | AA33: =MATCH($Z$1,OFFSET($U$1,'AN CÁC SAO CHÍNH TINH'!AA32,0,1000000),0)+'AN CÁC SAO CHÍNH TINH'!AA32 -> #N/A | AB33: {=INDEX($W:$W,AA33)} -> #N/A | AC33: {=INDEX($V:$V,AA33)} -> #N/A | AH33: 40 | AI33: THÁI ÂM- HÀNH THỦY | AJ33: THÁI BẠCH - HÀNH KIM | AN33: L.HÓA KỴTHÌN | AO33: L.HÓA KỴ-Đ | AR33: =CONCATENATE(AS33,AU33) -> THIÊN ĐỒNGTHÌN | AS33: THIÊN ĐỒNG | AT33: H | AU33: THÌN | AV33: =CONCATENATE(AS33," ",AT33) -> THIÊN ĐỒNG H | AX33: =CONCATENATE("L.",AN33) -> L.L.HÓA KỴTHÌN | AY33: =CONCATENATE("L.",AO33) -> L.L.HÓA KỴ-Đ | DJ33: =CONCATENATE(DK33,DL33) -> DẦNMÙI | DK33: DẦN | DL33: MÙI | DM33: DẬU | DO33: LN.VĂN TINH
A34: DẦN-8 | B34: CUNG MỆNH | C34: MÙI | I34: =IF(LEFT(RIGHT(L34,2))="-",LEFT(L34,LEN(L34)-LEN(RIGHT(L34,2))),L34) -> #N/A | J34: AN CHÍNH TINH DỰA VÀO SAO TỬ VI | K34: =MATCH($J$16,OFFSET('AN CÁC SAO CHÍNH TINH'!$A$1,'AN CÁC SAO CHÍNH TINH'!K33,0,1000000),0)+'AN CÁC SAO CHÍNH TINH'!K33 -> #N/A | L34: {=INDEX($B:$B,K34)} -> #N/A | M34: {=INDEX($C:$C,K34)} -> #N/A | N34: =VLOOKUP(M34,$M$3:$N$14,2,0) -> #N/A | U34: DƯƠNG NAMHỎA 6 CỤC | V34: SUY | W34: MÙI | Z34: AN TÊN CÁC CUNG AN TRONG NĂM SINH | AA34: =MATCH($Z$1,OFFSET($U$1,'AN CÁC SAO CHÍNH TINH'!AA33,0,1000000),0)+'AN CÁC SAO CHÍNH TINH'!AA33 -> #N/A | AB34: {=INDEX($W:$W,AA34)} -> #N/A | AC34: {=INDEX($V:$V,AA34)} -> #N/A | AH34: 41 | AI34: THỔ TÚ - HÀNH THỔ | AJ34: THÁI DƯƠNG - HÀNH HỎA | AN34: L.HÓA KỴTUẤT | AO34: L.HÓA KỴ-Đ | AR34: =CONCATENATE(AS34,AU34) -> THIÊN ĐỒNGTUẤT | AS34: THIÊN ĐỒNG | AT34: H | AU34: TUẤT | AV34: =CONCATENATE(AS34," ",AT34) -> THIÊN ĐỒNG H | AX34: =CONCATENATE("L.",AN34) -> L.L.HÓA KỴTUẤT | AY34: =CONCATENATE("L.",AO34) -> L.L.HÓA KỴ-Đ | DJ34: =CONCATENATE(DK34,DL34) -> DẦNTHÂN | DK34: DẦN | DL34: THÂN | DM34: TUẤT | DO34: LỘC TỒN
A35: DẦN-9 | B35: CUNG MỆNH | C35: THÂN | U35: DƯƠNG NAMHỎA 6 CỤC | V35: ĐẾ VƯỢNG | W35: NGỌ | AH35: 42 | AI35: LA HẦU - HÀNH KIM | AJ35: VÂN HỚN - HÀNH HỎA | AN35: L.HÓA KỴSỬU | AO35: L.HÓA KỴ-Đ | AR35: =CONCATENATE(AS35,AU35) -> THIÊN ĐỒNGSỬU | AS35: THIÊN ĐỒNG | AT35: H | AU35: SỬU | AV35: =CONCATENATE(AS35," ",AT35) -> THIÊN ĐỒNG H | AX35: =CONCATENATE("L.",AN35) -> L.L.HÓA KỴSỬU | AY35: =CONCATENATE("L.",AO35) -> L.L.HÓA KỴ-Đ | DJ35: =CONCATENATE(DK35,DL35) -> DẦNDẬU | DK35: DẦN | DL35: DẬU | DM35: HỢI | DO35: LONG ĐỨC
A36: DẦN-10 | B36: CUNG MỆNH | C36: DẬU | I36: =IF(LEFT(RIGHT(L36,2))="-",LEFT(L36,LEN(L36)-LEN(RIGHT(L36,2))),L36) -> TUẦN | J36: kết hợp can chi | K36: =MATCH($H$2,OFFSET('AN CÁC SAO CHÍNH TINH'!$A$1,'AN CÁC SAO CHÍNH TINH'!K35,0,1000000),0)+'AN CÁC SAO CHÍNH TINH'!K35 -> 3710 | L36: {=INDEX($B:$B,K36)} -> TUẦN | M36: {=INDEX($C:$C,K36)} -> TUẤT | N36: =VLOOKUP(M36,$M$3:$N$14,2,0) -> CUNG PHU/THÊ | U36: DƯƠNG NAMHỎA 6 CỤC | V36: LÂM QUAN | W36: TỴ | AH36: 43 | AI36: THÁI DƯƠNG - HÀNH HỎA | AJ36: KẾ ĐÔ - HÀNH THỔ | AN36: L.HÓA KỴMÙI | AO36: L.HÓA KỴ-Đ | AR36: =CONCATENATE(AS36,AU36) -> THIÊN ĐỒNGMÙI | AS36: THIÊN ĐỒNG | AT36: H | AU36: MÙI | AV36: =CONCATENATE(AS36," ",AT36) -> THIÊN ĐỒNG H | AX36: =CONCATENATE("L.",AN36) -> L.L.HÓA KỴMÙI | AY36: =CONCATENATE("L.",AO36) -> L.L.HÓA KỴ-Đ | DJ36: =CONCATENATE(DK36,DL36) -> DẦNTUẤT | DK36: DẦN | DL36: TUẤT | DM36: TÝ | DO36: LONG TRÌ
A37: DẦN-11 | B37: CUNG MỆNH | C37: TUẤT | I37: =IF(LEFT(RIGHT(L37,2))="-",LEFT(L37,LEN(L37)-LEN(RIGHT(L37,2))),L37) -> TUẦN | J37: kết hợp can chi | K37: =MATCH($H$2,OFFSET('AN CÁC SAO CHÍNH TINH'!$A$1,'AN CÁC SAO CHÍNH TINH'!K36,0,1000000),0)+'AN CÁC SAO CHÍNH TINH'!K36 -> 3720 | L37: {=INDEX($B:$B,K37)} -> TUẦN | M37: {=INDEX($C:$C,K37)} -> HỢI | N37: =VLOOKUP(M37,$M$3:$N$14,2,0) -> CUNG HUYNH ĐỆ | U37: DƯƠNG NAMHỎA 6 CỤC | V37: QUAN ĐỚI | W37: THÌN | Z37: AN NGUYỆT VẬN TRONG THIÊN BÀN | AA37: =MATCH($Y$1,OFFSET($U$1,'AN CÁC SAO CHÍNH TINH'!AA36,0,1000000),0)+'AN CÁC SAO CHÍNH TINH'!AA36 -> 987 | AB37: {=INDEX($W:$W,AA37)} -> TÝ | AC37: {=INDEX($V:$V,AA37)} -> THÌN | AH37: 44 | AI37: THÁI BẠCH - HÀNH KIM | AJ37: THÁI ÂM- HÀNH THỦY | AN37: TỬ VITÝ | AO37: TỬ VI-B | AP37: TỬ VI B | AQ37: =CONCATENATE(TRIM(LEFT(AP37,LEN(AP37)-LEN(RIGHT(AP37)))),"-",RIGHT(AP37)) -> TỬ VI-B | AR37: =CONCATENATE(AS37,AU37) -> THIÊN ĐỒNGNGỌ | AS37: THIÊN ĐỒNG | AT37: H | AU37: NGỌ | AV37: =CONCATENATE(AS37," ",AT37) -> THIÊN ĐỒNG H | AX37: =CONCATENATE("L.",AN37) -> L.TỬ VITÝ | AY37: =CONCATENATE("L.",AO37) -> L.TỬ VI-B | DJ37: =CONCATENATE(DK37,DL37) -> DẦNHỢI | DK37: DẦN | DL37: HỢI | DM37: SỬU | DO37: LỰC SỸ
A38: DẦN-12 | B38: CUNG MỆNH | C38: HỢI | I38: =IF(LEFT(RIGHT(L38,2))="-",LEFT(L38,LEN(L38)-LEN(RIGHT(L38,2))),L38) -> #N/A | J38: kết hợp can chi | K38: =MATCH($H$2,OFFSET('AN CÁC SAO CHÍNH TINH'!$A$1,'AN CÁC SAO CHÍNH TINH'!K37,0,1000000),0)+'AN CÁC SAO CHÍNH TINH'!K37 -> #N/A | L38: {=INDEX($B:$B,K38)} -> #N/A | M38: {=INDEX($C:$C,K38)} -> #N/A | N38: =VLOOKUP(M38,$M$3:$N$14,2,0) -> #N/A | U38: DƯƠNG NAMHỎA 6 CỤC | V38: MỘC DỤC | W38: MÃO | Z38: AN NGUYỆT VẬN TRONG THIÊN BÀN | AA38: =MATCH($Y$1,OFFSET($U$1,'AN CÁC SAO CHÍNH TINH'!AA37,0,1000000),0)+'AN CÁC SAO CHÍNH TINH'!AA37 -> 988 | AB38: {=INDEX($W:$W,AA38)} -> SỬU | AC38: {=INDEX($V:$V,AA38)} -> MÃO | AH38: 45 | AI38: THỦY DIỆU - HÀNH THỦY | AJ38: MỘC ĐỨC- HÀNH MỘC | AK38: H | AN38: TỬ VISỬU | AO38: TỬ VI-B | AP38: TỬ VI Đ | AQ38: =CONCATENATE(TRIM(LEFT(AP38,LEN(AP38)-LEN(RIGHT(AP38)))),"-",RIGHT(AP38)) -> TỬ VI-Đ | AR38: =CONCATENATE(AS38,AU38) -> THIÊN ĐỒNGDẬU | AS38: THIÊN ĐỒNG | AT38: H | AU38: DẬU | AV38: =CONCATENATE(AS38," ",AT38) -> THIÊN ĐỒNG H | AX38: =CONCATENATE("L.",AN38) -> L.TỬ VISỬU | AY38: =CONCATENATE("L.",AO38) -> L.TỬ VI-B | DJ38: =CONCATENATE(DK38,DL38) -> MÃOTÝ | DK38: MÃO | DL38: TÝ | DM38: MÃO | DO38: LƯU HÀ
